Workbook

Sheet GENNAIO
B2: GENNAIO 2026
B3: Il tuo netto reale spendibile questo mese
B4: =K93+K91-K95-K96 -> -609.90975
B5: =CONCATENATE("su €",TEXT(K92,"#,##0")," di fatturato P.IVA • €",TEXT(K94,"#,##0")," tra tasse e INPS già accantonati") -> su €450 di fatturato P.IVA • €402 tra tasse e INPS già accantonati
B7: FATTURATO P.IVA | D7: DA ACCANTONARE | F7: STATO MESE | I7: 🎯 RIEPILOGO MESE
B8: =K92 -> 450 | D8: =K94 -> 401.86 | F8: =IF(B4<0,"🔴 IN ROSSO",IF(K97>=0.2,"🟢 SANO",IF(K97>=0.1,"🟡 ATTENZIONE","🟠 SAVING BASSO"))) -> 🔴 IN ROSSO | I8: =IF(B4>=0,CONCATENATE("✅ €",TEXT(B4,"#,##0")," netti reali questo mese"),CONCATENATE("⚠ Sotto di €",TEXT(-B4,"#,##0")," questo mese")) -> ⚠ Sotto di €610 questo mese
B9: =CONCATENATE("+ €",TEXT(K91,"#,##0")," entrate private") -> + €1.550 entrate private | D9: =CONCATENATE("Tasse €",TEXT(F25,"#,##0")," + INPS €",TEXT(SETUP!$C$6,"#,##0")) -> Tasse €0 + INPS €384 | F9: =CONCATENATE("Saving rate ",TEXT(K97,"0.0%")) -> Saving rate -135,5%
B11: =CONCATENATE("⚠ Soglia INPS lordo annua: €",TEXT(SETUP!$C$8,"#,##0")," • Fatturato P.IVA mese: €",TEXT(K92,"#,##0")," • Vedi DASHBOARD per il monitoraggio annuale") -> ⚠ Soglia INPS lordo annua: €23.608 • Fatturato P.IVA mese: €450 • Vedi DASHBOARD per il monitoraggio annuale
B13: 💰 ENTRATE | I13: 🟢 ENTRATE INCASSATE
B14: CLIENTE / FONTE | C14: LORDO € | D14: TIPO | E14: CON SOCIO? | F14: TASSE 5% | G14: INPS SOCIO | H14: STATO | I14: Fatturato P.IVA | J14: =K92 -> 450
B15: FRUTTETO | C15: 500 | D15: ENTRATA PRIVATA (no tasse) | E15: NO | F15: =IF(D15="FATTURA P.IVA",C15*SETUP!$C$4*SETUP!$C$5,0) -> 0 | G15: =IF(AND(D15="FATTURA P.IVA",E15="SI"),C15*SETUP!$C$4*SETUP!$C$11,0) -> 0 | H15: INCASSATO | I15: Entrate Private | J15: =K91 -> 1550
B16: PIADINA | C16: 250 | D16: FATTURA P.IVA | E16: SI | F16: =IF(D16="FATTURA P.IVA",C16*SETUP!$C$4*SETUP!$C$5,0) -> 9.75 | G16: =IF(AND(D16="FATTURA P.IVA",E16="SI"),C16*SETUP!$C$4*SETUP!$C$11,0) -> 50.8365 | H16: INCASSATO | I16: 🔵 ENTRATE PREVISTE
B17: GOBBO | C17: 150 | D17: ENTRATA PRIVATA (no tasse) | E17: NO | F17: =IF(D17="FATTURA P.IVA",C17*SETUP!$C$4*SETUP!$C$5,0) -> 0 | G17: =IF(AND(D17="FATTURA P.IVA",E17="SI"),C17*SETUP!$C$4*SETUP!$C$11,0) -> 0 | H17: INCASSATO | I17: Fatturato emesso | J17: =K106 -> 0
B18: RUBIERA | C18: 200 | D18: FATTURA P.IVA | E18: NO | F18: =IF(D18="FATTURA P.IVA",C18*SETUP!$C$4*SETUP!$C$5,0) -> 7.8 | G18: =IF(AND(D18="FATTURA P.IVA",E18="SI"),C18*SETUP!$C$4*SETUP!$C$11,0) -> 0 | H18: INCASSATO | I18: Pipeline programmata | J18: =K107 -> 0
B19: RIKY | C19: 150 | D19: ENTRATA PRIVATA (no tasse) | E19: NO | F19: =IF(D19="FATTURA P.IVA",C19*SETUP!$C$4*SETUP!$C$5,0) -> 0 | G19: =IF(AND(D19="FATTURA P.IVA",E19="SI"),C19*SETUP!$C$4*SETUP!$C$11,0) -> 0 | H19: INCASSATO | I19: Entrate Private previste | J19: =K108 -> 0
B20: REGALI | C20: 550 | D20: ENTRATA PRIVATA (no tasse) | E20: NO | F20: =IF(D20="FATTURA P.IVA",C20*SETUP!$C$4*SETUP!$C$5,0) -> 0 | G20: =IF(AND(D20="FATTURA P.IVA",E20="SI"),C20*SETUP!$C$4*SETUP!$C$11,0) -> 0 | H20: INCASSATO | I20: 💰 TASSE & INPS
B21: PIADA | C21: 200 | D21: ENTRATA PRIVATA (no tasse) | E21: NO | F21: =IF(D21="FATTURA P.IVA",C21*SETUP!$C$4*SETUP!$C$5,0) -> 0 | G21: =IF(AND(D21="FATTURA P.IVA",E21="SI"),C21*SETUP!$C$4*SETUP!$C$11,0) -> 0 | H21: INCASSATO | I21: Tasse 5% | J21: =F29 -> 17.55
F22: =IF(D22="FATTURA P.IVA",C22*SETUP!$C$4*SETUP!$C$5,0) -> 0 | G22: =IF(AND(D22="FATTURA P.IVA",E22="SI"),C22*SETUP!$C$4*SETUP!$C$11,0) -> 0 | I22: INPS Fisso (artig.) | J22: =SETUP!$C$6 -> 384.31
F23: =IF(D23="FATTURA P.IVA",C23*SETUP!$C$4*SETUP!$C$5,0) -> 0 | G23: =IF(AND(D23="FATTURA P.IVA",E23="SI"),C23*SETUP!$C$4*SETUP!$C$11,0) -> 0 | I23: INPS Socio (sim.) | J23: =G29 -> 50.8365
F24: =IF(D24="FATTURA P.IVA",C24*SETUP!$C$4*SETUP!$C$5,0) -> 0 | G24: =IF(AND(D24="FATTURA P.IVA",E24="SI"),C24*SETUP!$C$4*SETUP!$C$11,0) -> 0 | I24: 📤 USCITE & SAVING
F25: =IF(D25="FATTURA P.IVA",C25*SETUP!$C$4*SETUP!$C$5,0) -> 0 | G25: =IF(AND(D25="FATTURA P.IVA",E25="SI"),C25*SETUP!$C$4*SETUP!$C$11,0) -> 0 | I25: Tuo Netto P.IVA | J25: =K93 -> 286.90675
F26: =IF(D26="FATTURA P.IVA",C26*SETUP!$C$4*SETUP!$C$5,0) -> 0 | G26: =IF(AND(D26="FATTURA P.IVA",E26="SI"),C26*SETUP!$C$4*SETUP!$C$11,0) -> 0 | I26: Uscite effettive | J26: =D78 -> 1807.17
F27: =IF(D27="FATTURA P.IVA",C27*SETUP!$C$4*SETUP!$C$5,0) -> 0 | G27: =IF(AND(D27="FATTURA P.IVA",E27="SI"),C27*SETUP!$C$4*SETUP!$C$11,0) -> 0 | I27: Totale Secchielli | J27: =C92 -> 639.6465
F28: =IF(D28="FATTURA P.IVA",C28*SETUP!$C$4*SETUP!$C$5,0) -> 0 | G28: =IF(AND(D28="FATTURA P.IVA",E28="SI"),C28*SETUP!$C$4*SETUP!$C$11,0) -> 0 | I28: ✨ NETTO REALE | J28: =B4 -> -609.90975
B29: TOTALE ENTRATE | C29: =SUM(C15:C28) -> 2000 | F29: =SUMPRODUCT((D15:D28="FATTURA P.IVA")*(H15:H28="INCASSATO")*C15:C28*SETUP!$C$4*SETUP!$C$5) -> 17.55 | G29: =SUMPRODUCT((D15:D28="FATTURA P.IVA")*(H15:H28="INCASSATO")*(E15:E28="SI")*C15:C28*SETUP!$C$4*SETUP!$C$11) -> 50.8365
B31: 💸 USCITE
B32: CATEGORIA | C32: DESCRIZIONE | D32: IMPORTO € | E32: DATA | F32: PAGATO? | G32: NOTE
B33: SVAGO | C33: Bar | D33: 8.4
B34: SVAGO | C34: capodanno | D34: 200 | E34: 46023
B35: SVAGO | C35: bere | D35: 20
B36: SVAGO | C36: bere | D36: 10
B37: SVAGO | C37: Bar | D37: 8.4
B38: SVAGO | C38: Bere | D38: 67
B39: AUTO | C39: Gomme e convergenza | D39: 440
B40: SVAGO | C40: Poke | D40: 7.5
B41: AUTO | C41: cintura e manutenzione | D41: 70
B42: AUTO | C42: benzina | D42: 50
B43: SVAGO | C43: serata dema | D43: 30
B44: SVAGO | C44: Poke | D44: 25
B45: SVAGO | C45: Bar | D45: 2.8
...

Sheet FEBBRAIO
B2: FEBBRAIO 2026
B3: Il tuo netto reale spendibile questo mese
B4: =K93+K91-K95-K96 -> -242.72975
B5: =CONCATENATE("su €",TEXT(K92,"#,##0")," di fatturato P.IVA • €",TEXT(K94,"#,##0")," tra tasse e INPS già accantonati") -> su €250 di fatturato P.IVA • €394 tra tasse e INPS già accantonati
B7: FATTURATO P.IVA | D7: DA ACCANTONARE | F7: STATO MESE | I7: 🎯 RIEPILOGO MESE
B8: =K92 -> 250 | D8: =K94 -> 394.06 | F8: =IF(B4<0,"🔴 IN ROSSO",IF(K97>=0.2,"🟢 SANO",IF(K97>=0.1,"🟡 ATTENZIONE","🟠 SAVING BASSO"))) -> 🔴 IN ROSSO | I8: =IF(B4>=0,CONCATENATE("✅ €",TEXT(B4,"#,##0")," netti reali questo mese"),CONCATENATE("⚠ Sotto di €",TEXT(-B4,"#,##0")," questo mese")) -> ⚠ Sotto di €243 questo mese
B9: =CONCATENATE("+ €",TEXT(K91,"#,##0")," entrate private") -> + €1.450 entrate private | D9: =CONCATENATE("Tasse €",TEXT(F25,"#,##0")," + INPS €",TEXT(SETUP!$C$6,"#,##0")) -> Tasse €0 + INPS €384 | F9: =CONCATENATE("Saving rate ",TEXT(K97,"0.0%")) -> Saving rate -97,1%
B11: =CONCATENATE("⚠ Soglia INPS lordo annua: €",TEXT(SETUP!$C$8,"#,##0")," • Fatturato P.IVA mese: €",TEXT(K92,"#,##0")," • Vedi DASHBOARD per il monitoraggio annuale") -> ⚠ Soglia INPS lordo annua: €23.608 • Fatturato P.IVA mese: €250 • Vedi DASHBOARD per il monitoraggio annuale
B13: 💰 ENTRATE | I13: 🟢 ENTRATE INCASSATE
B14: CLIENTE / FONTE | C14: LORDO € | D14: TIPO | E14: CON SOCIO? | F14: TASSE 5% | G14: INPS SOCIO | H14: STATO | I14: Fatturato P.IVA | J14: =K92 -> 250
B15: FRUTTETO | C15: 500 | D15: ENTRATA PRIVATA (no tasse) | E15: NO | F15: =IF(D15="FATTURA P.IVA",C15*SETUP!$C$4*SETUP!$C$5,0) -> 0 | G15: =IF(AND(D15="FATTURA P.IVA",E15="SI"),C15*SETUP!$C$4*SETUP!$C$11,0) -> 0 | H15: INCASSATO | I15: Entrate Private | J15: =K91 -> 1450
B16: PIADINA | C16: 200 | D16: ENTRATA PRIVATA (no tasse) | E16: NO | F16: =IF(D16="FATTURA P.IVA",C16*SETUP!$C$4*SETUP!$C$5,0) -> 0 | G16: =IF(AND(D16="FATTURA P.IVA",E16="SI"),C16*SETUP!$C$4*SETUP!$C$11,0) -> 0 | H16: INCASSATO | I16: 🔵 ENTRATE PREVISTE
B17: PIADINA | C17: 250 | D17: FATTURA P.IVA | E17: SI | F17: =IF(D17="FATTURA P.IVA",C17*SETUP!$C$4*SETUP!$C$5,0) -> 9.75 | G17: =IF(AND(D17="FATTURA P.IVA",E17="SI"),C17*SETUP!$C$4*SETUP!$C$11,0) -> 50.8365 | H17: INCASSATO | I17: Fatturato emesso | J17: =K106 -> 0
B18: GOBBO | C18: 150 | D18: ENTRATA PRIVATA (no tasse) | E18: NO | F18: =IF(D18="FATTURA P.IVA",C18*SETUP!$C$4*SETUP!$C$5,0) -> 0 | G18: =IF(AND(D18="FATTURA P.IVA",E18="SI"),C18*SETUP!$C$4*SETUP!$C$11,0) -> 0 | H18: INCASSATO | I18: Pipeline programmata | J18: =K107 -> 0
B19: REGALI | C19: 600 | D19: ENTRATA PRIVATA (no tasse) | E19: NO | F19: =IF(D19="FATTURA P.IVA",C19*SETUP!$C$4*SETUP!$C$5,0) -> 0 | G19: =IF(AND(D19="FATTURA P.IVA",E19="SI"),C19*SETUP!$C$4*SETUP!$C$11,0) -> 0 | H19: INCASSATO | I19: Entrate Private previste | J19: =K108 -> 0
F20: =IF(D20="FATTURA P.IVA",C20*SETUP!$C$4*SETUP!$C$5,0) -> 0 | G20: =IF(AND(D20="FATTURA P.IVA",E20="SI"),C20*SETUP!$C$4*SETUP!$C$11,0) -> 0 | I20: 💰 TASSE & INPS
F21: =IF(D21="FATTURA P.IVA",C21*SETUP!$C$4*SETUP!$C$5,0) -> 0 | G21: =IF(AND(D21="FATTURA P.IVA",E21="SI"),C21*SETUP!$C$4*SETUP!$C$11,0) -> 0 | I21: Tasse 5% | J21: =F29 -> 9.75
F22: =IF(D22="FATTURA P.IVA",C22*SETUP!$C$4*SETUP!$C$5,0) -> 0 | G22: =IF(AND(D22="FATTURA P.IVA",E22="SI"),C22*SETUP!$C$4*SETUP!$C$11,0) -> 0 | I22: INPS Fisso (artig.) | J22: =SETUP!$C$6 -> 384.31
F23: =IF(D23="FATTURA P.IVA",C23*SETUP!$C$4*SETUP!$C$5,0) -> 0 | G23: =IF(AND(D23="FATTURA P.IVA",E23="SI"),C23*SETUP!$C$4*SETUP!$C$11,0) -> 0 | I23: INPS Socio (sim.) | J23: =G29 -> 50.8365
F24: =IF(D24="FATTURA P.IVA",C24*SETUP!$C$4*SETUP!$C$5,0) -> 0 | G24: =IF(AND(D24="FATTURA P.IVA",E24="SI"),C24*SETUP!$C$4*SETUP!$C$11,0) -> 0 | I24: 📤 USCITE & SAVING
F25: =IF(D25="FATTURA P.IVA",C25*SETUP!$C$4*SETUP!$C$5,0) -> 0 | G25: =IF(AND(D25="FATTURA P.IVA",E25="SI"),C25*SETUP!$C$4*SETUP!$C$11,0) -> 0 | I25: Tuo Netto P.IVA | J25: =K93 -> 94.70675
F26: =IF(D26="FATTURA P.IVA",C26*SETUP!$C$4*SETUP!$C$5,0) -> 0 | G26: =IF(AND(D26="FATTURA P.IVA",E26="SI"),C26*SETUP!$C$4*SETUP!$C$11,0) -> 0 | I26: Uscite effettive | J26: =D78 -> 1147.79
F27: =IF(D27="FATTURA P.IVA",C27*SETUP!$C$4*SETUP!$C$5,0) -> 0 | G27: =IF(AND(D27="FATTURA P.IVA",E27="SI"),C27*SETUP!$C$4*SETUP!$C$11,0) -> 0 | I27: Totale Secchielli | J27: =C92 -> 639.6465
F28: =IF(D28="FATTURA P.IVA",C28*SETUP!$C$4*SETUP!$C$5,0) -> 0 | G28: =IF(AND(D28="FATTURA P.IVA",E28="SI"),C28*SETUP!$C$4*SETUP!$C$11,0) -> 0 | I28: ✨ NETTO REALE | J28: =B4 -> -242.72975
B29: TOTALE ENTRATE | C29: =SUM(C15:C28) -> 1700 | F29: =SUMPRODUCT((D15:D28="FATTURA P.IVA")*(H15:H28="INCASSATO")*C15:C28*SETUP!$C$4*SETUP!$C$5) -> 9.75 | G29: =SUMPRODUCT((D15:D28="FATTURA P.IVA")*(H15:H28="INCASSATO")*(E15:E28="SI")*C15:C28*SETUP!$C$4*SETUP!$C$11) -> 50.8365
B31: 💸 USCITE
B32: CATEGORIA | C32: DESCRIZIONE | D32: IMPORTO € | E32: DATA | F32: PAGATO? | G32: NOTE
B33: SVAGO | C33: bar | D33: 9
B34: SVAGO | C34: bar | D34: 10.6
B35: SVAGO | C35: bere | D35: 6
B36: SVAGO | C36: bere | D36: 6
B37: SVAGO | C37: bar | D37: 9
B38: BUSINESS | C38: Template Adv metà | D38: 37 | E38: 46058
B39: SVAGO | C39: Benza | D39: 60
B40: SVAGO | C40: Bere | D40: 30 | E40: 46058
B41: AUTO | C41: carburante | D41: 60
B42: SVAGO | C42: principe | D42: 5.5 | E42: 46058
B43: SVAGO | C43: bar principe | D43: 1.5
B44: OBBLIGATORIE | C44: luciano riva barbiere | D44: 25 | E44: 46058
B45: BUSINESS | C45: attack | D45: 5
...

Sheet MARZO
B2: MARZO 2026
B3: Il tuo netto reale spendibile questo mese
B4: =K93+K91-K95-K96 -> -272.5547
B5: =CONCATENATE("su €",TEXT(K92,"#,##0")," di fatturato P.IVA • €",TEXT(K94,"#,##0")," tra tasse e INPS già accantonati") -> su €1.300 di fatturato P.IVA • €435 tra tasse e INPS già accantonati
B7: FATTURATO P.IVA | D7: DA ACCANTONARE | F7: STATO MESE | I7: 🎯 RIEPILOGO MESE
B8: =K92 -> 1300 | D8: =K94 -> 435.01 | F8: =IF(B4<0,"🔴 IN ROSSO",IF(K97>=0.2,"🟢 SANO",IF(K97>=0.1,"🟡 ATTENZIONE","🟠 SAVING BASSO"))) -> 🔴 IN ROSSO | I8: =IF(B4>=0,CONCATENATE("✅ €",TEXT(B4,"#,##0")," netti reali questo mese"),CONCATENATE("⚠ Sotto di €",TEXT(-B4,"#,##0")," questo mese")) -> ⚠ Sotto di €273 questo mese
B9: =CONCATENATE("+ €",TEXT(K91,"#,##0")," entrate private") -> + €1.450 entrate private | D9: =CONCATENATE("Tasse €",TEXT(F25,"#,##0")," + INPS €",TEXT(SETUP!$C$6,"#,##0")) -> Tasse €0 + INPS €384 | F9: =CONCATENATE("Saving rate ",TEXT(K97,"0.0%")) -> Saving rate -21,0%
B11: =CONCATENATE("⚠ Soglia INPS lordo annua: €",TEXT(SETUP!$C$8,"#,##0")," • Fatturato P.IVA mese: €",TEXT(K92,"#,##0")," • Vedi DASHBOARD per il monitoraggio annuale") -> ⚠ Soglia INPS lordo annua: €23.608 • Fatturato P.IVA mese: €1.300 • Vedi DASHBOARD per il monitoraggio annuale
B13: 💰 ENTRATE | I13: 🟢 ENTRATE INCASSATE
B14: CLIENTE / FONTE | C14: LORDO € | D14: TIPO | E14: CON SOCIO? | F14: TASSE 5% | G14: INPS SOCIO | H14: STATO | I14: Fatturato P.IVA | J14: =K92 -> 1300
B15: FRUTTETO | C15: 900 | D15: ENTRATA PRIVATA (no tasse) | E15: NO | F15: =IF(D15="FATTURA P.IVA",C15*SETUP!$C$4*SETUP!$C$5,0) -> 0 | G15: =IF(AND(D15="FATTURA P.IVA",E15="SI"),C15*SETUP!$C$4*SETUP!$C$11,0) -> 0 | H15: INCASSATO | I15: Entrate Private | J15: =K91 -> 1450
B16: PIADINA | C16: 200 | D16: ENTRATA PRIVATA (no tasse) | E16: NO | F16: =IF(D16="FATTURA P.IVA",C16*SETUP!$C$4*SETUP!$C$5,0) -> 0 | G16: =IF(AND(D16="FATTURA P.IVA",E16="SI"),C16*SETUP!$C$4*SETUP!$C$11,0) -> 0 | H16: INCASSATO | I16: 🔵 ENTRATE PREVISTE
B17: PIADINA | C17: 250 | D17: FATTURA P.IVA | E17: SI | F17: =IF(D17="FATTURA P.IVA",C17*SETUP!$C$4*SETUP!$C$5,0) -> 9.75 | G17: =IF(AND(D17="FATTURA P.IVA",E17="SI"),C17*SETUP!$C$4*SETUP!$C$11,0) -> 50.8365 | H17: INCASSATO | I17: Fatturato emesso | J17: =K106 -> 0
B18: GOBBO | C18: 150 | D18: ENTRATA PRIVATA (no tasse) | E18: NO | F18: =IF(D18="FATTURA P.IVA",C18*SETUP!$C$4*SETUP!$C$5,0) -> 0 | G18: =IF(AND(D18="FATTURA P.IVA",E18="SI"),C18*SETUP!$C$4*SETUP!$C$11,0) -> 0 | H18: INCASSATO | I18: Pipeline programmata | J18: =K107 -> 0
B19: DNG | C19: 550 | D19: FATTURA P.IVA | E19: SI | F19: =IF(D19="FATTURA P.IVA",C19*SETUP!$C$4*SETUP!$C$5,0) -> 21.45 | G19: =IF(AND(D19="FATTURA P.IVA",E19="SI"),C19*SETUP!$C$4*SETUP!$C$11,0) -> 111.8403 | H19: INCASSATO | I19: Entrate Private previste | J19: =K108 -> 0
B20: ROBE | C20: 500 | D20: FATTURA P.IVA | E20: SI | F20: =IF(D20="FATTURA P.IVA",C20*SETUP!$C$4*SETUP!$C$5,0) -> 19.5 | G20: =IF(AND(D20="FATTURA P.IVA",E20="SI"),C20*SETUP!$C$4*SETUP!$C$11,0) -> 101.673 | H20: INCASSATO | I20: 💰 TASSE & INPS
B21: DONG | C21: 200 | D21: ENTRATA PRIVATA (no tasse) | E21: NO | F21: =IF(D21="FATTURA P.IVA",C21*SETUP!$C$4*SETUP!$C$5,0) -> 0 | G21: =IF(AND(D21="FATTURA P.IVA",E21="SI"),C21*SETUP!$C$4*SETUP!$C$11,0) -> 0 | H21: INCASSATO | I21: Tasse 5% | J21: =F29 -> 50.7
F22: =IF(D22="FATTURA P.IVA",C22*SETUP!$C$4*SETUP!$C$5,0) -> 0 | G22: =IF(AND(D22="FATTURA P.IVA",E22="SI"),C22*SETUP!$C$4*SETUP!$C$11,0) -> 0 | I22: INPS Fisso (artig.) | J22: =SETUP!$C$6 -> 384.31
F23: =IF(D23="FATTURA P.IVA",C23*SETUP!$C$4*SETUP!$C$5,0) -> 0 | G23: =IF(AND(D23="FATTURA P.IVA",E23="SI"),C23*SETUP!$C$4*SETUP!$C$11,0) -> 0 | I23: INPS Socio (sim.) | J23: =G29 -> 264.3498
F24: =IF(D24="FATTURA P.IVA",C24*SETUP!$C$4*SETUP!$C$5,0) -> 0 | G24: =IF(AND(D24="FATTURA P.IVA",E24="SI"),C24*SETUP!$C$4*SETUP!$C$11,0) -> 0 | I24: 📤 USCITE & SAVING
F25: =IF(D25="FATTURA P.IVA",C25*SETUP!$C$4*SETUP!$C$5,0) -> 0 | G25: =IF(AND(D25="FATTURA P.IVA",E25="SI"),C25*SETUP!$C$4*SETUP!$C$11,0) -> 0 | I25: Tuo Netto P.IVA | J25: =K93 -> 492.4751
F26: =IF(D26="FATTURA P.IVA",C26*SETUP!$C$4*SETUP!$C$5,0) -> 0 | G26: =IF(AND(D26="FATTURA P.IVA",E26="SI"),C26*SETUP!$C$4*SETUP!$C$11,0) -> 0 | I26: Uscite effettive | J26: =D78 -> 1361.87
F27: =IF(D27="FATTURA P.IVA",C27*SETUP!$C$4*SETUP!$C$5,0) -> 0 | G27: =IF(AND(D27="FATTURA P.IVA",E27="SI"),C27*SETUP!$C$4*SETUP!$C$11,0) -> 0 | I27: Totale Secchielli | J27: =C92 -> 853.1598
F28: =IF(D28="FATTURA P.IVA",C28*SETUP!$C$4*SETUP!$C$5,0) -> 0 | G28: =IF(AND(D28="FATTURA P.IVA",E28="SI"),C28*SETUP!$C$4*SETUP!$C$11,0) -> 0 | I28: ✨ NETTO REALE | J28: =B4 -> -272.5547
B29: TOTALE ENTRATE | C29: =SUM(C15:C28) -> 2750 | F29: =SUMPRODUCT((D15:D28="FATTURA P.IVA")*(H15:H28="INCASSATO")*C15:C28*SETUP!$C$4*SETUP!$C$5) -> 50.7 | G29: =SUMPRODUCT((D15:D28="FATTURA P.IVA")*(H15:H28="INCASSATO")*(E15:E28="SI")*C15:C28*SETUP!$C$4*SETUP!$C$11) -> 264.3498
B31: 💸 USCITE
B32: CATEGORIA | C32: DESCRIZIONE | D32: IMPORTO € | E32: DATA | F32: PAGATO? | G32: NOTE
B33: BUSINESS | C33: schermo | D33: 180
B34: SVAGO | C34: piada | D34: 10
B35: BUSINESS | C35: KLING IA | D35: 7
B36: SVAGO | C36: pasqua | D36: 140
B37: BUSINESS | C37: schermo | D37: 180
B38: AUTO | C38: Benza | D38: 50
B39: SVAGO | C39: Colazione | D39: 5.8
B40: BUSINESS | C40: Replit | D40: 24.4
B41: SVAGO | C41: Bere | D41: 5
B42: SVAGO | C42: Cena | D42: 38
B43: SVAGO | C43: Cena | D43: 35
B44: AUTO | C44: Benza | D44: 40
... B65: BUSINESS | C65: REPLIT | D65: 4.23
...

Sheet APRILE
B2: APRILE 2026
B3: Il tuo netto reale spendibile questo mese
B4: =K93+K91-K95-K96 -> 118.92985
B5: =CONCATENATE("su €",TEXT(K92,"#,##0")," di fatturato P.IVA • €",TEXT(K94,"#,##0")," tra tasse e INPS già accantonati") -> su €1.850 di fatturato P.IVA • €456 tra tasse e INPS già accantonati
B7: FATTURATO P.IVA | D7: DA ACCANTONARE | F7: STATO MESE | I7: 🎯 RIEPILOGO MESE
B8: =K92 -> 1850 | D8: =K94 -> 456.46 | F8: =IF(B4<0,"🔴 IN ROSSO",IF(K97>=0.2,"🟢 SANO",IF(K97>=0.1,"🟡 ATTENZIONE","🟠 SAVING BASSO"))) -> 🟠 SAVING BASSO | I8: =IF(B4>=0,CONCATENATE("✅ €",TEXT(B4,"#,##0")," netti reali questo mese"),CONCATENATE("⚠ Sotto di €",TEXT(-B4,"#,##0")," questo mese")) -> ✅ €119 netti reali questo mese
B9: =CONCATENATE("+ €",TEXT(K91,"#,##0")," entrate private") -> + €1.138 entrate private | D9: =CONCATENATE("Tasse €",TEXT(F25,"#,##0")," + INPS €",TEXT(SETUP!$C$6,"#,##0")) -> Tasse €0 + INPS €384 | F9: =CONCATENATE("Saving rate ",TEXT(K97,"0.0%")) -> Saving rate 6,4%
B11: =CONCATENATE("⚠ Soglia INPS lordo annua: €",TEXT(SETUP!$C$8,"#,##0")," • Fatturato P.IVA mese: €",TEXT(K92,"#,##0")," • Vedi DASHBOARD per il monitoraggio annuale") -> ⚠ Soglia INPS lordo annua: €23.608 • Fatturato P.IVA mese: €1.850 • Vedi DASHBOARD per il monitoraggio annuale
B13: 💰 ENTRATE | I13: 🟢 ENTRATE INCASSATE
B14: CLIENTE / FONTE | C14: LORDO € | D14: TIPO | E14: CON SOCIO? | F14: TASSE 5% | G14: INPS SOCIO | H14: STATO | I14: Fatturato P.IVA | J14: =K92 -> 1850
B15: FRUTTETO | C15: 400 | D15: ENTRATA PRIVATA (no tasse) | E15: SI | F15: =IF(D15="FATTURA P.IVA",C15*SETUP!$C$4*SETUP!$C$5,0) -> 0 | G15: =IF(AND(D15="FATTURA P.IVA",E15="SI"),C15*SETUP!$C$4*SETUP!$C$11,0) -> 0 | H15: INCASSATO | I15: Entrate Private | J15: =K91 -> 1138
B16: PIADINA | C16: 250 | D16: FATTURA P.IVA | E16: SI | F16: =IF(D16="FATTURA P.IVA",C16*SETUP!$C$4*SETUP!$C$5,0) -> 9.75 | G16: =IF(AND(D16="FATTURA P.IVA",E16="SI"),C16*SETUP!$C$4*SETUP!$C$11,0) -> 50.8365 | H16: INCASSATO | I16: 🔵 ENTRATE PREVISTE
B17: PIADINA | C17: 200 | D17: ENTRATA PRIVATA (no tasse) | E17: NO | F17: =IF(D17="FATTURA P.IVA",C17*SETUP!$C$4*SETUP!$C$5,0) -> 0 | G17: =IF(AND(D17="FATTURA P.IVA",E17="SI"),C17*SETUP!$C$4*SETUP!$C$11,0) -> 0 | H17: INCASSATO | I17: Fatturato emesso | J17: =K106 -> 1500
B18: GOBBO | C18: 150 | D18: ENTRATA PRIVATA (no tasse) | E18: NO | F18: =IF(D18="FATTURA P.IVA",C18*SETUP!$C$4*SETUP!$C$5,0) -> 0 | G18: =IF(AND(D18="FATTURA P.IVA",E18="SI"),C18*SETUP!$C$4*SETUP!$C$11,0) -> 0 | H18: INCASSATO | I18: Pipeline programmata | J18: =K107 -> 0
B19: DNG | C19: 550 | D19: FATTURA P.IVA | E19: SI | F19: =IF(D19="FATTURA P.IVA",C19*SETUP!$C$4*SETUP!$C$5,0) -> 21.45 | G19: =IF(AND(D19="FATTURA P.IVA",E19="SI"),C19*SETUP!$C$4*SETUP!$C$11,0) -> 111.8403 | H19: INCASSATO | I19: Entrate Private previste | J19: =K108 -> 0
B20: k2 | C20: 550 | D20: FATTURA P.IVA | E20: SI | F20: =IF(D20="FATTURA P.IVA",C20*SETUP!$C$4*SETUP!$C$5,0) -> 21.45 | G20: =IF(AND(D20="FATTURA P.IVA",E20="SI"),C20*SETUP!$C$4*SETUP!$C$11,0) -> 111.8403 | H20: INCASSATO | I20: 💰 TASSE & INPS
B21: ROBE | C21: 500 | D21: FATTURA P.IVA | E21: SI | F21: =IF(D21="FATTURA P.IVA",C21*SETUP!$C$4*SETUP!$C$5,0) -> 19.5 | G21: =IF(AND(D21="FATTURA P.IVA",E21="SI"),C21*SETUP!$C$4*SETUP!$C$11,0) -> 101.673 | H21: INCASSATO | I21: Tasse 5% | J21: =F29 -> 72.15
B22: FROZEN | C22: 308 | D22: ENTRATA PRIVATA (no tasse) | E22: NO | F22: =IF(D22="FATTURA P.IVA",C22*SETUP!$C$4*SETUP!$C$5,0) -> 0 | G22: =IF(AND(D22="FATTURA P.IVA",E22="SI"),C22*SETUP!$C$4*SETUP!$C$11,0) -> 0 | H22: INCASSATO | I22: INPS Fisso (artig.) | J22: =SETUP!$C$6 -> 384.31
B23: ELEVEN | C23: 700 | D23: FATTURA P.IVA | E23: NO | F23: =IF(D23="FATTURA P.IVA",C23*SETUP!$C$4*SETUP!$C$5,0) -> 27.3 | G23: =IF(AND(D23="FATTURA P.IVA",E23="SI"),C23*SETUP!$C$4*SETUP!$C$11,0) -> 0 | H23: FATTURATO | I23: INPS Socio (sim.) | J23: =G29 -> 376.1901
B24: ORIOKY | C24: 800 | D24: FATTURA P.IVA | E24: SI | F24: =IF(D24="FATTURA P.IVA",C24*SETUP!$C$4*SETUP!$C$5,0) -> 31.2 | G24: =IF(AND(D24="FATTURA P.IVA",E24="SI"),C24*SETUP!$C$4*SETUP!$C$11,0) -> 162.6768 | H24: FATTURATO | I24: 📤 USCITE & SAVING
B25: BARBOLINI | C25: 80 | D25: ENTRATA PRIVATA (no tasse) | E25: NO | F25: =IF(D25="FATTURA P.IVA",C25*SETUP!$C$4*SETUP!$C$5,0) -> 0 | G25: =IF(AND(D25="FATTURA P.IVA",E25="SI"),C25*SETUP!$C$4*SETUP!$C$11,0) -> 0 | I25: Tuo Netto P.IVA | J25: =K93 -> 700.82995
F26: =IF(D26="FATTURA P.IVA",C26*SETUP!$C$4*SETUP!$C$5,0) -> 0 | G26: =IF(AND(D26="FATTURA P.IVA",E26="SI"),C26*SETUP!$C$4*SETUP!$C$11,0) -> 0 | I26: Uscite effettive | J26: =D78 -> 754.9
F27: =IF(D27="FATTURA P.IVA",C27*SETUP!$C$4*SETUP!$C$5,0) -> 0 | G27: =IF(AND(D27="FATTURA P.IVA",E27="SI"),C27*SETUP!$C$4*SETUP!$C$11,0) -> 0 | I27: Totale Secchielli | J27: =C92 -> 965.0001
F28: =IF(D28="FATTURA P.IVA",C28*SETUP!$C$4*SETUP!$C$5,0) -> 0 | G28: =IF(AND(D28="FATTURA P.IVA",E28="SI"),C28*SETUP!$C$4*SETUP!$C$11,0) -> 0 | I28: ✨ NETTO REALE | J28: =B4 -> 118.92985
B29: TOTALE ENTRATE | C29: =SUM(C15:C28) -> 4488 | F29: =SUMPRODUCT((D15:D28="FATTURA P.IVA")*(H15:H28="INCASSATO")*C15:C28*SETUP!$C$4*SETUP!$C$5) -> 72.15 | G29: =SUMPRODUCT((D15:D28="FATTURA P.IVA")*(H15:H28="INCASSATO")*(E15:E28="SI")*C15:C28*SETUP!$C$4*SETUP!$C$11) -> 376.1901
B31: 💸 USCITE
B32: CATEGORIA | C32: DESCRIZIONE | D32: IMPORTO € | E32: DATA | F32: PAGATO? | G32: NOTE
B33: SVAGO | C33: Bere | D33: 24
B34: SVAGO | C34: Mima | D34: 100
B35: SVAGO | C35: Autostrada | D35: 17
B36: SVAGO | C36: Bar | D36: 5
B37: SVAGO | C37: Bere | D37: 24
B38: AUTO | C38: Benza | D38: 50
B39: SVAGO | C39: Puff | D39: 10
B40: SVAGO | C40: profumo | D40: 54
B41: SVAGO | C41: birra | D41: 5
B42: SVAGO | C42: pizza | D42: 3
B43: SVAGO | C43: bingo | D43: 3
B44: SVAGO | C44: gioco bmx street | D44: 28
... B66: SVAGO | C66: bacca di caffe | D66: 5.3
...

Sheet MAGGIO
B2: MAGGIO 2026
B3: Il tuo netto reale spendibile questo mese
B4: =K93+K91-K95-K96 -> 6145.6502
B5: =CONCATENATE("su €",TEXT(K92,"#,##0")," di fatturato P.IVA • €",TEXT(K94,"#,##0")," tra tasse e INPS già accantonati") -> su €250 di fatturato P.IVA • €394 tra tasse e INPS già accantonati
B7: FATTURATO P.IVA | D7: DA ACCANTONARE | F7: STATO MESE | I7: 🎯 RIEPILOGO MESE
B8: =K92 -> 250 | D8: =K94 -> 394.06 | F8: =IF(B4<0,"🔴 IN ROSSO",IF(K98>=0.2,"🟢 SANO",IF(K98>=0.1,"🟡 ATTENZIONE","🟠 SAVING BASSO"))) -> 🟠 SAVING BASSO | I8: =IF(B4>=0,CONCATENATE("✅ €",TEXT(B4,"#,##0")," netti reali questo mese"),CONCATENATE("⚠ Sotto di €",TEXT(-B4,"#,##0")," questo mese")) -> ✅ €6.146 netti reali questo mese
B9: =CONCATENATE("+ €",TEXT(K92,"#,##0")," entrate private") -> + €250 entrate private | D9: =CONCATENATE("Tasse €",TEXT(F26,"#,##0")," + INPS €",TEXT(SETUP!$C$6,"#,##0")) -> Tasse €0 + INPS €384 | F9: =CONCATENATE("Saving rate ",TEXT(K98,"0.0%")) -> Saving rate 0,0%
B11: =CONCATENATE("⚠ Soglia INPS lordo annua: €",TEXT(SETUP!$C$8,"#,##0")," • Fatturato P.IVA mese: €",TEXT(K93,"#,##0")," • Vedi DASHBOARD per il monitoraggio annuale") -> ⚠ Soglia INPS lordo annua: €23.608 • Fatturato P.IVA mese: €95 • Vedi DASHBOARD per il monitoraggio annuale
B13: 💰 ENTRATE | I13: 🟢 ENTRATE INCASSATE
B14: CLIENTE / FONTE | C14: LORDO € | D14: TIPO | E14: CON SOCIO? | F14: TASSE 5% | G14: INPS SOCIO | H14: STATO | I14: Fatturato P.IVA | J14: =K92 -> 250
B15: FRUTTETO | C15: 500 | D15: ENTRATA PRIVATA (no tasse) | E15: NO | F15: =IF(D15="FATTURA P.IVA",C15*SETUP!$C$4*SETUP!$C$5,0) -> 0 | G15: =IF(AND(D15="FATTURA P.IVA",E15="SI"),C15*SETUP!$C$4*SETUP!$C$11,0) -> 0 | H15: FATTURATO | I15: Entrate Private | J15: =K91 -> 7058
B16: PIADINA | C16: 250 | D16: FATTURA P.IVA | E16: SI | F16: =IF(D16="FATTURA P.IVA",C16*SETUP!$C$4*SETUP!$C$5,0) -> 9.75 | G16: =IF(AND(D16="FATTURA P.IVA",E16="SI"),C16*SETUP!$C$4*SETUP!$C$11,0) -> 50.8365 | H16: INCASSATO | I16: 🔵 ENTRATE PREVISTE
B17: PIADINA | C17: 200 | D17: ENTRATA PRIVATA (no tasse) | E17: NO | F17: =IF(D17="FATTURA P.IVA",C17*SETUP!$C$4*SETUP!$C$5,0) -> 0 | G17: =IF(AND(D17="FATTURA P.IVA",E17="SI"),C17*SETUP!$C$4*SETUP!$C$11,0) -> 0 | H17: FATTURATO | I17: Fatturato emesso | J17: =K106 -> 2050
B18: GOBBO | C18: 150 | D18: ENTRATA PRIVATA (no tasse) | E18: NO | F18: =IF(D18="FATTURA P.IVA",C18*SETUP!$C$4*SETUP!$C$5,0) -> 0 | G18: =IF(AND(D18="FATTURA P.IVA",E18="SI"),C18*SETUP!$C$4*SETUP!$C$11,0) -> 0 | H18: FATTURATO | I18: Pipeline programmata | J18: =K107 -> 0
B19: DNG | C19: 550 | D19: FATTURA P.IVA | E19: SI | F19: =IF(D19="FATTURA P.IVA",C19*SETUP!$C$4*SETUP!$C$5,0) -> 21.45 | G19: =IF(AND(D19="FATTURA P.IVA",E19="SI"),C19*SETUP!$C$4*SETUP!$C$11,0) -> 111.8403 | H19: FATTURATO | I19: Entrate Private previste | J19: =K108 -> 0
B20: k2 | C20: 550 | D20: FATTURA P.IVA | E20: SI | F20: =IF(D20="FATTURA P.IVA",C20*SETUP!$C$4*SETUP!$C$5,0) -> 21.45 | G20: =IF(AND(D20="FATTURA P.IVA",E20="SI"),C20*SETUP!$C$4*SETUP!$C$11,0) -> 111.8403 | H20: FATTURATO | I20: 💰 TASSE & INPS
B21: ROBE | C21: 500 | D21: FATTURA P.IVA | E21: SI | F21: =IF(D21="FATTURA P.IVA",C21*SETUP!$C$4*SETUP!$C$5,0) -> 19.5 | G21: =IF(AND(D21="FATTURA P.IVA",E21="SI"),C21*SETUP!$C$4*SETUP!$C$11,0) -> 101.673 | H21: FATTURATO | I21: Tasse 5% | J21: =F29 -> 9.75
B22: FROZEN | C22: 308 | D22: ENTRATA PRIVATA (no tasse) | E22: NO | F22: =IF(D22="FATTURA P.IVA",C22*SETUP!$C$4*SETUP!$C$5,0) -> 0 | G22: =IF(AND(D22="FATTURA P.IVA",E22="SI"),C22*SETUP!$C$4*SETUP!$C$11,0) -> 0 | H22: FATTURATO | I22: INPS Fisso (artig.) | J22: =SETUP!$C$6 -> 384.31
B23: ORIOKY | C23: 450 | D23: FATTURA P.IVA | E23: NO | F23: =IF(D23="FATTURA P.IVA",C23*SETUP!$C$4*SETUP!$C$5,0) -> 17.55 | G23: =IF(AND(D23="FATTURA P.IVA",E23="SI"),C23*SETUP!$C$4*SETUP!$C$11,0) -> 0 | H23: FATTURATO | I23: INPS Socio (sim.) | J23: =G29 -> 50.8365
B24: DONG | C24: 150 | D24: ENTRATA PRIVATA (no tasse) | E24: SI | F24: =IF(D24="FATTURA P.IVA",C24*SETUP!$C$4*SETUP!$C$5,0) -> 0 | G24: =IF(AND(D24="FATTURA P.IVA",E24="SI"),C24*SETUP!$C$4*SETUP!$C$11,0) -> 0 | H24: FATTURATO | I24: 📤 USCITE & SAVING
B25: RUBIERA | C25: 250 | D25: ENTRATA PRIVATA (no tasse) | E25: SI | F25: =IF(D25="FATTURA P.IVA",C25*SETUP!$C$4*SETUP!$C$5,0) -> 0 | G25: =IF(AND(D25="FATTURA P.IVA",E25="SI"),C25*SETUP!$C$4*SETUP!$C$11,0) -> 0 | H25: FATTURATO | I25: Tuo Netto P.IVA | J25: =K93 -> 94.70675
B26: MOTO | C26: 5500 | D26: ENTRATA PRIVATA (no tasse) | E26: NO | F26: =IF(D26="FATTURA P.IVA",C26*SETUP!$C$4*SETUP!$C$5,0) -> 0 | G26: =IF(AND(D26="FATTURA P.IVA",E26="SI"),C26*SETUP!$C$4*SETUP!$C$11,0) -> 0 | H26: INCASSATO | I26: Uscite effettive | J26: =D78 -> 367.41
F27: =IF(D27="FATTURA P.IVA",C27*SETUP!$C$4*SETUP!$C$5,0) -> 0 | G27: =IF(AND(D27="FATTURA P.IVA",E27="SI"),C27*SETUP!$C$4*SETUP!$C$11,0) -> 0 | I27: Totale Secchielli | J27: =C92 -> 639.6465
F28: =IF(D28="FATTURA P.IVA",C28*SETUP!$C$4*SETUP!$C$5,0) -> 0 | G28: =IF(AND(D28="FATTURA P.IVA",E28="SI"),C28*SETUP!$C$4*SETUP!$C$11,0) -> 0 | I28: ✨ NETTO REALE | J28: =B4 -> 6145.6502
B29: TOTALE ENTRATE | C29: =SUM(C15:C28) -> 9358 | D29: IMPORTO € | E29: DATA | F29: =SUMPRODUCT((D15:D28="FATTURA P.IVA")*(H15:H28="INCASSATO")*C15:C28*SETUP!$C$4*SETUP!$C$5) -> 9.75 | G29: =SUMPRODUCT((D15:D28="FATTURA P.IVA")*(H15:H28="INCASSATO")*(E15:E28="SI")*C15:C28*SETUP!$C$4*SETUP!$C$11) -> 50.8365
B31: 💸 USCITE
B32: CATEGORIA | C32: DESCRIZIONE | D32: IMPORTO € | E32: DATA | F32: PAGATO? | G32: NOTE
B33: SVAGO | C33: Gobbo con Dema | D33: 7 | E33: 46149
B34: SVAGO | C34: PIADA | D34: 15
B35: SVAGO | C35: Claude ( si rinnova) | D35: 21.5 | F35: PROGRAMMATA
B36: SVAGO | C36: Gobbo con Dema | D36: 7 | E36: 46149 | F36: PROGRAMMATA
B37: SVAGO | C37: barbiere | D37: 25 | F37: PROGRAMMATA
B38: BUSINESS | C38: canva ( scad 19/12/26) | D38: 4.5 | F38: PROGRAMMATA
B39: BUSINESS | C39: cupcut (scad 23/12/26) | D39: 8.3 | E39: 46150 | F39: PROGRAMMATA
B40: BUSINESS | C40: google business mensile | D40: 15.81 | F40: PROGRAMMATA
B41: SVAGO | C41: BERE | D41: 15
B42: BUSINESS | C42: ADOBE | D42: 20.5 | E42: 46150 | F42: PROGRAMMATA
B43: BUSINESS | C43: ANTROPIC | D43: 24.4
B44: BUSINESS | C44: ANTROPIC | D44: 21.96
B45: SVAGO | C45: BAR | D45: 8
...

Sheet GIUGNO
B2: GIUGNO 2026
B3: Il tuo netto reale spendibile questo mese
B4: =K93+K91-K95-K96 -> 319.19
B5: =CONCATENATE("su €",TEXT(K92,"#,##0")," di fatturato P.IVA • €",TEXT(K94,"#,##0")," tra tasse e INPS già accantonati") -> su €0 di fatturato P.IVA • €384 tra tasse e INPS già accantonati
B7: FATTURATO P.IVA | D7: DA ACCANTONARE | F7: STATO MESE | I7: 🎯 RIEPILOGO MESE
B8: =K92 -> 0 | D8: =K94 -> 384.31 | F8: =IF(B4<0,"🔴 IN ROSSO",IF(K97>=0.2,"🟢 SANO",IF(K97>=0.1,"🟡 ATTENZIONE","🟠 SAVING BASSO"))) -> 🟠 SAVING BASSO | I8: =IF(B4>=0,CONCATENATE("✅ €",TEXT(B4,"#,##0")," netti reali questo mese"),CONCATENATE("⚠ Sotto di €",TEXT(-B4,"#,##0")," questo mese")) -> ✅ €319 netti reali questo mese
B9: =CONCATENATE("+ €",TEXT(K91,"#,##0")," entrate private") -> + €908 entrate private | D9: =CONCATENATE("Tasse €",TEXT(F25,"#,##0")," + INPS €",TEXT(SETUP!$C$6,"#,##0")) -> Tasse €0 + INPS €384 | F9: =CONCATENATE("Saving rate ",TEXT(K97,"0.0%")) -> Saving rate 0,0%
B11: =CONCATENATE("⚠ Soglia INPS lordo annua: €",TEXT(SETUP!$C$8,"#,##0")," • Fatturato P.IVA mese: €",TEXT(K92,"#,##0")," • Vedi DASHBOARD per il monitoraggio annuale") -> ⚠ Soglia INPS lordo annua: €23.608 • Fatturato P.IVA mese: €0 • Vedi DASHBOARD per il monitoraggio annuale
B13: 💰 ENTRATE | I13: 🟢 ENTRATE INCASSATE
B14: CLIENTE / FONTE | C14: LORDO € | D14: TIPO | E14: CON SOCIO? | F14: TASSE 5% | G14: INPS SOCIO | H14: STATO | I14: Fatturato P.IVA | J14: =K92 -> 0
B15: FRUTTETO | C15: 400 | D15: ENTRATA PRIVATA (no tasse) | F15: =IF(D15="FATTURA P.IVA",C15*SETUP!$C$4*SETUP!$C$5,0) -> 0 | G15: =IF(AND(D15="FATTURA P.IVA",E15="SI"),C15*SETUP!$C$4*SETUP!$C$11,0) -> 0 | H15: PROGRAMMATO | I15: Entrate Private | J15: =K91 -> 908
B16: PIADINA | C16: 250 | D16: FATTURA P.IVA | E16: SI | F16: =IF(D16="FATTURA P.IVA",C16*SETUP!$C$4*SETUP!$C$5,0) -> 9.75 | G16: =IF(AND(D16="FATTURA P.IVA",E16="SI"),C16*SETUP!$C$4*SETUP!$C$11,0) -> 50.8365 | H16: PROGRAMMATO | I16: 🔵 ENTRATE PREVISTE
B17: PIADINA | C17: 200 | D17: ENTRATA PRIVATA (no tasse) | E17: NO | F17: =IF(D17="FATTURA P.IVA",C17*SETUP!$C$4*SETUP!$C$5,0) -> 0 | G17: =IF(AND(D17="FATTURA P.IVA",E17="SI"),C17*SETUP!$C$4*SETUP!$C$11,0) -> 0 | H17: PROGRAMMATO | I17: Fatturato emesso | J17: =K106 -> 0
B18: DNG | C18: 550 | D18: FATTURA P.IVA | E18: SI | F18: =IF(D18="FATTURA P.IVA",C18*SETUP!$C$4*SETUP!$C$5,0) -> 21.45 | G18: =IF(AND(D18="FATTURA P.IVA",E18="SI"),C18*SETUP!$C$4*SETUP!$C$11,0) -> 111.8403 | H18: PROGRAMMATO | I18: Pipeline programmata | J18: =K107 -> 3450
B19: k2 | C19: 550 | D19: FATTURA P.IVA | E19: SI | F19: =IF(D19="FATTURA P.IVA",C19*SETUP!$C$4*SETUP!$C$5,0) -> 21.45 | G19: =IF(AND(D19="FATTURA P.IVA",E19="SI"),C19*SETUP!$C$4*SETUP!$C$11,0) -> 111.8403 | H19: PROGRAMMATO | I19: Entrate Private previste | J19: =K108 -> 0
B20: ROBE | C20: 500 | D20: FATTURA P.IVA | E20: SI | F20: =IF(D20="FATTURA P.IVA",C20*SETUP!$C$4*SETUP!$C$5,0) -> 19.5 | G20: =IF(AND(D20="FATTURA P.IVA",E20="SI"),C20*SETUP!$C$4*SETUP!$C$11,0) -> 101.673 | H20: PROGRAMMATO | I20: 💰 TASSE & INPS
B21: FROZEN | C21: 308 | D21: ENTRATA PRIVATA (no tasse) | E21: NO | F21: =IF(D21="FATTURA P.IVA",C21*SETUP!$C$4*SETUP!$C$5,0) -> 0 | G21: =IF(AND(D21="FATTURA P.IVA",E21="SI"),C21*SETUP!$C$4*SETUP!$C$11,0) -> 0 | H21: PROGRAMMATO | I21: Tasse 5% | J21: =F29 -> 0
B22: FRUTTETO | C22: 650 | D22: FATTURA P.IVA | E22: NO | F22: =IF(D22="FATTURA P.IVA",C22*SETUP!$C$4*SETUP!$C$5,0) -> 25.35 | G22: =IF(AND(D22="FATTURA P.IVA",E22="SI"),C22*SETUP!$C$4*SETUP!$C$11,0) -> 0 | H22: PROGRAMMATO | I22: INPS Fisso (artig.) | J22: =SETUP!$C$6 -> 384.31
B23: NEXTER | C23: 950 | D23: FATTURA P.IVA | E23: SI | F23: =IF(D23="FATTURA P.IVA",C23*SETUP!$C$4*SETUP!$C$5,0) -> 37.05 | G23: =IF(AND(D23="FATTURA P.IVA",E23="SI"),C23*SETUP!$C$4*SETUP!$C$11,0) -> 193.1787 | H23: PROGRAMMATO | I23: INPS Socio (sim.) | J23: =G29 -> 0
F24: =IF(D24="FATTURA P.IVA",C24*SETUP!$C$4*SETUP!$C$5,0) -> 0 | G24: =IF(AND(D24="FATTURA P.IVA",E24="SI"),C24*SETUP!$C$4*SETUP!$C$11,0) -> 0 | I24: 📤 USCITE & SAVING
F25: =IF(D25="FATTURA P.IVA",C25*SETUP!$C$4*SETUP!$C$5,0) -> 0 | G25: =IF(AND(D25="FATTURA P.IVA",E25="SI"),C25*SETUP!$C$4*SETUP!$C$11,0) -> 0 | I25: Tuo Netto P.IVA | J25: =K93 -> 0
F26: =IF(D26="FATTURA P.IVA",C26*SETUP!$C$4*SETUP!$C$5,0) -> 0 | G26: =IF(AND(D26="FATTURA P.IVA",E26="SI"),C26*SETUP!$C$4*SETUP!$C$11,0) -> 0 | I26: Uscite effettive | J26: =D78 -> 0
F27: =IF(D27="FATTURA P.IVA",C27*SETUP!$C$4*SETUP!$C$5,0) -> 0 | G27: =IF(AND(D27="FATTURA P.IVA",E27="SI"),C27*SETUP!$C$4*SETUP!$C$11,0) -> 0 | I27: Totale Secchielli | J27: =C92 -> 588.81
F28: =IF(D28="FATTURA P.IVA",C28*SETUP!$C$4*SETUP!$C$5,0) -> 0 | G28: =IF(AND(D28="FATTURA P.IVA",E28="SI"),C28*SETUP!$C$4*SETUP!$C$11,0) -> 0 | I28: ✨ NETTO REALE | J28: =B4 -> 319.19
B29: TOTALE ENTRATE | C29: =SUM(C15:C28) -> 4358 | F29: =SUMPRODUCT((D15:D28="FATTURA P.IVA")*(H15:H28="INCASSATO")*C15:C28*SETUP!$C$4*SETUP!$C$5) -> 0 | G29: =SUMPRODUCT((D15:D28="FATTURA P.IVA")*(H15:H28="INCASSATO")*(E15:E28="SI")*C15:C28*SETUP!$C$4*SETUP!$C$11) -> 0
B31: 💸 USCITE
B32: CATEGORIA | C32: DESCRIZIONE | D32: IMPORTO € | E32: DATA | F32: PAGATO? | G32: NOTE
B34: BUSINESS | C34: canva ( scad 19/12/26) | D34: 4.5 | F34: PROGRAMMATA
B35: BUSINESS | C35: cupcut (scad 23/12/26) | D35: 8.3 | F35: PROGRAMMATA
B36: BUSINESS | C36: google business mensile | D36: 7.81 | F36: PROGRAMMATA
B78: TOTALE USCITE EFFETTIVE | D78: =SUMPRODUCT((F33:F77<>"NO")*(F33:F77<>"PROGRAMMATA")*D33:D77) -> 0 | H78: DA VERSARE
B80: 🪣 SECCHIELLI / SAVING (PAC, fondi, investimenti) | H80: DA VERSARE
B81: OBIETTIVO / SECCHIELLO | C81: IMPORTO € | D81: FEE/SPREAD € | E81: DATA | F81: NOTE | H81: VERSATO?
B82: PAC 1 — Mediolanum Cina | C82: 75 | D82: =IFERROR(C82*VLOOKUP($B82,INVESTIMENTI!$B$23:$E$32,4,FALSE()),0) -> 2.25 | H82: DA VERSARE
B83: PAC 2 — Mediolanum India | C83: 75 | D83: =IFERROR(C83*VLOOKUP($B83,INVESTIMENTI!$B$23:$E$32,4,FALSE()),0) -> 2.25 | H83: DA VERSARE
B84: Polizza Vita Mediolanum | C84: 50 | D84: =IFERROR(C84*VLOOKUP($B84,INVESTIMENTI!$B$23:$E$32,4,FALSE()),0) -> 0 | H84: DA VERSARE
B85: QUOTA SOCIO — conguaglio | C85: =G29 -> 0 | D85: 0 | H85: DA VERSARE
B86: INPS Trimestrale (acconto) | C86: =SETUP!$C$6 -> 384.31 | D86: 0 | H86: DA VERSARE
D87: =IFERROR(C87*VLOOKUP($B87,INVESTIMENTI!$B$23:$E$32,4,FALSE()),0) -> 0
D90: =IFERROR(C90*VLOOKUP($B90,INVESTIMENTI!$B$23:$E$32,4,FALSE()),0) -> 0
...

Sheet LUGLIO
B2: LUGLIO 2026
B3: Il tuo netto reale spendibile questo mese
B4: =K93+K91-K95-K96 -> 319.19
B5: =CONCATENATE("su €",TEXT(K92,"#,##0")," di fatturato P.IVA • €",TEXT(K94,"#,##0")," tra tasse e INPS già accantonati") -> su €0 di fatturato P.IVA • €384 tra tasse e INPS già accantonati
B7: FATTURATO P.IVA | D7: DA ACCANTONARE | F7: STATO MESE | I7: 🎯 RIEPILOGO MESE
B8: =K92 -> 0 | D8: =K94 -> 384.31 | F8: =IF(B4<0,"🔴 IN ROSSO",IF(K97>=0.2,"🟢 SANO",IF(K97>=0.1,"🟡 ATTENZIONE","🟠 SAVING BASSO"))) -> 🟠 SAVING BASSO | I8: =IF(B4>=0,CONCATENATE("✅ €",TEXT(B4,"#,##0")," netti reali questo mese"),CONCATENATE("⚠ Sotto di €",TEXT(-B4,"#,##0")," questo mese")) -> ✅ €319 netti reali questo mese
B9: =CONCATENATE("+ €",TEXT(K91,"#,##0")," entrate private") -> + €908 entrate private | D9: =CONCATENATE("Tasse €",TEXT(F25,"#,##0")," + INPS €",TEXT(SETUP!$C$6,"#,##0")) -> Tasse €0 + INPS €384 | F9: =CONCATENATE("Saving rate ",TEXT(K97,"0.0%")) -> Saving rate 0,0%
B11: =CONCATENATE("⚠ Soglia INPS lordo annua: €",TEXT(SETUP!$C$8,"#,##0")," • Fatturato P.IVA mese: €",TEXT(K92,"#,##0")," • Vedi DASHBOARD per il monitoraggio annuale") -> ⚠ Soglia INPS lordo annua: €23.608 • Fatturato P.IVA mese: €0 • Vedi DASHBOARD per il monitoraggio annuale
B13: 💰 ENTRATE | I13: 🟢 ENTRATE INCASSATE
B14: CLIENTE / FONTE | C14: LORDO € | D14: TIPO | E14: CON SOCIO? | F14: TASSE 5% | G14: INPS SOCIO | H14: STATO | I14: Fatturato P.IVA | J14: =K92 -> 0
B15: FRUTTETO | C15: 400 | D15: ENTRATA PRIVATA (no tasse) | E15: NO | F15: =IF(D15="FATTURA P.IVA",C15*SETUP!$C$4*SETUP!$C$5,0) -> 0 | G15: =IF(AND(D15="FATTURA P.IVA",E15="SI"),C15*SETUP!$C$4*SETUP!$C$11,0) -> 0 | H15: PROGRAMMATO | I15: Entrate Private | J15: =K91 -> 908
B16: PIADINA | C16: 250 | D16: FATTURA P.IVA | E16: SI | F16: =IF(D16="FATTURA P.IVA",C16*SETUP!$C$4*SETUP!$C$5,0) -> 9.75 | G16: =IF(AND(D16="FATTURA P.IVA",E16="SI"),C16*SETUP!$C$4*SETUP!$C$11,0) -> 50.8365 | H16: PROGRAMMATO | I16: 🔵 ENTRATE PREVISTE
B17: PIADINA | C17: 200 | D17: ENTRATA PRIVATA (no tasse) | E17: NO | F17: =IF(D17="FATTURA P.IVA",C17*SETUP!$C$4*SETUP!$C$5,0) -> 0 | G17: =IF(AND(D17="FATTURA P.IVA",E17="SI"),C17*SETUP!$C$4*SETUP!$C$11,0) -> 0 | H17: PROGRAMMATO | I17: Fatturato emesso | J17: =K106 -> 0
B18: ROBE | C18: 500 | D18: FATTURA P.IVA | E18: SI | F18: =IF(D18="FATTURA P.IVA",C18*SETUP!$C$4*SETUP!$C$5,0) -> 19.5 | G18: =IF(AND(D18="FATTURA P.IVA",E18="SI"),C18*SETUP!$C$4*SETUP!$C$11,0) -> 101.673 | H18: PROGRAMMATO | I18: Pipeline programmata | J18: =K107 -> 2500
B19: FROZEN | C19: 308 | D19: ENTRATA PRIVATA (no tasse) | E19: NO | F19: =IF(D19="FATTURA P.IVA",C19*SETUP!$C$4*SETUP!$C$5,0) -> 0 | G19: =IF(AND(D19="FATTURA P.IVA",E19="SI"),C19*SETUP!$C$4*SETUP!$C$11,0) -> 0 | H19: PROGRAMMATO | I19: Entrate Private previste | J19: =K108 -> 0
B20: k2 | C20: 550 | D20: FATTURA P.IVA | E20: SI | F20: =IF(D20="FATTURA P.IVA",C20*SETUP!$C$4*SETUP!$C$5,0) -> 21.45 | G20: =IF(AND(D20="FATTURA P.IVA",E20="SI"),C20*SETUP!$C$4*SETUP!$C$11,0) -> 111.8403 | H20: PROGRAMMATO | I20: 💰 TASSE & INPS
B21: DNG | C21: 550 | D21: FATTURA P.IVA | E21: SI | F21: =IF(D21="FATTURA P.IVA",C21*SETUP!$C$4*SETUP!$C$5,0) -> 21.45 | G21: =IF(AND(D21="FATTURA P.IVA",E21="SI"),C21*SETUP!$C$4*SETUP!$C$11,0) -> 111.8403 | H21: PROGRAMMATO | I21: Tasse 5% | J21: =F29 -> 0
B22: FRUTTETO | C22: 650 | D22: FATTURA P.IVA | E22: NO | F22: =IF(D22="FATTURA P.IVA",C22*SETUP!$C$4*SETUP!$C$5,0) -> 25.35 | G22: =IF(AND(D22="FATTURA P.IVA",E22="SI"),C22*SETUP!$C$4*SETUP!$C$11,0) -> 0 | I22: INPS Fisso (artig.) | J22: =SETUP!$C$6 -> 384.31
F23: =IF(D23="FATTURA P.IVA",C23*SETUP!$C$4*SETUP!$C$5,0) -> 0 | G23: =IF(AND(D23="FATTURA P.IVA",E23="SI"),C23*SETUP!$C$4*SETUP!$C$11,0) -> 0 | I23: INPS Socio (sim.) | J23: =G29 -> 0
F24: =IF(D24="FATTURA P.IVA",C24*SETUP!$C$4*SETUP!$C$5,0) -> 0 | G24: =IF(AND(D24="FATTURA P.IVA",E24="SI"),C24*SETUP!$C$4*SETUP!$C$11,0) -> 0 | I24: 📤 USCITE & SAVING
F25: =IF(D25="FATTURA P.IVA",C25*SETUP!$C$4*SETUP!$C$5,0) -> 0 | G25: =IF(AND(D25="FATTURA P.IVA",E25="SI"),C25*SETUP!$C$4*SETUP!$C$11,0) -> 0 | I25: Tuo Netto P.IVA | J25: =K93 -> 0
F26: =IF(D26="FATTURA P.IVA",C26*SETUP!$C$4*SETUP!$C$5,0) -> 0 | G26: =IF(AND(D26="FATTURA P.IVA",E26="SI"),C26*SETUP!$C$4*SETUP!$C$11,0) -> 0 | I26: Uscite effettive | J26: =D78 -> 0
F27: =IF(D27="FATTURA P.IVA",C27*SETUP!$C$4*SETUP!$C$5,0) -> 0 | G27: =IF(AND(D27="FATTURA P.IVA",E27="SI"),C27*SETUP!$C$4*SETUP!$C$11,0) -> 0 | I27: Totale Secchielli | J27: =C92 -> 588.81
F28: =IF(D28="FATTURA P.IVA",C28*SETUP!$C$4*SETUP!$C$5,0) -> 0 | G28: =IF(AND(D28="FATTURA P.IVA",E28="SI"),C28*SETUP!$C$4*SETUP!$C$11,0) -> 0 | I28: ✨ NETTO REALE | J28: =B4 -> 319.19
B29: TOTALE ENTRATE | C29: =SUM(C15:C28) -> 3408 | F29: =SUMPRODUCT((D15:D28="FATTURA P.IVA")*(H15:H28="INCASSATO")*C15:C28*SETUP!$C$4*SETUP!$C$5) -> 0 | G29: =SUMPRODUCT((D15:D28="FATTURA P.IVA")*(H15:H28="INCASSATO")*(E15:E28="SI")*C15:C28*SETUP!$C$4*SETUP!$C$11) -> 0
B31: 💸 USCITE
B32: CATEGORIA | C32: DESCRIZIONE | D32: IMPORTO € | E32: DATA | F32: PAGATO? | G32: NOTE
B34: BUSINESS | C34: canva ( scad 19/12/26) | D34: 4.5 | F34: PROGRAMMATA
B35: BUSINESS | C35: cupcut (scad 23/12/26) | D35: 8.3 | F35: PROGRAMMATA
B36: BUSINESS | C36: google business mensile | D36: 15.81 | F36: PROGRAMMATA
B78: TOTALE USCITE EFFETTIVE | D78: =SUMPRODUCT((F33:F77<>"NO")*(F33:F77<>"PROGRAMMATA")*D33:D77) -> 0 | H78: DA VERSARE
B80: 🪣 SECCHIELLI / SAVING (PAC, fondi, investimenti) | H80: DA VERSARE
B81: OBIETTIVO / SECCHIELLO | C81: IMPORTO € | D81: FEE/SPREAD € | E81: DATA | F81: NOTE | H81: VERSATO?
B82: PAC 1 — Mediolanum Cina | C82: 75 | D82: =IFERROR(C82*VLOOKUP($B82,INVESTIMENTI!$B$23:$E$32,4,FALSE()),0) -> 2.25 | H82: DA VERSARE
B83: PAC 2 — Mediolanum India | C83: 75 | D83: =IFERROR(C83*VLOOKUP($B83,INVESTIMENTI!$B$23:$E$32,4,FALSE()),0) -> 2.25 | H83: DA VERSARE
B84: Polizza Vita Mediolanum | C84: 50 | D84: =IFERROR(C84*VLOOKUP($B84,INVESTIMENTI!$B$23:$E$32,4,FALSE()),0) -> 0 | H84: DA VERSARE
B85: QUOTA SOCIO — conguaglio | C85: =G29 -> 0 | D85: 0 | H85: DA VERSARE
B86: INPS Trimestrale (acconto) | C86: =SETUP!$C$6 -> 384.31 | D86: 0 | H86: DA VERSARE
D87: =IFERROR(C87*VLOOKUP($B87,INVESTIMENTI!$B$23:$E$32,4,FALSE()),0) -> 0
D90: =IFERROR(C90*VLOOKUP($B90,INVESTIMENTI!$B$23:$E$32,4,FALSE()),0) -> 0
...

Sheet AGOSTO
B2: AGOSTO 2026
B3: Il tuo netto reale spendibile questo mese
B4: =K93+K91-K95-K96 -> 319.19
B5: =CONCATENATE("su €",TEXT(K92,"#,##0")," di fatturato P.IVA • €",TEXT(K94,"#,##0")," tra tasse e INPS già accantonati") -> su €0 di fatturato P.IVA • €384 tra tasse e INPS già accantonati
B7: FATTURATO P.IVA | D7: DA ACCANTONARE | F7: STATO MESE | I7: 🎯 RIEPILOGO MESE
B8: =K92 -> 0 | D8: =K94 -> 384.31 | F8: =IF(B4<0,"🔴 IN ROSSO",IF(K97>=0.2,"🟢 SANO",IF(K97>=0.1,"🟡 ATTENZIONE","🟠 SAVING BASSO"))) -> 🟠 SAVING BASSO | I8: =IF(B4>=0,CONCATENATE("✅ €",TEXT(B4,"#,##0")," netti reali questo mese"),CONCATENATE("⚠ Sotto di €",TEXT(-B4,"#,##0")," questo mese")) -> ✅ €319 netti reali questo mese
B9: =CONCATENATE("+ €",TEXT(K91,"#,##0")," entrate private") -> + €908 entrate private | D9: =CONCATENATE("Tasse €",TEXT(F25,"#,##0")," + INPS €",TEXT(SETUP!$C$6,"#,##0")) -> Tasse €0 + INPS €384 | F9: =CONCATENATE("Saving rate ",TEXT(K97,"0.0%")) -> Saving rate 0,0%
B11: =CONCATENATE("⚠ Soglia INPS lordo annua: €",TEXT(SETUP!$C$8,"#,##0")," • Fatturato P.IVA mese: €",TEXT(K92,"#,##0")," • Vedi DASHBOARD per il monitoraggio annuale") -> ⚠ Soglia INPS lordo annua: €23.608 • Fatturato P.IVA mese: €0 • Vedi DASHBOARD per il monitoraggio annuale
B13: 💰 ENTRATE | I13: 🟢 ENTRATE INCASSATE
B14: CLIENTE / FONTE | C14: LORDO € | D14: TIPO | E14: CON SOCIO? | F14: TASSE 5% | G14: INPS SOCIO | H14: STATO | I14: Fatturato P.IVA | J14: =K92 -> 0
B15: FRUTTETO | C15: 400 | D15: ENTRATA PRIVATA (no tasse) | E15: NO | F15: =IF(D15="FATTURA P.IVA",C15*SETUP!$C$4*SETUP!$C$5,0) -> 0 | G15: =IF(AND(D15="FATTURA P.IVA",E15="SI"),C15*SETUP!$C$4*SETUP!$C$11,0) -> 0 | H15: PROGRAMMATO | I15: Entrate Private | J15: =K91 -> 908
B16: PIADINA | C16: 250 | D16: FATTURA P.IVA | E16: SI | F16: =IF(D16="FATTURA P.IVA",C16*SETUP!$C$4*SETUP!$C$5,0) -> 9.75 | G16: =IF(AND(D16="FATTURA P.IVA",E16="SI"),C16*SETUP!$C$4*SETUP!$C$11,0) -> 50.8365 | H16: PROGRAMMATO | I16: 🔵 ENTRATE PREVISTE
B17: PIADINA | C17: 200 | D17: ENTRATA PRIVATA (no tasse) | E17: NO | F17: =IF(D17="FATTURA P.IVA",C17*SETUP!$C$4*SETUP!$C$5,0) -> 0 | G17: =IF(AND(D17="FATTURA P.IVA",E17="SI"),C17*SETUP!$C$4*SETUP!$C$11,0) -> 0 | H17: PROGRAMMATO | I17: Fatturato emesso | J17: =K106 -> 0
B18: ROBE | C18: 500 | D18: FATTURA P.IVA | E18: SI | F18: =IF(D18="FATTURA P.IVA",C18*SETUP!$C$4*SETUP!$C$5,0) -> 19.5 | G18: =IF(AND(D18="FATTURA P.IVA",E18="SI"),C18*SETUP!$C$4*SETUP!$C$11,0) -> 101.673 | H18: PROGRAMMATO | I18: Pipeline programmata | J18: =K107 -> 2500
B19: FROZEN | C19: 308 | D19: ENTRATA PRIVATA (no tasse) | E19: NO | F19: =IF(D19="FATTURA P.IVA",C19*SETUP!$C$4*SETUP!$C$5,0) -> 0 | G19: =IF(AND(D19="FATTURA P.IVA",E19="SI"),C19*SETUP!$C$4*SETUP!$C$11,0) -> 0 | H19: PROGRAMMATO | I19: Entrate Private previste | J19: =K108 -> 0
B20: k2 | C20: 550 | D20: FATTURA P.IVA | E20: SI | F20: =IF(D20="FATTURA P.IVA",C20*SETUP!$C$4*SETUP!$C$5,0) -> 21.45 | G20: =IF(AND(D20="FATTURA P.IVA",E20="SI"),C20*SETUP!$C$4*SETUP!$C$11,0) -> 111.8403 | H20: PROGRAMMATO | I20: 💰 TASSE & INPS
B21: DNG | C21: 550 | D21: FATTURA P.IVA | E21: SI | F21: =IF(D21="FATTURA P.IVA",C21*SETUP!$C$4*SETUP!$C$5,0) -> 21.45 | G21: =IF(AND(D21="FATTURA P.IVA",E21="SI"),C21*SETUP!$C$4*SETUP!$C$11,0) -> 111.8403 | H21: PROGRAMMATO | I21: Tasse 5% | J21: =F29 -> 0
B22: FRUTTETO | C22: 650 | D22: FATTURA P.IVA | E22: NO | F22: =IF(D22="FATTURA P.IVA",C22*SETUP!$C$4*SETUP!$C$5,0) -> 25.35 | G22: =IF(AND(D22="FATTURA P.IVA",E22="SI"),C22*SETUP!$C$4*SETUP!$C$11,0) -> 0 | I22: INPS Fisso (artig.) | J22: =SETUP!$C$6 -> 384.31
F23: =IF(D23="FATTURA P.IVA",C23*SETUP!$C$4*SETUP!$C$5,0) -> 0 | G23: =IF(AND(D23="FATTURA P.IVA",E23="SI"),C23*SETUP!$C$4*SETUP!$C$11,0) -> 0 | I23: INPS Socio (sim.) | J23: =G29 -> 0
F24: =IF(D24="FATTURA P.IVA",C24*SETUP!$C$4*SETUP!$C$5,0) -> 0 | G24: =IF(AND(D24="FATTURA P.IVA",E24="SI"),C24*SETUP!$C$4*SETUP!$C$11,0) -> 0 | I24: 📤 USCITE & SAVING
F25: =IF(D25="FATTURA P.IVA",C25*SETUP!$C$4*SETUP!$C$5,0) -> 0 | G25: =IF(AND(D25="FATTURA P.IVA",E25="SI"),C25*SETUP!$C$4*SETUP!$C$11,0) -> 0 | I25: Tuo Netto P.IVA | J25: =K93 -> 0
F26: =IF(D26="FATTURA P.IVA",C26*SETUP!$C$4*SETUP!$C$5,0) -> 0 | G26: =IF(AND(D26="FATTURA P.IVA",E26="SI"),C26*SETUP!$C$4*SETUP!$C$11,0) -> 0 | I26: Uscite effettive | J26: =D78 -> 0
F27: =IF(D27="FATTURA P.IVA",C27*SETUP!$C$4*SETUP!$C$5,0) -> 0 | G27: =IF(AND(D27="FATTURA P.IVA",E27="SI"),C27*SETUP!$C$4*SETUP!$C$11,0) -> 0 | I27: Totale Secchielli | J27: =C92 -> 588.81
F28: =IF(D28="FATTURA P.IVA",C28*SETUP!$C$4*SETUP!$C$5,0) -> 0 | G28: =IF(AND(D28="FATTURA P.IVA",E28="SI"),C28*SETUP!$C$4*SETUP!$C$11,0) -> 0 | I28: ✨ NETTO REALE | J28: =B4 -> 319.19
B29: TOTALE ENTRATE | C29: =SUM(C15:C28) -> 3408 | F29: =SUMPRODUCT((D15:D28="FATTURA P.IVA")*(H15:H28="INCASSATO")*C15:C28*SETUP!$C$4*SETUP!$C$5) -> 0 | G29: =SUMPRODUCT((D15:D28="FATTURA P.IVA")*(H15:H28="INCASSATO")*(E15:E28="SI")*C15:C28*SETUP!$C$4*SETUP!$C$11) -> 0
B31: 💸 USCITE
B32: CATEGORIA | C32: DESCRIZIONE | D32: IMPORTO € | E32: DATA | F32: PAGATO? | G32: NOTE
B34: BUSINESS | C34: canva ( scad 19/12/26) | D34: 4.5 | F34: PROGRAMMATA
B35: BUSINESS | C35: cupcut (scad 23/12/26) | D35: 8.3 | F35: PROGRAMMATA
B36: BUSINESS | C36: google business mensile | D36: 15.81 | F36: PROGRAMMATA
B78: TOTALE USCITE EFFETTIVE | D78: =SUMPRODUCT((F33:F77<>"NO")*(F33:F77<>"PROGRAMMATA")*D33:D77) -> 0 | H78: DA VERSARE
B80: 🪣 SECCHIELLI / SAVING (PAC, fondi, investimenti) | H80: DA VERSARE
B81: OBIETTIVO / SECCHIELLO | C81: IMPORTO € | D81: FEE/SPREAD € | E81: DATA | F81: NOTE | H81: VERSATO?
B82: PAC 1 — Mediolanum Cina | C82: 75 | D82: =IFERROR(C82*VLOOKUP($B82,INVESTIMENTI!$B$23:$E$32,4,FALSE()),0) -> 2.25 | H82: DA VERSARE
B83: PAC 2 — Mediolanum India | C83: 75 | D83: =IFERROR(C83*VLOOKUP($B83,INVESTIMENTI!$B$23:$E$32,4,FALSE()),0) -> 2.25 | H83: DA VERSARE
B84: Polizza Vita Mediolanum | C84: 50 | D84: =IFERROR(C84*VLOOKUP($B84,INVESTIMENTI!$B$23:$E$32,4,FALSE()),0) -> 0 | H84: DA VERSARE
B85: QUOTA SOCIO — conguaglio | C85: =G29 -> 0 | D85: 0 | H85: DA VERSARE
B86: INPS Trimestrale (acconto) | C86: =SETUP!$C$6 -> 384.31 | D86: 0 | H86: DA VERSARE
D87: =IFERROR(C87*VLOOKUP($B87,INVESTIMENTI!$B$23:$E$32,4,FALSE()),0) -> 0
D90: =IFERROR(C90*VLOOKUP($B90,INVESTIMENTI!$B$23:$E$32,4,FALSE()),0) -> 0
...

Sheet SETTEMBRE
B2: SETTEMBRE 2026
B3: Il tuo netto reale spendibile questo mese
B4: =K93+K91-K95-K96 -> 319.19
B5: =CONCATENATE("su €",TEXT(K92,"#,##0")," di fatturato P.IVA • €",TEXT(K94,"#,##0")," tra tasse e INPS già accantonati") -> su €0 di fatturato P.IVA • €384 tra tasse e INPS già accantonati
B7: FATTURATO P.IVA | D7: DA ACCANTONARE | F7: STATO MESE | I7: 🎯 RIEPILOGO MESE
B8: =K92 -> 0 | D8: =K94 -> 384.31 | F8: =IF(B4<0,"🔴 IN ROSSO",IF(K97>=0.2,"🟢 SANO",IF(K97>=0.1,"🟡 ATTENZIONE","🟠 SAVING BASSO"))) -> 🟠 SAVING BASSO | I8: =IF(B4>=0,CONCATENATE("✅ €",TEXT(B4,"#,##0")," netti reali questo mese"),CONCATENATE("⚠ Sotto di €",TEXT(-B4,"#,##0")," questo mese")) -> ✅ €319 netti reali questo mese
B9: =CONCATENATE("+ €",TEXT(K91,"#,##0")," entrate private") -> + €908 entrate private | D9: =CONCATENATE("Tasse €",TEXT(F25,"#,##0")," + INPS €",TEXT(SETUP!$C$6,"#,##0")) -> Tasse €0 + INPS €384 | F9: =CONCATENATE("Saving rate ",TEXT(K97,"0.0%")) -> Saving rate 0,0%
B11: =CONCATENATE("⚠ Soglia INPS lordo annua: €",TEXT(SETUP!$C$8,"#,##0")," • Fatturato P.IVA mese: €",TEXT(K92,"#,##0")," • Vedi DASHBOARD per il monitoraggio annuale") -> ⚠ Soglia INPS lordo annua: €23.608 • Fatturato P.IVA mese: €0 • Vedi DASHBOARD per il monitoraggio annuale
B13: 💰 ENTRATE | I13: 🟢 ENTRATE INCASSATE
B14: CLIENTE / FONTE | C14: LORDO € | D14: TIPO | E14: CON SOCIO? | F14: TASSE 5% | G14: INPS SOCIO | H14: STATO | I14: Fatturato P.IVA | J14: =K92 -> 0
B15: FRUTTETO | C15: 400 | D15: ENTRATA PRIVATA (no tasse) | E15: NO | F15: =IF(D15="FATTURA P.IVA",C15*SETUP!$C$4*SETUP!$C$5,0) -> 0 | G15: =IF(AND(D15="FATTURA P.IVA",E15="SI"),C15*SETUP!$C$4*SETUP!$C$11,0) -> 0 | H15: PROGRAMMATO | I15: Entrate Private | J15: =K91 -> 908
B16: PIADINA | C16: 250 | D16: FATTURA P.IVA | E16: SI | F16: =IF(D16="FATTURA P.IVA",C16*SETUP!$C$4*SETUP!$C$5,0) -> 9.75 | G16: =IF(AND(D16="FATTURA P.IVA",E16="SI"),C16*SETUP!$C$4*SETUP!$C$11,0) -> 50.8365 | H16: PROGRAMMATO | I16: 🔵 ENTRATE PREVISTE
B17: PIADINA | C17: 200 | D17: ENTRATA PRIVATA (no tasse) | E17: NO | F17: =IF(D17="FATTURA P.IVA",C17*SETUP!$C$4*SETUP!$C$5,0) -> 0 | G17: =IF(AND(D17="FATTURA P.IVA",E17="SI"),C17*SETUP!$C$4*SETUP!$C$11,0) -> 0 | H17: PROGRAMMATO | I17: Fatturato emesso | J17: =K106 -> 0
B18: ROBE | C18: 500 | D18: FATTURA P.IVA | E18: SI | F18: =IF(D18="FATTURA P.IVA",C18*SETUP!$C$4*SETUP!$C$5,0) -> 19.5 | G18: =IF(AND(D18="FATTURA P.IVA",E18="SI"),C18*SETUP!$C$4*SETUP!$C$11,0) -> 101.673 | H18: PROGRAMMATO | I18: Pipeline programmata | J18: =K107 -> 1850
B19: FROZEN | C19: 308 | D19: ENTRATA PRIVATA (no tasse) | E19: NO | F19: =IF(D19="FATTURA P.IVA",C19*SETUP!$C$4*SETUP!$C$5,0) -> 0 | G19: =IF(AND(D19="FATTURA P.IVA",E19="SI"),C19*SETUP!$C$4*SETUP!$C$11,0) -> 0 | H19: PROGRAMMATO | I19: Entrate Private previste | J19: =K108 -> 0
B20: FRUTTETO | C20: 550 | D20: FATTURA P.IVA | E20: NO | F20: =IF(D20="FATTURA P.IVA",C20*SETUP!$C$4*SETUP!$C$5,0) -> 21.45 | G20: =IF(AND(D20="FATTURA P.IVA",E20="SI"),C20*SETUP!$C$4*SETUP!$C$11,0) -> 0 | I20: 💰 TASSE & INPS
B21: k2 | C21: 550 | D21: FATTURA P.IVA | E21: SI | F21: =IF(D21="FATTURA P.IVA",C21*SETUP!$C$4*SETUP!$C$5,0) -> 21.45 | G21: =IF(AND(D21="FATTURA P.IVA",E21="SI"),C21*SETUP!$C$4*SETUP!$C$11,0) -> 111.8403 | H21: PROGRAMMATO | I21: Tasse 5% | J21: =F29 -> 0
F22: =IF(D22="FATTURA P.IVA",C22*SETUP!$C$4*SETUP!$C$5,0) -> 0 | G22: =IF(AND(D22="FATTURA P.IVA",E22="SI"),C22*SETUP!$C$4*SETUP!$C$11,0) -> 0 | I22: INPS Fisso (artig.) | J22: =SETUP!$C$6 -> 384.31
F23: =IF(D23="FATTURA P.IVA",C23*SETUP!$C$4*SETUP!$C$5,0) -> 0 | G23: =IF(AND(D23="FATTURA P.IVA",E23="SI"),C23*SETUP!$C$4*SETUP!$C$11,0) -> 0 | I23: INPS Socio (sim.) | J23: =G29 -> 0
F24: =IF(D24="FATTURA P.IVA",C24*SETUP!$C$4*SETUP!$C$5,0) -> 0 | G24: =IF(AND(D24="FATTURA P.IVA",E24="SI"),C24*SETUP!$C$4*SETUP!$C$11,0) -> 0 | I24: 📤 USCITE & SAVING
F25: =IF(D25="FATTURA P.IVA",C25*SETUP!$C$4*SETUP!$C$5,0) -> 0 | G25: =IF(AND(D25="FATTURA P.IVA",E25="SI"),C25*SETUP!$C$4*SETUP!$C$11,0) -> 0 | I25: Tuo Netto P.IVA | J25: =K93 -> 0
F26: =IF(D26="FATTURA P.IVA",C26*SETUP!$C$4*SETUP!$C$5,0) -> 0 | G26: =IF(AND(D26="FATTURA P.IVA",E26="SI"),C26*SETUP!$C$4*SETUP!$C$11,0) -> 0 | I26: Uscite effettive | J26: =D78 -> 0
F27: =IF(D27="FATTURA P.IVA",C27*SETUP!$C$4*SETUP!$C$5,0) -> 0 | G27: =IF(AND(D27="FATTURA P.IVA",E27="SI"),C27*SETUP!$C$4*SETUP!$C$11,0) -> 0 | I27: Totale Secchielli | J27: =C92 -> 588.81
F28: =IF(D28="FATTURA P.IVA",C28*SETUP!$C$4*SETUP!$C$5,0) -> 0 | G28: =IF(AND(D28="FATTURA P.IVA",E28="SI"),C28*SETUP!$C$4*SETUP!$C$11,0) -> 0 | I28: ✨ NETTO REALE | J28: =B4 -> 319.19
B29: TOTALE ENTRATE | C29: =SUM(C15:C28) -> 2758 | F29: =SUMPRODUCT((D15:D28="FATTURA P.IVA")*(H15:H28="INCASSATO")*C15:C28*SETUP!$C$4*SETUP!$C$5) -> 0 | G29: =SUMPRODUCT((D15:D28="FATTURA P.IVA")*(H15:H28="INCASSATO")*(E15:E28="SI")*C15:C28*SETUP!$C$4*SETUP!$C$11) -> 0
B31: 💸 USCITE
B32: CATEGORIA | C32: DESCRIZIONE | D32: IMPORTO € | E32: DATA | F32: PAGATO? | G32: NOTE
B34: BUSINESS | C34: canva ( scad 19/12/26) | D34: 4.5 | F34: PROGRAMMATA
B35: BUSINESS | C35: cupcut (scad 23/12/26) | D35: 8.3 | F35: PROGRAMMATA
B36: BUSINESS | C36: google business mensile | D36: 15.81 | F36: PROGRAMMATA
B78: TOTALE USCITE EFFETTIVE | D78: =SUMPRODUCT((F33:F77<>"NO")*(F33:F77<>"PROGRAMMATA")*D33:D77) -> 0 | H78: DA VERSARE
B80: 🪣 SECCHIELLI / SAVING (PAC, fondi, investimenti) | H80: DA VERSARE
B81: OBIETTIVO / SECCHIELLO | C81: IMPORTO € | D81: FEE/SPREAD € | E81: DATA | F81: NOTE | H81: VERSATO?
B82: PAC 1 — Mediolanum Cina | C82: 75 | D82: =IFERROR(C82*VLOOKUP($B82,INVESTIMENTI!$B$23:$E$32,4,FALSE()),0) -> 2.25 | H82: DA VERSARE
B83: PAC 2 — Mediolanum India | C83: 75 | D83: =IFERROR(C83*VLOOKUP($B83,INVESTIMENTI!$B$23:$E$32,4,FALSE()),0) -> 2.25 | H83: DA VERSARE
B84: Polizza Vita Mediolanum | C84: 50 | D84: =IFERROR(C84*VLOOKUP($B84,INVESTIMENTI!$B$23:$E$32,4,FALSE()),0) -> 0 | H84: DA VERSARE
B85: QUOTA SOCIO — conguaglio | C85: =G29 -> 0 | D85: 0 | H85: DA VERSARE
B86: INPS Trimestrale (acconto) | C86: =SETUP!$C$6 -> 384.31 | D86: 0 | H86: DA VERSARE
D87: =IFERROR(C87*VLOOKUP($B87,INVESTIMENTI!$B$23:$E$32,4,FALSE()),0) -> 0
D90: =IFERROR(C90*VLOOKUP($B90,INVESTIMENTI!$B$23:$E$32,4,FALSE()),0) -> 0
...

Sheet OTTOBRE
B2: OTTOBRE 2026
B3: Il tuo netto reale spendibile questo mese
B4: =K93+K91-K95-K96 -> 319.19
B5: =CONCATENATE("su €",TEXT(K92,"#,##0")," di fatturato P.IVA • €",TEXT(K94,"#,##0")," tra tasse e INPS già accantonati") -> su €0 di fatturato P.IVA • €384 tra tasse e INPS già accantonati
B7: FATTURATO P.IVA | D7: DA ACCANTONARE | F7: STATO MESE | I7: 🎯 RIEPILOGO MESE
B8: =K92 -> 0 | D8: =K94 -> 384.31 | F8: =IF(B4<0,"🔴 IN ROSSO",IF(K97>=0.2,"🟢 SANO",IF(K97>=0.1,"🟡 ATTENZIONE","🟠 SAVING BASSO"))) -> 🟠 SAVING BASSO | I8: =IF(B4>=0,CONCATENATE("✅ €",TEXT(B4,"#,##0")," netti reali questo mese"),CONCATENATE("⚠ Sotto di €",TEXT(-B4,"#,##0")," questo mese")) -> ✅ €319 netti reali questo mese
B9: =CONCATENATE("+ €",TEXT(K91,"#,##0")," entrate private") -> + €908 entrate private | D9: =CONCATENATE("Tasse €",TEXT(F25,"#,##0")," + INPS €",TEXT(SETUP!$C$6,"#,##0")) -> Tasse €0 + INPS €384 | F9: =CONCATENATE("Saving rate ",TEXT(K97,"0.0%")) -> Saving rate 0,0%
B11: =CONCATENATE("⚠ Soglia INPS lordo annua: €",TEXT(SETUP!$C$8,"#,##0")," • Fatturato P.IVA mese: €",TEXT(K92,"#,##0")," • Vedi DASHBOARD per il monitoraggio annuale") -> ⚠ Soglia INPS lordo annua: €23.608 • Fatturato P.IVA mese: €0 • Vedi DASHBOARD per il monitoraggio annuale
B13: 💰 ENTRATE | I13: 🟢 ENTRATE INCASSATE
B14: CLIENTE / FONTE | C14: LORDO € | D14: TIPO | E14: CON SOCIO? | F14: TASSE 5% | G14: INPS SOCIO | H14: STATO | I14: Fatturato P.IVA | J14: =K92 -> 0
B15: FRUTTETO | C15: 400 | D15: ENTRATA PRIVATA (no tasse) | E15: NO | F15: =IF(D15="FATTURA P.IVA",C15*SETUP!$C$4*SETUP!$C$5,0) -> 0 | G15: =IF(AND(D15="FATTURA P.IVA",E15="SI"),C15*SETUP!$C$4*SETUP!$C$11,0) -> 0 | H15: PROGRAMMATO | I15: Entrate Private | J15: =K91 -> 908
B16: PIADINA | C16: 250 | D16: FATTURA P.IVA | E16: SI | F16: =IF(D16="FATTURA P.IVA",C16*SETUP!$C$4*SETUP!$C$5,0) -> 9.75 | G16: =IF(AND(D16="FATTURA P.IVA",E16="SI"),C16*SETUP!$C$4*SETUP!$C$11,0) -> 50.8365 | H16: PROGRAMMATO | I16: 🔵 ENTRATE PREVISTE
B17: PIADINA | C17: 200 | D17: ENTRATA PRIVATA (no tasse) | E17: NO | F17: =IF(D17="FATTURA P.IVA",C17*SETUP!$C$4*SETUP!$C$5,0) -> 0 | G17: =IF(AND(D17="FATTURA P.IVA",E17="SI"),C17*SETUP!$C$4*SETUP!$C$11,0) -> 0 | H17: PROGRAMMATO | I17: Fatturato emesso | J17: =K106 -> 0
B18: ROBE | C18: 500 | D18: FATTURA P.IVA | E18: SI | F18: =IF(D18="FATTURA P.IVA",C18*SETUP!$C$4*SETUP!$C$5,0) -> 19.5 | G18: =IF(AND(D18="FATTURA P.IVA",E18="SI"),C18*SETUP!$C$4*SETUP!$C$11,0) -> 101.673 | H18: PROGRAMMATO | I18: Pipeline programmata | J18: =K107 -> 750
B19: FROZEN | C19: 308 | D19: ENTRATA PRIVATA (no tasse) | E19: NO | F19: =IF(D19="FATTURA P.IVA",C19*SETUP!$C$4*SETUP!$C$5,0) -> 0 | G19: =IF(AND(D19="FATTURA P.IVA",E19="SI"),C19*SETUP!$C$4*SETUP!$C$11,0) -> 0 | H19: PROGRAMMATO | I19: Entrate Private previste | J19: =K108 -> 0
F20: =IF(D20="FATTURA P.IVA",C20*SETUP!$C$4*SETUP!$C$5,0) -> 0 | G20: =IF(AND(D20="FATTURA P.IVA",E20="SI"),C20*SETUP!$C$4*SETUP!$C$11,0) -> 0 | I20: 💰 TASSE & INPS
F21: =IF(D21="FATTURA P.IVA",C21*SETUP!$C$4*SETUP!$C$5,0) -> 0 | G21: =IF(AND(D21="FATTURA P.IVA",E21="SI"),C21*SETUP!$C$4*SETUP!$C$11,0) -> 0 | I21: Tasse 5% | J21: =F29 -> 0
F22: =IF(D22="FATTURA P.IVA",C22*SETUP!$C$4*SETUP!$C$5,0) -> 0 | G22: =IF(AND(D22="FATTURA P.IVA",E22="SI"),C22*SETUP!$C$4*SETUP!$C$11,0) -> 0 | I22: INPS Fisso (artig.) | J22: =SETUP!$C$6 -> 384.31
F23: =IF(D23="FATTURA P.IVA",C23*SETUP!$C$4*SETUP!$C$5,0) -> 0 | G23: =IF(AND(D23="FATTURA P.IVA",E23="SI"),C23*SETUP!$C$4*SETUP!$C$11,0) -> 0 | I23: INPS Socio (sim.) | J23: =G29 -> 0
F24: =IF(D24="FATTURA P.IVA",C24*SETUP!$C$4*SETUP!$C$5,0) -> 0 | G24: =IF(AND(D24="FATTURA P.IVA",E24="SI"),C24*SETUP!$C$4*SETUP!$C$11,0) -> 0 | I24: 📤 USCITE & SAVING
F25: =IF(D25="FATTURA P.IVA",C25*SETUP!$C$4*SETUP!$C$5,0) -> 0 | G25: =IF(AND(D25="FATTURA P.IVA",E25="SI"),C25*SETUP!$C$4*SETUP!$C$11,0) -> 0 | I25: Tuo Netto P.IVA | J25: =K93 -> 0
F26: =IF(D26="FATTURA P.IVA",C26*SETUP!$C$4*SETUP!$C$5,0) -> 0 | G26: =IF(AND(D26="FATTURA P.IVA",E26="SI"),C26*SETUP!$C$4*SETUP!$C$11,0) -> 0 | I26: Uscite effettive | J26: =D78 -> 0
F27: =IF(D27="FATTURA P.IVA",C27*SETUP!$C$4*SETUP!$C$5,0) -> 0 | G27: =IF(AND(D27="FATTURA P.IVA",E27="SI"),C27*SETUP!$C$4*SETUP!$C$11,0) -> 0 | I27: Totale Secchielli | J27: =C92 -> 588.81
F28: =IF(D28="FATTURA P.IVA",C28*SETUP!$C$4*SETUP!$C$5,0) -> 0 | G28: =IF(AND(D28="FATTURA P.IVA",E28="SI"),C28*SETUP!$C$4*SETUP!$C$11,0) -> 0 | I28: ✨ NETTO REALE | J28: =B4 -> 319.19
B29: TOTALE ENTRATE | C29: =SUM(C15:C28) -> 1658 | F29: =SUMPRODUCT((D15:D28="FATTURA P.IVA")*(H15:H28="INCASSATO")*C15:C28*SETUP!$C$4*SETUP!$C$5) -> 0 | G29: =SUMPRODUCT((D15:D28="FATTURA P.IVA")*(H15:H28="INCASSATO")*(E15:E28="SI")*C15:C28*SETUP!$C$4*SETUP!$C$11) -> 0
B31: 💸 USCITE
B32: CATEGORIA | C32: DESCRIZIONE | D32: IMPORTO € | E32: DATA | F32: PAGATO? | G32: NOTE
B34: BUSINESS | C34: canva ( scad 19/12/26) | D34: 4.5 | F34: PROGRAMMATA
B35: BUSINESS | C35: cupcut (scad 23/12/26) | D35: 8.3 | F35: PROGRAMMATA
B36: BUSINESS | C36: google business mensile | D36: 15.81 | F36: PROGRAMMATA
B78: TOTALE USCITE EFFETTIVE | D78: =SUMPRODUCT((F33:F77<>"NO")*(F33:F77<>"PROGRAMMATA")*D33:D77) -> 0 | H78: DA VERSARE
B80: 🪣 SECCHIELLI / SAVING (PAC, fondi, investimenti) | H80: DA VERSARE
B81: OBIETTIVO / SECCHIELLO | C81: IMPORTO € | D81: FEE/SPREAD € | E81: DATA | F81: NOTE | H81: VERSATO?
B82: PAC 1 — Mediolanum Cina | C82: 75 | D82: =IFERROR(C82*VLOOKUP($B82,INVESTIMENTI!$B$23:$E$32,4,FALSE()),0) -> 2.25 | H82: DA VERSARE
B83: PAC 2 — Mediolanum India | C83: 75 | D83: =IFERROR(C83*VLOOKUP($B83,INVESTIMENTI!$B$23:$E$32,4,FALSE()),0) -> 2.25 | H83: DA VERSARE
B84: Polizza Vita Mediolanum | C84: 50 | D84: =IFERROR(C84*VLOOKUP($B84,INVESTIMENTI!$B$23:$E$32,4,FALSE()),0) -> 0 | H84: DA VERSARE
B85: QUOTA SOCIO — conguaglio | C85: =G29 -> 0 | D85: 0 | H85: DA VERSARE
B86: INPS Trimestrale (acconto) | C86: =SETUP!$C$6 -> 384.31 | D86: 0 | H86: DA VERSARE
D87: =IFERROR(C87*VLOOKUP($B87,INVESTIMENTI!$B$23:$E$32,4,FALSE()),0) -> 0
D90: =IFERROR(C90*VLOOKUP($B90,INVESTIMENTI!$B$23:$E$32,4,FALSE()),0) -> 0
...

Sheet NOVEMBRE
B2: NOVEMBRE 2026
B3: Il tuo netto reale spendibile questo mese
B4: =K93+K91-K95-K96 -> 319.19
B5: =CONCATENATE("su €",TEXT(K92,"#,##0")," di fatturato P.IVA • €",TEXT(K94,"#,##0")," tra tasse e INPS già accantonati") -> su €0 di fatturato P.IVA • €384 tra tasse e INPS già accantonati
