Workbook

Sheet SETUP
B1: TANGERINE SHEETS — SETUP FISCALE
B3: VARIABILI FISCALI | E3: CATEGORIE SPESA | G3: SECCHIELLI RISPARMIO | I3: STATO FATTURA | K3: TIPO SPESA
B4: Coefficiente Redditivita | C4: 0.78 | E4: BUSINESS | G4: FONDO EMERGENZA | I4: PAGATO | K4: EFFETTIVA
B5: Aliquota Tasse | C5: 0.05 | E5: AUTO | G5: PENSIONE | I5: DA PAGARE | K5: PROGRAMMATA
B6: Minimale INPS Annuo | C6: 18808 | E6: VITA | G6: VACANZE | I6: PROGRAMMATO
B7: INPS Fisso Mensile | C7: 376.78 | E7: SVAGO | G7: FORMAZIONE
B8: Aliquota INPS Eccedenza | C8: 0.24 | E8: INVESTIMENTO | G8: INVESTIMENTO PAC
E9: FORMAZIONE | G9: ALTRO
E10: SALUTE

Sheet GENNAIO
B1: GENNAIO 2026
B3: FATTURE P.IVA | J3: RIEPILOGO MESE
B4: CLIENTE | C4: LORDO | D4: NETTO | E4: STATO | F4: TASSE | G4: INPS | H4: NETTO REALE
D5: =IF(E5="PAGATO",C5-F5-G5,0) | F5: =IF(E5="PAGATO",C5*SETUP!$C$4*SETUP!$C$5,0) | G5: =IF(E5="PAGATO",IF(COUNTIF($E$5:E5,"PAGATO")=1,SETUP!$C$7,0),0) | H5: =IF(E5="PAGATO",C5-F5-G5,0) | J5: Fatturato Incassato | K5: =SUMIF(E5:E36,"PAGATO",C5:C36)
D6: =IF(E6="PAGATO",C6-F6-G6,0) | F6: =IF(E6="PAGATO",C6*SETUP!$C$4*SETUP!$C$5,0) | G6: =IF(E6="PAGATO",IF(COUNTIF($E$5:E6,"PAGATO")=1,SETUP!$C$7,0),0) | H6: =IF(E6="PAGATO",C6-F6-G6,0) | J6: Da Incassare | K6: =SUMIF(E5:E36,"DA PAGARE",C5:C36)
D7: =IF(E7="PAGATO",C7-F7-G7,0) | F7: =IF(E7="PAGATO",C7*SETUP!$C$4*SETUP!$C$5,0) | G7: =IF(E7="PAGATO",IF(COUNTIF($E$5:E7,"PAGATO")=1,SETUP!$C$7,0),0) | H7: =IF(E7="PAGATO",C7-F7-G7,0) | J7: Pipeline Programmata | K7: =SUMIF(E5:E36,"PROGRAMMATO",C5:C36)
D8: =IF(E8="PAGATO",C8-F8-G8,0) | F8: =IF(E8="PAGATO",C8*SETUP!$C$4*SETUP!$C$5,0) | G8: =IF(E8="PAGATO",IF(COUNTIF($E$5:E8,"PAGATO")=1,SETUP!$C$7,0),0) | H8: =IF(E8="PAGATO",C8-F8-G8,0) | J8: Entrate Nette Pure | K8: =C51
D9: =IF(E9="PAGATO",C9-F9-G9,0) | F9: =IF(E9="PAGATO",C9*SETUP!$C$4*SETUP!$C$5,0) | G9: =IF(E9="PAGATO",IF(COUNTIF($E$5:E9,"PAGATO")=1,SETUP!$C$7,0),0) | H9: =IF(E9="PAGATO",C9-F9-G9,0) | J9: Spese Effettive | K9: =C89
D10: =IF(E10="PAGATO",C10-F10-G10,0) | F10: =IF(E10="PAGATO",C10*SETUP!$C$4*SETUP!$C$5,0) | G10: =IF(E10="PAGATO",IF(COUNTIF($E$5:E10,"PAGATO")=1,SETUP!$C$7,0),0) | H10: =IF(E10="PAGATO",C10-F10-G10,0) | J10: Spese Programmate | K10: =C90
D11: =IF(E11="PAGATO",C11-F11-G11,0) | F11: =IF(E11="PAGATO",C11*SETUP!$C$4*SETUP!$C$5,0) | G11: =IF(E11="PAGATO",IF(COUNTIF($E$5:E11,"PAGATO")=1,SETUP!$C$7,0),0) | H11: =IF(E11="PAGATO",C11-F11-G11,0) | J11: Zavorra Fiscale | K11: =SUM(F5:F36)+SUM(G5:G36)
D12: =IF(E12="PAGATO",C12-F12-G12,0) | F12: =IF(E12="PAGATO",C12*SETUP!$C$4*SETUP!$C$5,0) | G12: =IF(E12="PAGATO",IF(COUNTIF($E$5:E12,"PAGATO")=1,SETUP!$C$7,0),0) | H12: =IF(E12="PAGATO",C12-F12-G12,0) | J12: Netto Reale Mensile | K12: =(K5-K11)+K8-K9
D13: =IF(E13="PAGATO",C13-F13-G13,0) | F13: =IF(E13="PAGATO",C13*SETUP!$C$4*SETUP!$C$5,0) | G13: =IF(E13="PAGATO",IF(COUNTIF($E$5:E13,"PAGATO")=1,SETUP!$C$7,0),0) | H13: =IF(E13="PAGATO",C13-F13-G13,0) | J13: Totale Secchielli | K13: =SUM(K20:K31)
D14: =IF(E14="PAGATO",C14-F14-G14,0) | F14: =IF(E14="PAGATO",C14*SETUP!$C$4*SETUP!$C$5,0) | G14: =IF(E14="PAGATO",IF(COUNTIF($E$5:E14,"PAGATO")=1,SETUP!$C$7,0),0) | H14: =IF(E14="PAGATO",C14-F14-G14,0) | J14: Netto Rimanente | K14: =K12-K13
D15: =IF(E15="PAGATO",C15-F15-G15,0) | F15: =IF(E15="PAGATO",C15*SETUP!$C$4*SETUP!$C$5,0) | G15: =IF(E15="PAGATO",IF(COUNTIF($E$5:E15,"PAGATO")=1,SETUP!$C$7,0),0) | H15: =IF(E15="PAGATO",C15-F15-G15,0) | J15: Imponibile Mese | K15: =K5*SETUP!$C$4
D16: =IF(E16="PAGATO",C16-F16-G16,0) | F16: =IF(E16="PAGATO",C16*SETUP!$C$4*SETUP!$C$5,0) | G16: =IF(E16="PAGATO",IF(COUNTIF($E$5:E16,"PAGATO")=1,SETUP!$C$7,0),0) | H16: =IF(E16="PAGATO",C16-F16-G16,0) | J16: Saving Rate | K16: =IFERROR(K13/K5,0)
D17: =IF(E17="PAGATO",C17-F17-G17,0) | F17: =IF(E17="PAGATO",C17*SETUP!$C$4*SETUP!$C$5,0) | G17: =IF(E17="PAGATO",IF(COUNTIF($E$5:E17,"PAGATO")=1,SETUP!$C$7,0),0) | H17: =IF(E17="PAGATO",C17-F17-G17,0) | J17: TAX SAFE | K17: =K14-K11
D18: =IF(E18="PAGATO",C18-F18-G18,0) | F18: =IF(E18="PAGATO",C18*SETUP!$C$4*SETUP!$C$5,0) | G18: =IF(E18="PAGATO",IF(COUNTIF($E$5:E18,"PAGATO")=1,SETUP!$C$7,0),0) | H18: =IF(E18="PAGATO",C18-F18-G18,0) | J18: STATO MESE | K18: =IF(K16>=0.2,"MESE SANO",IF(K16>=0.1,"ATTENZIONE",IF(K17<0,"TASSE A RISCHIO","SAVING BASSO")))
D19: =IF(E19="PAGATO",C19-F19-G19,0) | F19: =IF(E19="PAGATO",C19*SETUP!$C$4*SETUP!$C$5,0) | G19: =IF(E19="PAGATO",IF(COUNTIF($E$5:E19,"PAGATO")=1,SETUP!$C$7,0),0) | H19: =IF(E19="PAGATO",C19-F19-G19,0) | J19: SECCHIELLI RISPARMIO
D20: =IF(E20="PAGATO",C20-F20-G20,0) | F20: =IF(E20="PAGATO",C20*SETUP!$C$4*SETUP!$C$5,0) | G20: =IF(E20="PAGATO",IF(COUNTIF($E$5:E20,"PAGATO")=1,SETUP!$C$7,0),0) | H20: =IF(E20="PAGATO",C20-F20-G20,0) | J20: OBIETTIVO | K20: IMPORTO | L20: DESCRIZIONE
D21: =IF(E21="PAGATO",C21-F21-G21,0) | F21: =IF(E21="PAGATO",C21*SETUP!$C$4*SETUP!$C$5,0) | G21: =IF(E21="PAGATO",IF(COUNTIF($E$5:E21,"PAGATO")=1,SETUP!$C$7,0),0) | H21: =IF(E21="PAGATO",C21-F21-G21,0)
D22: =IF(E22="PAGATO",C22-F22-G22,0) | F22: =IF(E22="PAGATO",C22*SETUP!$C$4*SETUP!$C$5,0) | G22: =IF(E22="PAGATO",IF(COUNTIF($E$5:E22,"PAGATO")=1,SETUP!$C$7,0),0) | H22: =IF(E22="PAGATO",C22-F22-G22,0)
D23: =IF(E23="PAGATO",C23-F23-G23,0) | F23: =IF(E23="PAGATO",C23*SETUP!$C$4*SETUP!$C$5,0) | G23: =IF(E23="PAGATO",IF(COUNTIF($E$5:E23,"PAGATO")=1,SETUP!$C$7,0),0) | H23: =IF(E23="PAGATO",C23-F23-G23,0)
D24: =IF(E24="PAGATO",C24-F24-G24,0) | F24: =IF(E24="PAGATO",C24*SETUP!$C$4*SETUP!$C$5,0) | G24: =IF(E24="PAGATO",IF(COUNTIF($E$5:E24,"PAGATO")=1,SETUP!$C$7,0),0) | H24: =IF(E24="PAGATO",C24-F24-G24,0)
D25: =IF(E25="PAGATO",C25-F25-G25,0) | F25: =IF(E25="PAGATO",C25*SETUP!$C$4*SETUP!$C$5,0) | G25: =IF(E25="PAGATO",IF(COUNTIF($E$5:E25,"PAGATO")=1,SETUP!$C$7,0),0) | H25: =IF(E25="PAGATO",C25-F25-G25,0)
D26: =IF(E26="PAGATO",C26-F26-G26,0) | F26: =IF(E26="PAGATO",C26*SETUP!$C$4*SETUP!$C$5,0) | G26: =IF(E26="PAGATO",IF(COUNTIF($E$5:E26,"PAGATO")=1,SETUP!$C$7,0),0) | H26: =IF(E26="PAGATO",C26-F26-G26,0)
D27: =IF(E27="PAGATO",C27-F27-G27,0) | F27: =IF(E27="PAGATO",C27*SETUP!$C$4*SETUP!$C$5,0) | G27: =IF(E27="PAGATO",IF(COUNTIF($E$5:E27,"PAGATO")=1,SETUP!$C$7,0),0) | H27: =IF(E27="PAGATO",C27-F27-G27,0)
D28: =IF(E28="PAGATO",C28-F28-G28,0) | F28: =IF(E28="PAGATO",C28*SETUP!$C$4*SETUP!$C$5,0) | G28: =IF(E28="PAGATO",IF(COUNTIF($E$5:E28,"PAGATO")=1,SETUP!$C$7,0),0) | H28: =IF(E28="PAGATO",C28-F28-G28,0)
D29: =IF(E29="PAGATO",C29-F29-G29,0) | F29: =IF(E29="PAGATO",C29*SETUP!$C$4*SETUP!$C$5,0) | G29: =IF(E29="PAGATO",IF(COUNTIF($E$5:E29,"PAGATO")=1,SETUP!$C$7,0),0) | H29: =IF(E29="PAGATO",C29-F29-G29,0)
D30: =IF(E30="PAGATO",C30-F30-G30,0) | F30: =IF(E30="PAGATO",C30*SETUP!$C$4*SETUP!$C$5,0) | G30: =IF(E30="PAGATO",IF(COUNTIF($E$5:E30,"PAGATO")=1,SETUP!$C$7,0),0) | H30: =IF(E30="PAGATO",C30-F30-G30,0)
D31: =IF(E31="PAGATO",C31-F31-G31,0) | F31: =IF(E31="PAGATO",C31*SETUP!$C$4*SETUP!$C$5,0) | G31: =IF(E31="PAGATO",IF(COUNTIF($E$5:E31,"PAGATO")=1,SETUP!$C$7,0),0) | H31: =IF(E31="PAGATO",C31-F31-G31,0)
D32: =IF(E32="PAGATO",C32-F32-G32,0) | F32: =IF(E32="PAGATO",C32*SETUP!$C$4*SETUP!$C$5,0) | G32: =IF(E32="PAGATO",IF(COUNTIF($E$5:E32,"PAGATO")=1,SETUP!$C$7,0),0) | H32: =IF(E32="PAGATO",C32-F32-G32,0)
... D36: =IF(E36="PAGATO",C36-F36-G36,0) | F36: =IF(E36="PAGATO",C36*SETUP!$C$4*SETUP!$C$5,0) | G36: =IF(E36="PAGATO",IF(COUNTIF($E$5:E36,"PAGATO")=1,SETUP!$C$7,0),0) | H36: =IF(E36="PAGATO",C36-F36-G36,0)
B39: ENTRATE NETTE / ESENTASSE
B40: VOCE | C40: IMPORTO NETTO | D40: NOTE
B51: TOTALE ENTRATE NETTE | C51: =SUM(C41:C50)
B54: USCITE
B55: CATEGORIA | C55: IMPORTO | D55: DATA | E55: TIPO | F55: NOTE
B89: TOTALE USCITE EFFETTIVE | C89: =SUMIF(E56:E88,"EFFETTIVA",C56:C88)
B90: TOTALE SPESE PROGRAMMATE | C90: =SUMIF(E56:E88,"PROGRAMMATA",C56:C88)

Sheet FEBBRAIO
B1: FEBBRAIO 2026
B3: FATTURE P.IVA | J3: RIEPILOGO MESE
B4: CLIENTE | C4: LORDO | D4: NETTO | E4: STATO | F4: TASSE | G4: INPS | H4: NETTO REALE
D5: =IF(E5="PAGATO",C5-F5-G5,0) | F5: =IF(E5="PAGATO",C5*SETUP!$C$4*SETUP!$C$5,0) | G5: =IF(E5="PAGATO",IF(COUNTIF($E$5:E5,"PAGATO")=1,SETUP!$C$7,0),0) | H5: =IF(E5="PAGATO",C5-F5-G5,0) | J5: Fatturato Incassato | K5: =SUMIF(E5:E36,"PAGATO",C5:C36)
D6: =IF(E6="PAGATO",C6-F6-G6,0) | F6: =IF(E6="PAGATO",C6*SETUP!$C$4*SETUP!$C$5,0) | G6: =IF(E6="PAGATO",IF(COUNTIF($E$5:E6,"PAGATO")=1,SETUP!$C$7,0),0) | H6: =IF(E6="PAGATO",C6-F6-G6,0) | J6: Da Incassare | K6: =SUMIF(E5:E36,"DA PAGARE",C5:C36)
D7: =IF(E7="PAGATO",C7-F7-G7,0) | F7: =IF(E7="PAGATO",C7*SETUP!$C$4*SETUP!$C$5,0) | G7: =IF(E7="PAGATO",IF(COUNTIF($E$5:E7,"PAGATO")=1,SETUP!$C$7,0),0) | H7: =IF(E7="PAGATO",C7-F7-G7,0) | J7: Pipeline Programmata | K7: =SUMIF(E5:E36,"PROGRAMMATO",C5:C36)
D8: =IF(E8="PAGATO",C8-F8-G8,0) | F8: =IF(E8="PAGATO",C8*SETUP!$C$4*SETUP!$C$5,0) | G8: =IF(E8="PAGATO",IF(COUNTIF($E$5:E8,"PAGATO")=1,SETUP!$C$7,0),0) | H8: =IF(E8="PAGATO",C8-F8-G8,0) | J8: Entrate Nette Pure | K8: =C51
D9: =IF(E9="PAGATO",C9-F9-G9,0) | F9: =IF(E9="PAGATO",C9*SETUP!$C$4*SETUP!$C$5,0) | G9: =IF(E9="PAGATO",IF(COUNTIF($E$5:E9,"PAGATO")=1,SETUP!$C$7,0),0) | H9: =IF(E9="PAGATO",C9-F9-G9,0) | J9: Spese Effettive | K9: =C89
D10: =IF(E10="PAGATO",C10-F10-G10,0) | F10: =IF(E10="PAGATO",C10*SETUP!$C$4*SETUP!$C$5,0) | G10: =IF(E10="PAGATO",IF(COUNTIF($E$5:E10,"PAGATO")=1,SETUP!$C$7,0),0) | H10: =IF(E10="PAGATO",C10-F10-G10,0) | J10: Spese Programmate | K10: =C90
D11: =IF(E11="PAGATO",C11-F11-G11,0) | F11: =IF(E11="PAGATO",C11*SETUP!$C$4*SETUP!$C$5,0) | G11: =IF(E11="PAGATO",IF(COUNTIF($E$5:E11,"PAGATO")=1,SETUP!$C$7,0),0) | H11: =IF(E11="PAGATO",C11-F11-G11,0) | J11: Zavorra Fiscale | K11: =SUM(F5:F36)+SUM(G5:G36)
D12: =IF(E12="PAGATO",C12-F12-G12,0) | F12: =IF(E12="PAGATO",C12*SETUP!$C$4*SETUP!$C$5,0) | G12: =IF(E12="PAGATO",IF(COUNTIF($E$5:E12,"PAGATO")=1,SETUP!$C$7,0),0) | H12: =IF(E12="PAGATO",C12-F12-G12,0) | J12: Netto Reale Mensile | K12: =(K5-K11)+K8-K9
D13: =IF(E13="PAGATO",C13-F13-G13,0) | F13: =IF(E13="PAGATO",C13*SETUP!$C$4*SETUP!$C$5,0) | G13: =IF(E13="PAGATO",IF(COUNTIF($E$5:E13,"PAGATO")=1,SETUP!$C$7,0),0) | H13: =IF(E13="PAGATO",C13-F13-G13,0) | J13: Totale Secchielli | K13: =SUM(K20:K31)
D14: =IF(E14="PAGATO",C14-F14-G14,0) | F14: =IF(E14="PAGATO",C14*SETUP!$C$4*SETUP!$C$5,0) | G14: =IF(E14="PAGATO",IF(COUNTIF($E$5:E14,"PAGATO")=1,SETUP!$C$7,0),0) | H14: =IF(E14="PAGATO",C14-F14-G14,0) | J14: Netto Rimanente | K14: =K12-K13
D15: =IF(E15="PAGATO",C15-F15-G15,0) | F15: =IF(E15="PAGATO",C15*SETUP!$C$4*SETUP!$C$5,0) | G15: =IF(E15="PAGATO",IF(COUNTIF($E$5:E15,"PAGATO")=1,SETUP!$C$7,0),0) | H15: =IF(E15="PAGATO",C15-F15-G15,0) | J15: Imponibile Mese | K15: =K5*SETUP!$C$4
D16: =IF(E16="PAGATO",C16-F16-G16,0) | F16: =IF(E16="PAGATO",C16*SETUP!$C$4*SETUP!$C$5,0) | G16: =IF(E16="PAGATO",IF(COUNTIF($E$5:E16,"PAGATO")=1,SETUP!$C$7,0),0) | H16: =IF(E16="PAGATO",C16-F16-G16,0) | J16: Saving Rate | K16: =IFERROR(K13/K5,0)
D17: =IF(E17="PAGATO",C17-F17-G17,0) | F17: =IF(E17="PAGATO",C17*SETUP!$C$4*SETUP!$C$5,0) | G17: =IF(E17="PAGATO",IF(COUNTIF($E$5:E17,"PAGATO")=1,SETUP!$C$7,0),0) | H17: =IF(E17="PAGATO",C17-F17-G17,0) | J17: TAX SAFE | K17: =K14-K11
D18: =IF(E18="PAGATO",C18-F18-G18,0) | F18: =IF(E18="PAGATO",C18*SETUP!$C$4*SETUP!$C$5,0) | G18: =IF(E18="PAGATO",IF(COUNTIF($E$5:E18,"PAGATO")=1,SETUP!$C$7,0),0) | H18: =IF(E18="PAGATO",C18-F18-G18,0) | J18: STATO MESE | K18: =IF(K16>=0.2,"MESE SANO",IF(K16>=0.1,"ATTENZIONE",IF(K17<0,"TASSE A RISCHIO","SAVING BASSO")))
D19: =IF(E19="PAGATO",C19-F19-G19,0) | F19: =IF(E19="PAGATO",C19*SETUP!$C$4*SETUP!$C$5,0) | G19: =IF(E19="PAGATO",IF(COUNTIF($E$5:E19,"PAGATO")=1,SETUP!$C$7,0),0) | H19: =IF(E19="PAGATO",C19-F19-G19,0) | J19: SECCHIELLI RISPARMIO
D20: =IF(E20="PAGATO",C20-F20-G20,0) | F20: =IF(E20="PAGATO",C20*SETUP!$C$4*SETUP!$C$5,0) | G20: =IF(E20="PAGATO",IF(COUNTIF($E$5:E20,"PAGATO")=1,SETUP!$C$7,0),0) | H20: =IF(E20="PAGATO",C20-F20-G20,0) | J20: OBIETTIVO | K20: IMPORTO | L20: DESCRIZIONE
D21: =IF(E21="PAGATO",C21-F21-G21,0) | F21: =IF(E21="PAGATO",C21*SETUP!$C$4*SETUP!$C$5,0) | G21: =IF(E21="PAGATO",IF(COUNTIF($E$5:E21,"PAGATO")=1,SETUP!$C$7,0),0) | H21: =IF(E21="PAGATO",C21-F21-G21,0)
D22: =IF(E22="PAGATO",C22-F22-G22,0) | F22: =IF(E22="PAGATO",C22*SETUP!$C$4*SETUP!$C$5,0) | G22: =IF(E22="PAGATO",IF(COUNTIF($E$5:E22,"PAGATO")=1,SETUP!$C$7,0),0) | H22: =IF(E22="PAGATO",C22-F22-G22,0)
D23: =IF(E23="PAGATO",C23-F23-G23,0) | F23: =IF(E23="PAGATO",C23*SETUP!$C$4*SETUP!$C$5,0) | G23: =IF(E23="PAGATO",IF(COUNTIF($E$5:E23,"PAGATO")=1,SETUP!$C$7,0),0) | H23: =IF(E23="PAGATO",C23-F23-G23,0)
D24: =IF(E24="PAGATO",C24-F24-G24,0) | F24: =IF(E24="PAGATO",C24*SETUP!$C$4*SETUP!$C$5,0) | G24: =IF(E24="PAGATO",IF(COUNTIF($E$5:E24,"PAGATO")=1,SETUP!$C$7,0),0) | H24: =IF(E24="PAGATO",C24-F24-G24,0)
D25: =IF(E25="PAGATO",C25-F25-G25,0) | F25: =IF(E25="PAGATO",C25*SETUP!$C$4*SETUP!$C$5,0) | G25: =IF(E25="PAGATO",IF(COUNTIF($E$5:E25,"PAGATO")=1,SETUP!$C$7,0),0) | H25: =IF(E25="PAGATO",C25-F25-G25,0)
D26: =IF(E26="PAGATO",C26-F26-G26,0) | F26: =IF(E26="PAGATO",C26*SETUP!$C$4*SETUP!$C$5,0) | G26: =IF(E26="PAGATO",IF(COUNTIF($E$5:E26,"PAGATO")=1,SETUP!$C$7,0),0) | H26: =IF(E26="PAGATO",C26-F26-G26,0)
D27: =IF(E27="PAGATO",C27-F27-G27,0) | F27: =IF(E27="PAGATO",C27*SETUP!$C$4*SETUP!$C$5,0) | G27: =IF(E27="PAGATO",IF(COUNTIF($E$5:E27,"PAGATO")=1,SETUP!$C$7,0),0) | H27: =IF(E27="PAGATO",C27-F27-G27,0)
D28: =IF(E28="PAGATO",C28-F28-G28,0) | F28: =IF(E28="PAGATO",C28*SETUP!$C$4*SETUP!$C$5,0) | G28: =IF(E28="PAGATO",IF(COUNTIF($E$5:E28,"PAGATO")=1,SETUP!$C$7,0),0) | H28: =IF(E28="PAGATO",C28-F28-G28,0)
D29: =IF(E29="PAGATO",C29-F29-G29,0) | F29: =IF(E29="PAGATO",C29*SETUP!$C$4*SETUP!$C$5,0) | G29: =IF(E29="PAGATO",IF(COUNTIF($E$5:E29,"PAGATO")=1,SETUP!$C$7,0),0) | H29: =IF(E29="PAGATO",C29-F29-G29,0)
D30: =IF(E30="PAGATO",C30-F30-G30,0) | F30: =IF(E30="PAGATO",C30*SETUP!$C$4*SETUP!$C$5,0) | G30: =IF(E30="PAGATO",IF(COUNTIF($E$5:E30,"PAGATO")=1,SETUP!$C$7,0),0) | H30: =IF(E30="PAGATO",C30-F30-G30,0)
D31: =IF(E31="PAGATO",C31-F31-G31,0) | F31: =IF(E31="PAGATO",C31*SETUP!$C$4*SETUP!$C$5,0) | G31: =IF(E31="PAGATO",IF(COUNTIF($E$5:E31,"PAGATO")=1,SETUP!$C$7,0),0) | H31: =IF(E31="PAGATO",C31-F31-G31,0)
D32: =IF(E32="PAGATO",C32-F32-G32,0) | F32: =IF(E32="PAGATO",C32*SETUP!$C$4*SETUP!$C$5,0) | G32: =IF(E32="PAGATO",IF(COUNTIF($E$5:E32,"PAGATO")=1,SETUP!$C$7,0),0) | H32: =IF(E32="PAGATO",C32-F32-G32,0)
... D36: =IF(E36="PAGATO",C36-F36-G36,0) | F36: =IF(E36="PAGATO",C36*SETUP!$C$4*SETUP!$C$5,0) | G36: =IF(E36="PAGATO",IF(COUNTIF($E$5:E36,"PAGATO")=1,SETUP!$C$7,0),0) | H36: =IF(E36="PAGATO",C36-F36-G36,0)
B39: ENTRATE NETTE / ESENTASSE
B40: VOCE | C40: IMPORTO NETTO | D40: NOTE
B51: TOTALE ENTRATE NETTE | C51: =SUM(C41:C50)
B54: USCITE
B55: CATEGORIA | C55: IMPORTO | D55: DATA | E55: TIPO | F55: NOTE
B89: TOTALE USCITE EFFETTIVE | C89: =SUMIF(E56:E88,"EFFETTIVA",C56:C88)
B90: TOTALE SPESE PROGRAMMATE | C90: =SUMIF(E56:E88,"PROGRAMMATA",C56:C88)

Sheet MARZO
B1: MARZO 2026
B3: FATTURE P.IVA | J3: RIEPILOGO MESE
B4: CLIENTE | C4: LORDO | D4: NETTO | E4: STATO | F4: TASSE | G4: INPS | H4: NETTO REALE
D5: =IF(E5="PAGATO",C5-F5-G5,0) | F5: =IF(E5="PAGATO",C5*SETUP!$C$4*SETUP!$C$5,0) | G5: =IF(E5="PAGATO",IF(COUNTIF($E$5:E5,"PAGATO")=1,SETUP!$C$7,0),0) | H5: =IF(E5="PAGATO",C5-F5-G5,0) | J5: Fatturato Incassato | K5: =SUMIF(E5:E36,"PAGATO",C5:C36)
D6: =IF(E6="PAGATO",C6-F6-G6,0) | F6: =IF(E6="PAGATO",C6*SETUP!$C$4*SETUP!$C$5,0) | G6: =IF(E6="PAGATO",IF(COUNTIF($E$5:E6,"PAGATO")=1,SETUP!$C$7,0),0) | H6: =IF(E6="PAGATO",C6-F6-G6,0) | J6: Da Incassare | K6: =SUMIF(E5:E36,"DA PAGARE",C5:C36)
D7: =IF(E7="PAGATO",C7-F7-G7,0) | F7: =IF(E7="PAGATO",C7*SETUP!$C$4*SETUP!$C$5,0) | G7: =IF(E7="PAGATO",IF(COUNTIF($E$5:E7,"PAGATO")=1,SETUP!$C$7,0),0) | H7: =IF(E7="PAGATO",C7-F7-G7,0) | J7: Pipeline Programmata | K7: =SUMIF(E5:E36,"PROGRAMMATO",C5:C36)
D8: =IF(E8="PAGATO",C8-F8-G8,0) | F8: =IF(E8="PAGATO",C8*SETUP!$C$4*SETUP!$C$5,0) | G8: =IF(E8="PAGATO",IF(COUNTIF($E$5:E8,"PAGATO")=1,SETUP!$C$7,0),0) | H8: =IF(E8="PAGATO",C8-F8-G8,0) | J8: Entrate Nette Pure | K8: =C51
D9: =IF(E9="PAGATO",C9-F9-G9,0) | F9: =IF(E9="PAGATO",C9*SETUP!$C$4*SETUP!$C$5,0) | G9: =IF(E9="PAGATO",IF(COUNTIF($E$5:E9,"PAGATO")=1,SETUP!$C$7,0),0) | H9: =IF(E9="PAGATO",C9-F9-G9,0) | J9: Spese Effettive | K9: =C89
D10: =IF(E10="PAGATO",C10-F10-G10,0) | F10: =IF(E10="PAGATO",C10*SETUP!$C$4*SETUP!$C$5,0) | G10: =IF(E10="PAGATO",IF(COUNTIF($E$5:E10,"PAGATO")=1,SETUP!$C$7,0),0) | H10: =IF(E10="PAGATO",C10-F10-G10,0) | J10: Spese Programmate | K10: =C90
D11: =IF(E11="PAGATO",C11-F11-G11,0) | F11: =IF(E11="PAGATO",C11*SETUP!$C$4*SETUP!$C$5,0) | G11: =IF(E11="PAGATO",IF(COUNTIF($E$5:E11,"PAGATO")=1,SETUP!$C$7,0),0) | H11: =IF(E11="PAGATO",C11-F11-G11,0) | J11: Zavorra Fiscale | K11: =SUM(F5:F36)+SUM(G5:G36)
D12: =IF(E12="PAGATO",C12-F12-G12,0) | F12: =IF(E12="PAGATO",C12*SETUP!$C$4*SETUP!$C$5,0) | G12: =IF(E12="PAGATO",IF(COUNTIF($E$5:E12,"PAGATO")=1,SETUP!$C$7,0),0) | H12: =IF(E12="PAGATO",C12-F12-G12,0) | J12: Netto Reale Mensile | K12: =(K5-K11)+K8-K9
D13: =IF(E13="PAGATO",C13-F13-G13,0) | F13: =IF(E13="PAGATO",C13*SETUP!$C$4*SETUP!$C$5,0) | G13: =IF(E13="PAGATO",IF(COUNTIF($E$5:E13,"PAGATO")=1,SETUP!$C$7,0),0) | H13: =IF(E13="PAGATO",C13-F13-G13,0) | J13: Totale Secchielli | K13: =SUM(K20:K31)
D14: =IF(E14="PAGATO",C14-F14-G14,0) | F14: =IF(E14="PAGATO",C14*SETUP!$C$4*SETUP!$C$5,0) | G14: =IF(E14="PAGATO",IF(COUNTIF($E$5:E14,"PAGATO")=1,SETUP!$C$7,0),0) | H14: =IF(E14="PAGATO",C14-F14-G14,0) | J14: Netto Rimanente | K14: =K12-K13
D15: =IF(E15="PAGATO",C15-F15-G15,0) | F15: =IF(E15="PAGATO",C15*SETUP!$C$4*SETUP!$C$5,0) | G15: =IF(E15="PAGATO",IF(COUNTIF($E$5:E15,"PAGATO")=1,SETUP!$C$7,0),0) | H15: =IF(E15="PAGATO",C15-F15-G15,0) | J15: Imponibile Mese | K15: =K5*SETUP!$C$4
D16: =IF(E16="PAGATO",C16-F16-G16,0) | F16: =IF(E16="PAGATO",C16*SETUP!$C$4*SETUP!$C$5,0) | G16: =IF(E16="PAGATO",IF(COUNTIF($E$5:E16,"PAGATO")=1,SETUP!$C$7,0),0) | H16: =IF(E16="PAGATO",C16-F16-G16,0) | J16: Saving Rate | K16: =IFERROR(K13/K5,0)
D17: =IF(E17="PAGATO",C17-F17-G17,0) | F17: =IF(E17="PAGATO",C17*SETUP!$C$4*SETUP!$C$5,0) | G17: =IF(E17="PAGATO",IF(COUNTIF($E$5:E17,"PAGATO")=1,SETUP!$C$7,0),0) | H17: =IF(E17="PAGATO",C17-F17-G17,0) | J17: TAX SAFE | K17: =K14-K11
D18: =IF(E18="PAGATO",C18-F18-G18,0) | F18: =IF(E18="PAGATO",C18*SETUP!$C$4*SETUP!$C$5,0) | G18: =IF(E18="PAGATO",IF(COUNTIF($E$5:E18,"PAGATO")=1,SETUP!$C$7,0),0) | H18: =IF(E18="PAGATO",C18-F18-G18,0) | J18: STATO MESE | K18: =IF(K16>=0.2,"MESE SANO",IF(K16>=0.1,"ATTENZIONE",IF(K17<0,"TASSE A RISCHIO","SAVING BASSO")))
D19: =IF(E19="PAGATO",C19-F19-G19,0) | F19: =IF(E19="PAGATO",C19*SETUP!$C$4*SETUP!$C$5,0) | G19: =IF(E19="PAGATO",IF(COUNTIF($E$5:E19,"PAGATO")=1,SETUP!$C$7,0),0) | H19: =IF(E19="PAGATO",C19-F19-G19,0) | J19: SECCHIELLI RISPARMIO
D20: =IF(E20="PAGATO",C20-F20-G20,0) | F20: =IF(E20="PAGATO",C20*SETUP!$C$4*SETUP!$C$5,0) | G20: =IF(E20="PAGATO",IF(COUNTIF($E$5:E20,"PAGATO")=1,SETUP!$C$7,0),0) | H20: =IF(E20="PAGATO",C20-F20-G20,0) | J20: OBIETTIVO | K20: IMPORTO | L20: DESCRIZIONE
D21: =IF(E21="PAGATO",C21-F21-G21,0) | F21: =IF(E21="PAGATO",C21*SETUP!$C$4*SETUP!$C$5,0) | G21: =IF(E21="PAGATO",IF(COUNTIF($E$5:E21,"PAGATO")=1,SETUP!$C$7,0),0) | H21: =IF(E21="PAGATO",C21-F21-G21,0)
D22: =IF(E22="PAGATO",C22-F22-G22,0) | F22: =IF(E22="PAGATO",C22*SETUP!$C$4*SETUP!$C$5,0) | G22: =IF(E22="PAGATO",IF(COUNTIF($E$5:E22,"PAGATO")=1,SETUP!$C$7,0),0) | H22: =IF(E22="PAGATO",C22-F22-G22,0)
D23: =IF(E23="PAGATO",C23-F23-G23,0) | F23: =IF(E23="PAGATO",C23*SETUP!$C$4*SETUP!$C$5,0) | G23: =IF(E23="PAGATO",IF(COUNTIF($E$5:E23,"PAGATO")=1,SETUP!$C$7,0),0) | H23: =IF(E23="PAGATO",C23-F23-G23,0)
D24: =IF(E24="PAGATO",C24-F24-G24,0) | F24: =IF(E24="PAGATO",C24*SETUP!$C$4*SETUP!$C$5,0) | G24: =IF(E24="PAGATO",IF(COUNTIF($E$5:E24,"PAGATO")=1,SETUP!$C$7,0),0) | H24: =IF(E24="PAGATO",C24-F24-G24,0)
D25: =IF(E25="PAGATO",C25-F25-G25,0) | F25: =IF(E25="PAGATO",C25*SETUP!$C$4*SETUP!$C$5,0) | G25: =IF(E25="PAGATO",IF(COUNTIF($E$5:E25,"PAGATO")=1,SETUP!$C$7,0),0) | H25: =IF(E25="PAGATO",C25-F25-G25,0)
D26: =IF(E26="PAGATO",C26-F26-G26,0) | F26: =IF(E26="PAGATO",C26*SETUP!$C$4*SETUP!$C$5,0) | G26: =IF(E26="PAGATO",IF(COUNTIF($E$5:E26,"PAGATO")=1,SETUP!$C$7,0),0) | H26: =IF(E26="PAGATO",C26-F26-G26,0)
D27: =IF(E27="PAGATO",C27-F27-G27,0) | F27: =IF(E27="PAGATO",C27*SETUP!$C$4*SETUP!$C$5,0) | G27: =IF(E27="PAGATO",IF(COUNTIF($E$5:E27,"PAGATO")=1,SETUP!$C$7,0),0) | H27: =IF(E27="PAGATO",C27-F27-G27,0)
D28: =IF(E28="PAGATO",C28-F28-G28,0) | F28: =IF(E28="PAGATO",C28*SETUP!$C$4*SETUP!$C$5,0) | G28: =IF(E28="PAGATO",IF(COUNTIF($E$5:E28,"PAGATO")=1,SETUP!$C$7,0),0) | H28: =IF(E28="PAGATO",C28-F28-G28,0)
D29: =IF(E29="PAGATO",C29-F29-G29,0) | F29: =IF(E29="PAGATO",C29*SETUP!$C$4*SETUP!$C$5,0) | G29: =IF(E29="PAGATO",IF(COUNTIF($E$5:E29,"PAGATO")=1,SETUP!$C$7,0),0) | H29: =IF(E29="PAGATO",C29-F29-G29,0)
D30: =IF(E30="PAGATO",C30-F30-G30,0) | F30: =IF(E30="PAGATO",C30*SETUP!$C$4*SETUP!$C$5,0) | G30: =IF(E30="PAGATO",IF(COUNTIF($E$5:E30,"PAGATO")=1,SETUP!$C$7,0),0) | H30: =IF(E30="PAGATO",C30-F30-G30,0)
D31: =IF(E31="PAGATO",C31-F31-G31,0) | F31: =IF(E31="PAGATO",C31*SETUP!$C$4*SETUP!$C$5,0) | G31: =IF(E31="PAGATO",IF(COUNTIF($E$5:E31,"PAGATO")=1,SETUP!$C$7,0),0) | H31: =IF(E31="PAGATO",C31-F31-G31,0)
D32: =IF(E32="PAGATO",C32-F32-G32,0) | F32: =IF(E32="PAGATO",C32*SETUP!$C$4*SETUP!$C$5,0) | G32: =IF(E32="PAGATO",IF(COUNTIF($E$5:E32,"PAGATO")=1,SETUP!$C$7,0),0) | H32: =IF(E32="PAGATO",C32-F32-G32,0)
... D36: =IF(E36="PAGATO",C36-F36-G36,0) | F36: =IF(E36="PAGATO",C36*SETUP!$C$4*SETUP!$C$5,0) | G36: =IF(E36="PAGATO",IF(COUNTIF($E$5:E36,"PAGATO")=1,SETUP!$C$7,0),0) | H36: =IF(E36="PAGATO",C36-F36-G36,0)
B39: ENTRATE NETTE / ESENTASSE
B40: VOCE | C40: IMPORTO NETTO | D40: NOTE
B51: TOTALE ENTRATE NETTE | C51: =SUM(C41:C50)
B54: USCITE
B55: CATEGORIA | C55: IMPORTO | D55: DATA | E55: TIPO | F55: NOTE
B89: TOTALE USCITE EFFETTIVE | C89: =SUMIF(E56:E88,"EFFETTIVA",C56:C88)
B90: TOTALE SPESE PROGRAMMATE | C90: =SUMIF(E56:E88,"PROGRAMMATA",C56:C88)

Sheet APRILE
B1: APRILE 2026
B3: FATTURE P.IVA | J3: RIEPILOGO MESE
B4: CLIENTE | C4: LORDO | D4: NETTO | E4: STATO | F4: TASSE | G4: INPS | H4: NETTO REALE
D5: =IF(E5="PAGATO",C5-F5-G5,0) | F5: =IF(E5="PAGATO",C5*SETUP!$C$4*SETUP!$C$5,0) | G5: =IF(E5="PAGATO",IF(COUNTIF($E$5:E5,"PAGATO")=1,SETUP!$C$7,0),0) | H5: =IF(E5="PAGATO",C5-F5-G5,0) | J5: Fatturato Incassato | K5: =SUMIF(E5:E36,"PAGATO",C5:C36)
D6: =IF(E6="PAGATO",C6-F6-G6,0) | F6: =IF(E6="PAGATO",C6*SETUP!$C$4*SETUP!$C$5,0) | G6: =IF(E6="PAGATO",IF(COUNTIF($E$5:E6,"PAGATO")=1,SETUP!$C$7,0),0) | H6: =IF(E6="PAGATO",C6-F6-G6,0) | J6: Da Incassare | K6: =SUMIF(E5:E36,"DA PAGARE",C5:C36)
D7: =IF(E7="PAGATO",C7-F7-G7,0) | F7: =IF(E7="PAGATO",C7*SETUP!$C$4*SETUP!$C$5,0) | G7: =IF(E7="PAGATO",IF(COUNTIF($E$5:E7,"PAGATO")=1,SETUP!$C$7,0),0) | H7: =IF(E7="PAGATO",C7-F7-G7,0) | J7: Pipeline Programmata | K7: =SUMIF(E5:E36,"PROGRAMMATO",C5:C36)
D8: =IF(E8="PAGATO",C8-F8-G8,0) | F8: =IF(E8="PAGATO",C8*SETUP!$C$4*SETUP!$C$5,0) | G8: =IF(E8="PAGATO",IF(COUNTIF($E$5:E8,"PAGATO")=1,SETUP!$C$7,0),0) | H8: =IF(E8="PAGATO",C8-F8-G8,0) | J8: Entrate Nette Pure | K8: =C51
D9: =IF(E9="PAGATO",C9-F9-G9,0) | F9: =IF(E9="PAGATO",C9*SETUP!$C$4*SETUP!$C$5,0) | G9: =IF(E9="PAGATO",IF(COUNTIF($E$5:E9,"PAGATO")=1,SETUP!$C$7,0),0) | H9: =IF(E9="PAGATO",C9-F9-G9,0) | J9: Spese Effettive | K9: =C89
D10: =IF(E10="PAGATO",C10-F10-G10,0) | F10: =IF(E10="PAGATO",C10*SETUP!$C$4*SETUP!$C$5,0) | G10: =IF(E10="PAGATO",IF(COUNTIF($E$5:E10,"PAGATO")=1,SETUP!$C$7,0),0) | H10: =IF(E10="PAGATO",C10-F10-G10,0) | J10: Spese Programmate | K10: =C90
D11: =IF(E11="PAGATO",C11-F11-G11,0) | F11: =IF(E11="PAGATO",C11*SETUP!$C$4*SETUP!$C$5,0) | G11: =IF(E11="PAGATO",IF(COUNTIF($E$5:E11,"PAGATO")=1,SETUP!$C$7,0),0) | H11: =IF(E11="PAGATO",C11-F11-G11,0) | J11: Zavorra Fiscale | K11: =SUM(F5:F36)+SUM(G5:G36)
D12: =IF(E12="PAGATO",C12-F12-G12,0) | F12: =IF(E12="PAGATO",C12*SETUP!$C$4*SETUP!$C$5,0) | G12: =IF(E12="PAGATO",IF(COUNTIF($E$5:E12,"PAGATO")=1,SETUP!$C$7,0),0) | H12: =IF(E12="PAGATO",C12-F12-G12,0) | J12: Netto Reale Mensile | K12: =(K5-K11)+K8-K9
D13: =IF(E13="PAGATO",C13-F13-G13,0) | F13: =IF(E13="PAGATO",C13*SETUP!$C$4*SETUP!$C$5,0) | G13: =IF(E13="PAGATO",IF(COUNTIF($E$5:E13,"PAGATO")=1,SETUP!$C$7,0),0) | H13: =IF(E13="PAGATO",C13-F13-G13,0) | J13: Totale Secchielli | K13: =SUM(K20:K31)
D14: =IF(E14="PAGATO",C14-F14-G14,0) | F14: =IF(E14="PAGATO",C14*SETUP!$C$4*SETUP!$C$5,0) | G14: =IF(E14="PAGATO",IF(COUNTIF($E$5:E14,"PAGATO")=1,SETUP!$C$7,0),0) | H14: =IF(E14="PAGATO",C14-F14-G14,0) | J14: Netto Rimanente | K14: =K12-K13
D15: =IF(E15="PAGATO",C15-F15-G15,0) | F15: =IF(E15="PAGATO",C15*SETUP!$C$4*SETUP!$C$5,0) | G15: =IF(E15="PAGATO",IF(COUNTIF($E$5:E15,"PAGATO")=1,SETUP!$C$7,0),0) | H15: =IF(E15="PAGATO",C15-F15-G15,0) | J15: Imponibile Mese | K15: =K5*SETUP!$C$4
D16: =IF(E16="PAGATO",C16-F16-G16,0) | F16: =IF(E16="PAGATO",C16*SETUP!$C$4*SETUP!$C$5,0) | G16: =IF(E16="PAGATO",IF(COUNTIF($E$5:E16,"PAGATO")=1,SETUP!$C$7,0),0) | H16: =IF(E16="PAGATO",C16-F16-G16,0) | J16: Saving Rate | K16: =IFERROR(K13/K5,0)
D17: =IF(E17="PAGATO",C17-F17-G17,0) | F17: =IF(E17="PAGATO",C17*SETUP!$C$4*SETUP!$C$5,0) | G17: =IF(E17="PAGATO",IF(COUNTIF($E$5:E17,"PAGATO")=1,SETUP!$C$7,0),0) | H17: =IF(E17="PAGATO",C17-F17-G17,0) | J17: TAX SAFE | K17: =K14-K11
D18: =IF(E18="PAGATO",C18-F18-G18,0) | F18: =IF(E18="PAGATO",C18*SETUP!$C$4*SETUP!$C$5,0) | G18: =IF(E18="PAGATO",IF(COUNTIF($E$5:E18,"PAGATO")=1,SETUP!$C$7,0),0) | H18: =IF(E18="PAGATO",C18-F18-G18,0) | J18: STATO MESE | K18: =IF(K16>=0.2,"MESE SANO",IF(K16>=0.1,"ATTENZIONE",IF(K17<0,"TASSE A RISCHIO","SAVING BASSO")))
D19: =IF(E19="PAGATO",C19-F19-G19,0) | F19: =IF(E19="PAGATO",C19*SETUP!$C$4*SETUP!$C$5,0) | G19: =IF(E19="PAGATO",IF(COUNTIF($E$5:E19,"PAGATO")=1,SETUP!$C$7,0),0) | H19: =IF(E19="PAGATO",C19-F19-G19,0) | J19: SECCHIELLI RISPARMIO
D20: =IF(E20="PAGATO",C20-F20-G20,0) | F20: =IF(E20="PAGATO",C20*SETUP!$C$4*SETUP!$C$5,0) | G20: =IF(E20="PAGATO",IF(COUNTIF($E$5:E20,"PAGATO")=1,SETUP!$C$7,0),0) | H20: =IF(E20="PAGATO",C20-F20-G20,0) | J20: OBIETTIVO | K20: IMPORTO | L20: DESCRIZIONE
D21: =IF(E21="PAGATO",C21-F21-G21,0) | F21: =IF(E21="PAGATO",C21*SETUP!$C$4*SETUP!$C$5,0) | G21: =IF(E21="PAGATO",IF(COUNTIF($E$5:E21,"PAGATO")=1,SETUP!$C$7,0),0) | H21: =IF(E21="PAGATO",C21-F21-G21,0)
D22: =IF(E22="PAGATO",C22-F22-G22,0) | F22: =IF(E22="PAGATO",C22*SETUP!$C$4*SETUP!$C$5,0) | G22: =IF(E22="PAGATO",IF(COUNTIF($E$5:E22,"PAGATO")=1,SETUP!$C$7,0),0) | H22: =IF(E22="PAGATO",C22-F22-G22,0)
D23: =IF(E23="PAGATO",C23-F23-G23,0) | F23: =IF(E23="PAGATO",C23*SETUP!$C$4*SETUP!$C$5,0) | G23: =IF(E23="PAGATO",IF(COUNTIF($E$5:E23,"PAGATO")=1,SETUP!$C$7,0),0) | H23: =IF(E23="PAGATO",C23-F23-G23,0)
D24: =IF(E24="PAGATO",C24-F24-G24,0) | F24: =IF(E24="PAGATO",C24*SETUP!$C$4*SETUP!$C$5,0) | G24: =IF(E24="PAGATO",IF(COUNTIF($E$5:E24,"PAGATO")=1,SETUP!$C$7,0),0) | H24: =IF(E24="PAGATO",C24-F24-G24,0)
D25: =IF(E25="PAGATO",C25-F25-G25,0) | F25: =IF(E25="PAGATO",C25*SETUP!$C$4*SETUP!$C$5,0) | G25: =IF(E25="PAGATO",IF(COUNTIF($E$5:E25,"PAGATO")=1,SETUP!$C$7,0),0) | H25: =IF(E25="PAGATO",C25-F25-G25,0)
D26: =IF(E26="PAGATO",C26-F26-G26,0) | F26: =IF(E26="PAGATO",C26*SETUP!$C$4*SETUP!$C$5,0) | G26: =IF(E26="PAGATO",IF(COUNTIF($E$5:E26,"PAGATO")=1,SETUP!$C$7,0),0) | H26: =IF(E26="PAGATO",C26-F26-G26,0)
D27: =IF(E27="PAGATO",C27-F27-G27,0) | F27: =IF(E27="PAGATO",C27*SETUP!$C$4*SETUP!$C$5,0) | G27: =IF(E27="PAGATO",IF(COUNTIF($E$5:E27,"PAGATO")=1,SETUP!$C$7,0),0) | H27: =IF(E27="PAGATO",C27-F27-G27,0)
D28: =IF(E28="PAGATO",C28-F28-G28,0) | F28: =IF(E28="PAGATO",C28*SETUP!$C$4*SETUP!$C$5,0) | G28: =IF(E28="PAGATO",IF(COUNTIF($E$5:E28,"PAGATO")=1,SETUP!$C$7,0),0) | H28: =IF(E28="PAGATO",C28-F28-G28,0)
D29: =IF(E29="PAGATO",C29-F29-G29,0) | F29: =IF(E29="PAGATO",C29*SETUP!$C$4*SETUP!$C$5,0) | G29: =IF(E29="PAGATO",IF(COUNTIF($E$5:E29,"PAGATO")=1,SETUP!$C$7,0),0) | H29: =IF(E29="PAGATO",C29-F29-G29,0)
D30: =IF(E30="PAGATO",C30-F30-G30,0) | F30: =IF(E30="PAGATO",C30*SETUP!$C$4*SETUP!$C$5,0) | G30: =IF(E30="PAGATO",IF(COUNTIF($E$5:E30,"PAGATO")=1,SETUP!$C$7,0),0) | H30: =IF(E30="PAGATO",C30-F30-G30,0)
D31: =IF(E31="PAGATO",C31-F31-G31,0) | F31: =IF(E31="PAGATO",C31*SETUP!$C$4*SETUP!$C$5,0) | G31: =IF(E31="PAGATO",IF(COUNTIF($E$5:E31,"PAGATO")=1,SETUP!$C$7,0),0) | H31: =IF(E31="PAGATO",C31-F31-G31,0)
D32: =IF(E32="PAGATO",C32-F32-G32,0) | F32: =IF(E32="PAGATO",C32*SETUP!$C$4*SETUP!$C$5,0) | G32: =IF(E32="PAGATO",IF(COUNTIF($E$5:E32,"PAGATO")=1,SETUP!$C$7,0),0) | H32: =IF(E32="PAGATO",C32-F32-G32,0)
... D36: =IF(E36="PAGATO",C36-F36-G36,0) | F36: =IF(E36="PAGATO",C36*SETUP!$C$4*SETUP!$C$5,0) | G36: =IF(E36="PAGATO",IF(COUNTIF($E$5:E36,"PAGATO")=1,SETUP!$C$7,0),0) | H36: =IF(E36="PAGATO",C36-F36-G36,0)
B39: ENTRATE NETTE / ESENTASSE
B40: VOCE | C40: IMPORTO NETTO | D40: NOTE
B51: TOTALE ENTRATE NETTE | C51: =SUM(C41:C50)
B54: USCITE
B55: CATEGORIA | C55: IMPORTO | D55: DATA | E55: TIPO | F55: NOTE
B89: TOTALE USCITE EFFETTIVE | C89: =SUMIF(E56:E88,"EFFETTIVA",C56:C88)
B90: TOTALE SPESE PROGRAMMATE | C90: =SUMIF(E56:E88,"PROGRAMMATA",C56:C88)

Sheet MAGGIO
B1: MAGGIO 2026
B3: FATTURE P.IVA | J3: RIEPILOGO MESE
B4: CLIENTE | C4: LORDO | D4: NETTO | E4: STATO | F4: TASSE | G4: INPS | H4: NETTO REALE
D5: =IF(E5="PAGATO",C5-F5-G5,0) | F5: =IF(E5="PAGATO",C5*SETUP!$C$4*SETUP!$C$5,0) | G5: =IF(E5="PAGATO",IF(COUNTIF($E$5:E5,"PAGATO")=1,SETUP!$C$7,0),0) | H5: =IF(E5="PAGATO",C5-F5-G5,0) | J5: Fatturato Incassato | K5: =SUMIF(E5:E36,"PAGATO",C5:C36)
D6: =IF(E6="PAGATO",C6-F6-G6,0) | F6: =IF(E6="PAGATO",C6*SETUP!$C$4*SETUP!$C$5,0) | G6: =IF(E6="PAGATO",IF(COUNTIF($E$5:E6,"PAGATO")=1,SETUP!$C$7,0),0) | H6: =IF(E6="PAGATO",C6-F6-G6,0) | J6: Da Incassare | K6: =SUMIF(E5:E36,"DA PAGARE",C5:C36)
D7: =IF(E7="PAGATO",C7-F7-G7,0) | F7: =IF(E7="PAGATO",C7*SETUP!$C$4*SETUP!$C$5,0) | G7: =IF(E7="PAGATO",IF(COUNTIF($E$5:E7,"PAGATO")=1,SETUP!$C$7,0),0) | H7: =IF(E7="PAGATO",C7-F7-G7,0) | J7: Pipeline Programmata | K7: =SUMIF(E5:E36,"PROGRAMMATO",C5:C36)
D8: =IF(E8="PAGATO",C8-F8-G8,0) | F8: =IF(E8="PAGATO",C8*SETUP!$C$4*SETUP!$C$5,0) | G8: =IF(E8="PAGATO",IF(COUNTIF($E$5:E8,"PAGATO")=1,SETUP!$C$7,0),0) | H8: =IF(E8="PAGATO",C8-F8-G8,0) | J8: Entrate Nette Pure | K8: =C51
D9: =IF(E9="PAGATO",C9-F9-G9,0) | F9: =IF(E9="PAGATO",C9*SETUP!$C$4*SETUP!$C$5,0) | G9: =IF(E9="PAGATO",IF(COUNTIF($E$5:E9,"PAGATO")=1,SETUP!$C$7,0),0) | H9: =IF(E9="PAGATO",C9-F9-G9,0) | J9: Spese Effettive | K9: =C89
D10: =IF(E10="PAGATO",C10-F10-G10,0) | F10: =IF(E10="PAGATO",C10*SETUP!$C$4*SETUP!$C$5,0) | G10: =IF(E10="PAGATO",IF(COUNTIF($E$5:E10,"PAGATO")=1,SETUP!$C$7,0),0) | H10: =IF(E10="PAGATO",C10-F10-G10,0) | J10: Spese Programmate | K10: =C90
D11: =IF(E11="PAGATO",C11-F11-G11,0) | F11: =IF(E11="PAGATO",C11*SETUP!$C$4*SETUP!$C$5,0) | G11: =IF(E11="PAGATO",IF(COUNTIF($E$5:E11,"PAGATO")=1,SETUP!$C$7,0),0) | H11: =IF(E11="PAGATO",C11-F11-G11,0) | J11: Zavorra Fiscale | K11: =SUM(F5:F36)+SUM(G5:G36)
D12: =IF(E12="PAGATO",C12-F12-G12,0) | F12: =IF(E12="PAGATO",C12*SETUP!$C$4*SETUP!$C$5,0) | G12: =IF(E12="PAGATO",IF(COUNTIF($E$5:E12,"PAGATO")=1,SETUP!$C$7,0),0) | H12: =IF(E12="PAGATO",C12-F12-G12,0) | J12: Netto Reale Mensile | K12: =(K5-K11)+K8-K9
D13: =IF(E13="PAGATO",C13-F13-G13,0) | F13: =IF(E13="PAGATO",C13*SETUP!$C$4*SETUP!$C$5,0) | G13: =IF(E13="PAGATO",IF(COUNTIF($E$5:E13,"PAGATO")=1,SETUP!$C$7,0),0) | H13: =IF(E13="PAGATO",C13-F13-G13,0) | J13: Totale Secchielli | K13: =SUM(K20:K31)
D14: =IF(E14="PAGATO",C14-F14-G14,0) | F14: =IF(E14="PAGATO",C14*SETUP!$C$4*SETUP!$C$5,0) | G14: =IF(E14="PAGATO",IF(COUNTIF($E$5:E14,"PAGATO")=1,SETUP!$C$7,0),0) | H14: =IF(E14="PAGATO",C14-F14-G14,0) | J14: Netto Rimanente | K14: =K12-K13
D15: =IF(E15="PAGATO",C15-F15-G15,0) | F15: =IF(E15="PAGATO",C15*SETUP!$C$4*SETUP!$C$5,0) | G15: =IF(E15="PAGATO",IF(COUNTIF($E$5:E15,"PAGATO")=1,SETUP!$C$7,0),0) | H15: =IF(E15="PAGATO",C15-F15-G15,0) | J15: Imponibile Mese | K15: =K5*SETUP!$C$4
D16: =IF(E16="PAGATO",C16-F16-G16,0) | F16: =IF(E16="PAGATO",C16*SETUP!$C$4*SETUP!$C$5,0) | G16: =IF(E16="PAGATO",IF(COUNTIF($E$5:E16,"PAGATO")=1,SETUP!$C$7,0),0) | H16: =IF(E16="PAGATO",C16-F16-G16,0) | J16: Saving Rate | K16: =IFERROR(K13/K5,0)
D17: =IF(E17="PAGATO",C17-F17-G17,0) | F17: =IF(E17="PAGATO",C17*SETUP!$C$4*SETUP!$C$5,0) | G17: =IF(E17="PAGATO",IF(COUNTIF($E$5:E17,"PAGATO")=1,SETUP!$C$7,0),0) | H17: =IF(E17="PAGATO",C17-F17-G17,0) | J17: TAX SAFE | K17: =K14-K11
D18: =IF(E18="PAGATO",C18-F18-G18,0) | F18: =IF(E18="PAGATO",C18*SETUP!$C$4*SETUP!$C$5,0) | G18: =IF(E18="PAGATO",IF(COUNTIF($E$5:E18,"PAGATO")=1,SETUP!$C$7,0),0) | H18: =IF(E18="PAGATO",C18-F18-G18,0) | J18: STATO MESE | K18: =IF(K16>=0.2,"MESE SANO",IF(K16>=0.1,"ATTENZIONE",IF(K17<0,"TASSE A RISCHIO","SAVING BASSO")))
D19: =IF(E19="PAGATO",C19-F19-G19,0) | F19: =IF(E19="PAGATO",C19*SETUP!$C$4*SETUP!$C$5,0) | G19: =IF(E19="PAGATO",IF(COUNTIF($E$5:E19,"PAGATO")=1,SETUP!$C$7,0),0) | H19: =IF(E19="PAGATO",C19-F19-G19,0) | J19: SECCHIELLI RISPARMIO
D20: =IF(E20="PAGATO",C20-F20-G20,0) | F20: =IF(E20="PAGATO",C20*SETUP!$C$4*SETUP!$C$5,0) | G20: =IF(E20="PAGATO",IF(COUNTIF($E$5:E20,"PAGATO")=1,SETUP!$C$7,0),0) | H20: =IF(E20="PAGATO",C20-F20-G20,0) | J20: OBIETTIVO | K20: IMPORTO | L20: DESCRIZIONE
D21: =IF(E21="PAGATO",C21-F21-G21,0) | F21: =IF(E21="PAGATO",C21*SETUP!$C$4*SETUP!$C$5,0) | G21: =IF(E21="PAGATO",IF(COUNTIF($E$5:E21,"PAGATO")=1,SETUP!$C$7,0),0) | H21: =IF(E21="PAGATO",C21-F21-G21,0)
D22: =IF(E22="PAGATO",C22-F22-G22,0) | F22: =IF(E22="PAGATO",C22*SETUP!$C$4*SETUP!$C$5,0) | G22: =IF(E22="PAGATO",IF(COUNTIF($E$5:E22,"PAGATO")=1,SETUP!$C$7,0),0) | H22: =IF(E22="PAGATO",C22-F22-G22,0)
D23: =IF(E23="PAGATO",C23-F23-G23,0) | F23: =IF(E23="PAGATO",C23*SETUP!$C$4*SETUP!$C$5,0) | G23: =IF(E23="PAGATO",IF(COUNTIF($E$5:E23,"PAGATO")=1,SETUP!$C$7,0),0) | H23: =IF(E23="PAGATO",C23-F23-G23,0)
D24: =IF(E24="PAGATO",C24-F24-G24,0) | F24: =IF(E24="PAGATO",C24*SETUP!$C$4*SETUP!$C$5,0) | G24: =IF(E24="PAGATO",IF(COUNTIF($E$5:E24,"PAGATO")=1,SETUP!$C$7,0),0) | H24: =IF(E24="PAGATO",C24-F24-G24,0)
D25: =IF(E25="PAGATO",C25-F25-G25,0) | F25: =IF(E25="PAGATO",C25*SETUP!$C$4*SETUP!$C$5,0) | G25: =IF(E25="PAGATO",IF(COUNTIF($E$5:E25,"PAGATO")=1,SETUP!$C$7,0),0) | H25: =IF(E25="PAGATO",C25-F25-G25,0)
D26: =IF(E26="PAGATO",C26-F26-G26,0) | F26: =IF(E26="PAGATO",C26*SETUP!$C$4*SETUP!$C$5,0) | G26: =IF(E26="PAGATO",IF(COUNTIF($E$5:E26,"PAGATO")=1,SETUP!$C$7,0),0) | H26: =IF(E26="PAGATO",C26-F26-G26,0)
D27: =IF(E27="PAGATO",C27-F27-G27,0) | F27: =IF(E27="PAGATO",C27*SETUP!$C$4*SETUP!$C$5,0) | G27: =IF(E27="PAGATO",IF(COUNTIF($E$5:E27,"PAGATO")=1,SETUP!$C$7,0),0) | H27: =IF(E27="PAGATO",C27-F27-G27,0)
D28: =IF(E28="PAGATO",C28-F28-G28,0) | F28: =IF(E28="PAGATO",C28*SETUP!$C$4*SETUP!$C$5,0) | G28: =IF(E28="PAGATO",IF(COUNTIF($E$5:E28,"PAGATO")=1,SETUP!$C$7,0),0) | H28: =IF(E28="PAGATO",C28-F28-G28,0)
D29: =IF(E29="PAGATO",C29-F29-G29,0) | F29: =IF(E29="PAGATO",C29*SETUP!$C$4*SETUP!$C$5,0) | G29: =IF(E29="PAGATO",IF(COUNTIF($E$5:E29,"PAGATO")=1,SETUP!$C$7,0),0) | H29: =IF(E29="PAGATO",C29-F29-G29,0)
D30: =IF(E30="PAGATO",C30-F30-G30,0) | F30: =IF(E30="PAGATO",C30*SETUP!$C$4*SETUP!$C$5,0) | G30: =IF(E30="PAGATO",IF(COUNTIF($E$5:E30,"PAGATO")=1,SETUP!$C$7,0),0) | H30: =IF(E30="PAGATO",C30-F30-G30,0)
D31: =IF(E31="PAGATO",C31-F31-G31,0) | F31: =IF(E31="PAGATO",C31*SETUP!$C$4*SETUP!$C$5,0) | G31: =IF(E31="PAGATO",IF(COUNTIF($E$5:E31,"PAGATO")=1,SETUP!$C$7,0),0) | H31: =IF(E31="PAGATO",C31-F31-G31,0)
D32: =IF(E32="PAGATO",C32-F32-G32,0) | F32: =IF(E32="PAGATO",C32*SETUP!$C$4*SETUP!$C$5,0) | G32: =IF(E32="PAGATO",IF(COUNTIF($E$5:E32,"PAGATO")=1,SETUP!$C$7,0),0) | H32: =IF(E32="PAGATO",C32-F32-G32,0)
... D36: =IF(E36="PAGATO",C36-F36-G36,0) | F36: =IF(E36="PAGATO",C36*SETUP!$C$4*SETUP!$C$5,0) | G36: =IF(E36="PAGATO",IF(COUNTIF($E$5:E36,"PAGATO")=1,SETUP!$C$7,0),0) | H36: =IF(E36="PAGATO",C36-F36-G36,0)
B39: ENTRATE NETTE / ESENTASSE
B40: VOCE | C40: IMPORTO NETTO | D40: NOTE
B51: TOTALE ENTRATE NETTE | C51: =SUM(C41:C50)
B54: USCITE
B55: CATEGORIA | C55: IMPORTO | D55: DATA | E55: TIPO | F55: NOTE
B89: TOTALE USCITE EFFETTIVE | C89: =SUMIF(E56:E88,"EFFETTIVA",C56:C88)
B90: TOTALE SPESE PROGRAMMATE | C90: =SUMIF(E56:E88,"PROGRAMMATA",C56:C88)

Sheet GIUGNO
B1: GIUGNO 2026
B3: FATTURE P.IVA | J3: RIEPILOGO MESE
B4: CLIENTE | C4: LORDO | D4: NETTO | E4: STATO | F4: TASSE | G4: INPS | H4: NETTO REALE
D5: =IF(E5="PAGATO",C5-F5-G5,0) | F5: =IF(E5="PAGATO",C5*SETUP!$C$4*SETUP!$C$5,0) | G5: =IF(E5="PAGATO",IF(COUNTIF($E$5:E5,"PAGATO")=1,SETUP!$C$7,0),0) | H5: =IF(E5="PAGATO",C5-F5-G5,0) | J5: Fatturato Incassato | K5: =SUMIF(E5:E36,"PAGATO",C5:C36)
D6: =IF(E6="PAGATO",C6-F6-G6,0) | F6: =IF(E6="PAGATO",C6*SETUP!$C$4*SETUP!$C$5,0) | G6: =IF(E6="PAGATO",IF(COUNTIF($E$5:E6,"PAGATO")=1,SETUP!$C$7,0),0) | H6: =IF(E6="PAGATO",C6-F6-G6,0) | J6: Da Incassare | K6: =SUMIF(E5:E36,"DA PAGARE",C5:C36)
D7: =IF(E7="PAGATO",C7-F7-G7,0) | F7: =IF(E7="PAGATO",C7*SETUP!$C$4*SETUP!$C$5,0) | G7: =IF(E7="PAGATO",IF(COUNTIF($E$5:E7,"PAGATO")=1,SETUP!$C$7,0),0) | H7: =IF(E7="PAGATO",C7-F7-G7,0) | J7: Pipeline Programmata | K7: =SUMIF(E5:E36,"PROGRAMMATO",C5:C36)
D8: =IF(E8="PAGATO",C8-F8-G8,0) | F8: =IF(E8="PAGATO",C8*SETUP!$C$4*SETUP!$C$5,0) | G8: =IF(E8="PAGATO",IF(COUNTIF($E$5:E8,"PAGATO")=1,SETUP!$C$7,0),0) | H8: =IF(E8="PAGATO",C8-F8-G8,0) | J8: Entrate Nette Pure | K8: =C51
D9: =IF(E9="PAGATO",C9-F9-G9,0) | F9: =IF(E9="PAGATO",C9*SETUP!$C$4*SETUP!$C$5,0) | G9: =IF(E9="PAGATO",IF(COUNTIF($E$5:E9,"PAGATO")=1,SETUP!$C$7,0),0) | H9: =IF(E9="PAGATO",C9-F9-G9,0) | J9: Spese Effettive | K9: =C89
D10: =IF(E10="PAGATO",C10-F10-G10,0) | F10: =IF(E10="PAGATO",C10*SETUP!$C$4*SETUP!$C$5,0) | G10: =IF(E10="PAGATO",IF(COUNTIF($E$5:E10,"PAGATO")=1,SETUP!$C$7,0),0) | H10: =IF(E10="PAGATO",C10-F10-G10,0) | J10: Spese Programmate | K10: =C90
D11: =IF(E11="PAGATO",C11-F11-G11,0) | F11: =IF(E11="PAGATO",C11*SETUP!$C$4*SETUP!$C$5,0) | G11: =IF(E11="PAGATO",IF(COUNTIF($E$5:E11,"PAGATO")=1,SETUP!$C$7,0),0) | H11: =IF(E11="PAGATO",C11-F11-G11,0) | J11: Zavorra Fiscale | K11: =SUM(F5:F36)+SUM(G5:G36)
D12: =IF(E12="PAGATO",C12-F12-G12,0) | F12: =IF(E12="PAGATO",C12*SETUP!$C$4*SETUP!$C$5,0) | G12: =IF(E12="PAGATO",IF(COUNTIF($E$5:E12,"PAGATO")=1,SETUP!$C$7,0),0) | H12: =IF(E12="PAGATO",C12-F12-G12,0) | J12: Netto Reale Mensile | K12: =(K5-K11)+K8-K9
D13: =IF(E13="PAGATO",C13-F13-G13,0) | F13: =IF(E13="PAGATO",C13*SETUP!$C$4*SETUP!$C$5,0) | G13: =IF(E13="PAGATO",IF(COUNTIF($E$5:E13,"PAGATO")=1,SETUP!$C$7,0),0) | H13: =IF(E13="PAGATO",C13-F13-G13,0) | J13: Totale Secchielli | K13: =SUM(K20:K31)
D14: =IF(E14="PAGATO",C14-F14-G14,0) | F14: =IF(E14="PAGATO",C14*SETUP!$C$4*SETUP!$C$5,0) | G14: =IF(E14="PAGATO",IF(COUNTIF($E$5:E14,"PAGATO")=1,SETUP!$C$7,0),0) | H14: =IF(E14="PAGATO",C14-F14-G14,0) | J14: Netto Rimanente | K14: =K12-K13
D15: =IF(E15="PAGATO",C15-F15-G15,0) | F15: =IF(E15="PAGATO",C15*SETUP!$C$4*SETUP!$C$5,0) | G15: =IF(E15="PAGATO",IF(COUNTIF($E$5:E15,"PAGATO")=1,SETUP!$C$7,0),0) | H15: =IF(E15="PAGATO",C15-F15-G15,0) | J15: Imponibile Mese | K15: =K5*SETUP!$C$4
D16: =IF(E16="PAGATO",C16-F16-G16,0) | F16: =IF(E16="PAGATO",C16*SETUP!$C$4*SETUP!$C$5,0) | G16: =IF(E16="PAGATO",IF(COUNTIF($E$5:E16,"PAGATO")=1,SETUP!$C$7,0),0) | H16: =IF(E16="PAGATO",C16-F16-G16,0) | J16: Saving Rate | K16: =IFERROR(K13/K5,0)
D17: =IF(E17="PAGATO",C17-F17-G17,0) | F17: =IF(E17="PAGATO",C17*SETUP!$C$4*SETUP!$C$5,0) | G17: =IF(E17="PAGATO",IF(COUNTIF($E$5:E17,"PAGATO")=1,SETUP!$C$7,0),0) | H17: =IF(E17="PAGATO",C17-F17-G17,0) | J17: TAX SAFE | K17: =K14-K11
D18: =IF(E18="PAGATO",C18-F18-G18,0) | F18: =IF(E18="PAGATO",C18*SETUP!$C$4*SETUP!$C$5,0) | G18: =IF(E18="PAGATO",IF(COUNTIF($E$5:E18,"PAGATO")=1,SETUP!$C$7,0),0) | H18: =IF(E18="PAGATO",C18-F18-G18,0) | J18: STATO MESE | K18: =IF(K16>=0.2,"MESE SANO",IF(K16>=0.1,"ATTENZIONE",IF(K17<0,"TASSE A RISCHIO","SAVING BASSO")))
D19: =IF(E19="PAGATO",C19-F19-G19,0) | F19: =IF(E19="PAGATO",C19*SETUP!$C$4*SETUP!$C$5,0) | G19: =IF(E19="PAGATO",IF(COUNTIF($E$5:E19,"PAGATO")=1,SETUP!$C$7,0),0) | H19: =IF(E19="PAGATO",C19-F19-G19,0) | J19: SECCHIELLI RISPARMIO
D20: =IF(E20="PAGATO",C20-F20-G20,0) | F20: =IF(E20="PAGATO",C20*SETUP!$C$4*SETUP!$C$5,0) | G20: =IF(E20="PAGATO",IF(COUNTIF($E$5:E20,"PAGATO")=1,SETUP!$C$7,0),0) | H20: =IF(E20="PAGATO",C20-F20-G20,0) | J20: OBIETTIVO | K20: IMPORTO | L20: DESCRIZIONE
D21: =IF(E21="PAGATO",C21-F21-G21,0) | F21: =IF(E21="PAGATO",C21*SETUP!$C$4*SETUP!$C$5,0) | G21: =IF(E21="PAGATO",IF(COUNTIF($E$5:E21,"PAGATO")=1,SETUP!$C$7,0),0) | H21: =IF(E21="PAGATO",C21-F21-G21,0)
D22: =IF(E22="PAGATO",C22-F22-G22,0) | F22: =IF(E22="PAGATO",C22*SETUP!$C$4*SETUP!$C$5,0) | G22: =IF(E22="PAGATO",IF(COUNTIF($E$5:E22,"PAGATO")=1,SETUP!$C$7,0),0) | H22: =IF(E22="PAGATO",C22-F22-G22,0)
D23: =IF(E23="PAGATO",C23-F23-G23,0) | F23: =IF(E23="PAGATO",C23*SETUP!$C$4*SETUP!$C$5,0) | G23: =IF(E23="PAGATO",IF(COUNTIF($E$5:E23,"PAGATO")=1,SETUP!$C$7,0),0) | H23: =IF(E23="PAGATO",C23-F23-G23,0)
D24: =IF(E24="PAGATO",C24-F24-G24,0) | F24: =IF(E24="PAGATO",C24*SETUP!$C$4*SETUP!$C$5,0) | G24: =IF(E24="PAGATO",IF(COUNTIF($E$5:E24,"PAGATO")=1,SETUP!$C$7,0),0) | H24: =IF(E24="PAGATO",C24-F24-G24,0)
D25: =IF(E25="PAGATO",C25-F25-G25,0) | F25: =IF(E25="PAGATO",C25*SETUP!$C$4*SETUP!$C$5,0) | G25: =IF(E25="PAGATO",IF(COUNTIF($E$5:E25,"PAGATO")=1,SETUP!$C$7,0),0) | H25: =IF(E25="PAGATO",C25-F25-G25,0)
D26: =IF(E26="PAGATO",C26-F26-G26,0) | F26: =IF(E26="PAGATO",C26*SETUP!$C$4*SETUP!$C$5,0) | G26: =IF(E26="PAGATO",IF(COUNTIF($E$5:E26,"PAGATO")=1,SETUP!$C$7,0),0) | H26: =IF(E26="PAGATO",C26-F26-G26,0)
D27: =IF(E27="PAGATO",C27-F27-G27,0) | F27: =IF(E27="PAGATO",C27*SETUP!$C$4*SETUP!$C$5,0) | G27: =IF(E27="PAGATO",IF(COUNTIF($E$5:E27,"PAGATO")=1,SETUP!$C$7,0),0) | H27: =IF(E27="PAGATO",C27-F27-G27,0)
D28: =IF(E28="PAGATO",C28-F28-G28,0) | F28: =IF(E28="PAGATO",C28*SETUP!$C$4*SETUP!$C$5,0) | G28: =IF(E28="PAGATO",IF(COUNTIF($E$5:E28,"PAGATO")=1,SETUP!$C$7,0),0) | H28: =IF(E28="PAGATO",C28-F28-G28,0)
D29: =IF(E29="PAGATO",C29-F29-G29,0) | F29: =IF(E29="PAGATO",C29*SETUP!$C$4*SETUP!$C$5,0) | G29: =IF(E29="PAGATO",IF(COUNTIF($E$5:E29,"PAGATO")=1,SETUP!$C$7,0),0) | H29: =IF(E29="PAGATO",C29-F29-G29,0)
D30: =IF(E30="PAGATO",C30-F30-G30,0) | F30: =IF(E30="PAGATO",C30*SETUP!$C$4*SETUP!$C$5,0) | G30: =IF(E30="PAGATO",IF(COUNTIF($E$5:E30,"PAGATO")=1,SETUP!$C$7,0),0) | H30: =IF(E30="PAGATO",C30-F30-G30,0)
D31: =IF(E31="PAGATO",C31-F31-G31,0) | F31: =IF(E31="PAGATO",C31*SETUP!$C$4*SETUP!$C$5,0) | G31: =IF(E31="PAGATO",IF(COUNTIF($E$5:E31,"PAGATO")=1,SETUP!$C$7,0),0) | H31: =IF(E31="PAGATO",C31-F31-G31,0)
D32: =IF(E32="PAGATO",C32-F32-G32,0) | F32: =IF(E32="PAGATO",C32*SETUP!$C$4*SETUP!$C$5,0) | G32: =IF(E32="PAGATO",IF(COUNTIF($E$5:E32,"PAGATO")=1,SETUP!$C$7,0),0) | H32: =IF(E32="PAGATO",C32-F32-G32,0)
... D36: =IF(E36="PAGATO",C36-F36-G36,0) | F36: =IF(E36="PAGATO",C36*SETUP!$C$4*SETUP!$C$5,0) | G36: =IF(E36="PAGATO",IF(COUNTIF($E$5:E36,"PAGATO")=1,SETUP!$C$7,0),0) | H36: =IF(E36="PAGATO",C36-F36-G36,0)
B39: ENTRATE NETTE / ESENTASSE
B40: VOCE | C40: IMPORTO NETTO | D40: NOTE
B51: TOTALE ENTRATE NETTE | C51: =SUM(C41:C50)
B54: USCITE
B55: CATEGORIA | C55: IMPORTO | D55: DATA | E55: TIPO | F55: NOTE
B89: TOTALE USCITE EFFETTIVE | C89: =SUMIF(E56:E88,"EFFETTIVA",C56:C88)
B90: TOTALE SPESE PROGRAMMATE | C90: =SUMIF(E56:E88,"PROGRAMMATA",C56:C88)

Sheet LUGLIO
B1: LUGLIO 2026
B3: FATTURE P.IVA | J3: RIEPILOGO MESE
B4: CLIENTE | C4: LORDO | D4: NETTO | E4: STATO | F4: TASSE | G4: INPS | H4: NETTO REALE
D5: =IF(E5="PAGATO",C5-F5-G5,0) | F5: =IF(E5="PAGATO",C5*SETUP!$C$4*SETUP!$C$5,0) | G5: =IF(E5="PAGATO",IF(COUNTIF($E$5:E5,"PAGATO")=1,SETUP!$C$7,0),0) | H5: =IF(E5="PAGATO",C5-F5-G5,0) | J5: Fatturato Incassato | K5: =SUMIF(E5:E36,"PAGATO",C5:C36)
D6: =IF(E6="PAGATO",C6-F6-G6,0) | F6: =IF(E6="PAGATO",C6*SETUP!$C$4*SETUP!$C$5,0) | G6: =IF(E6="PAGATO",IF(COUNTIF($E$5:E6,"PAGATO")=1,SETUP!$C$7,0),0) | H6: =IF(E6="PAGATO",C6-F6-G6,0) | J6: Da Incassare | K6: =SUMIF(E5:E36,"DA PAGARE",C5:C36)
D7: =IF(E7="PAGATO",C7-F7-G7,0) | F7: =IF(E7="PAGATO",C7*SETUP!$C$4*SETUP!$C$5,0) | G7: =IF(E7="PAGATO",IF(COUNTIF($E$5:E7,"PAGATO")=1,SETUP!$C$7,0),0) | H7: =IF(E7="PAGATO",C7-F7-G7,0) | J7: Pipeline Programmata | K7: =SUMIF(E5:E36,"PROGRAMMATO",C5:C36)
D8: =IF(E8="PAGATO",C8-F8-G8,0) | F8: =IF(E8="PAGATO",C8*SETUP!$C$4*SETUP!$C$5,0) | G8: =IF(E8="PAGATO",IF(COUNTIF($E$5:E8,"PAGATO")=1,SETUP!$C$7,0),0) | H8: =IF(E8="PAGATO",C8-F8-G8,0) | J8: Entrate Nette Pure | K8: =C51
D9: =IF(E9="PAGATO",C9-F9-G9,0) | F9: =IF(E9="PAGATO",C9*SETUP!$C$4*SETUP!$C$5,0) | G9: =IF(E9="PAGATO",IF(COUNTIF($E$5:E9,"PAGATO")=1,SETUP!$C$7,0),0) | H9: =IF(E9="PAGATO",C9-F9-G9,0) | J9: Spese Effettive | K9: =C89
D10: =IF(E10="PAGATO",C10-F10-G10,0) | F10: =IF(E10="PAGATO",C10*SETUP!$C$4*SETUP!$C$5,0) | G10: =IF(E10="PAGATO",IF(COUNTIF($E$5:E10,"PAGATO")=1,SETUP!$C$7,0),0) | H10: =IF(E10="PAGATO",C10-F10-G10,0) | J10: Spese Programmate | K10: =C90
D11: =IF(E11="PAGATO",C11-F11-G11,0) | F11: =IF(E11="PAGATO",C11*SETUP!$C$4*SETUP!$C$5,0) | G11: =IF(E11="PAGATO",IF(COUNTIF($E$5:E11,"PAGATO")=1,SETUP!$C$7,0),0) | H11: =IF(E11="PAGATO",C11-F11-G11,0) | J11: Zavorra Fiscale | K11: =SUM(F5:F36)+SUM(G5:G36)
D12: =IF(E12="PAGATO",C12-F12-G12,0) | F12: =IF(E12="PAGATO",C12*SETUP!$C$4*SETUP!$C$5,0) | G12: =IF(E12="PAGATO",IF(COUNTIF($E$5:E12,"PAGATO")=1,SETUP!$C$7,0),0) | H12: =IF(E12="PAGATO",C12-F12-G12,0) | J12: Netto Reale Mensile | K12: =(K5-K11)+K8-K9
D13: =IF(E13="PAGATO",C13-F13-G13,0) | F13: =IF(E13="PAGATO",C13*SETUP!$C$4*SETUP!$C$5,0) | G13: =IF(E13="PAGATO",IF(COUNTIF($E$5:E13,"PAGATO")=1,SETUP!$C$7,0),0) | H13: =IF(E13="PAGATO",C13-F13-G13,0) | J13: Totale Secchielli | K13: =SUM(K20:K31)
D14: =IF(E14="PAGATO",C14-F14-G14,0) | F14: =IF(E14="PAGATO",C14*SETUP!$C$4*SETUP!$C$5,0) | G14: =IF(E14="PAGATO",IF(COUNTIF($E$5:E14,"PAGATO")=1,SETUP!$C$7,0),0) | H14: =IF(E14="PAGATO",C14-F14-G14,0) | J14: Netto Rimanente | K14: =K12-K13
D15: =IF(E15="PAGATO",C15-F15-G15,0) | F15: =IF(E15="PAGATO",C15*SETUP!$C$4*SETUP!$C$5,0) | G15: =IF(E15="PAGATO",IF(COUNTIF($E$5:E15,"PAGATO")=1,SETUP!$C$7,0),0) | H15: =IF(E15="PAGATO",C15-F15-G15,0) | J15: Imponibile Mese | K15: =K5*SETUP!$C$4
D16: =IF(E16="PAGATO",C16-F16-G16,0) | F16: =IF(E16="PAGATO",C16*SETUP!$C$4*SETUP!$C$5,0) | G16: =IF(E16="PAGATO",IF(COUNTIF($E$5:E16,"PAGATO")=1,SETUP!$C$7,0),0) | H16: =IF(E16="PAGATO",C16-F16-G16,0) | J16: Saving Rate | K16: =IFERROR(K13/K5,0)
D17: =IF(E17="PAGATO",C17-F17-G17,0) | F17: =IF(E17="PAGATO",C17*SETUP!$C$4*SETUP!$C$5,0) | G17: =IF(E17="PAGATO",IF(COUNTIF($E$5:E17,"PAGATO")=1,SETUP!$C$7,0),0) | H17: =IF(E17="PAGATO",C17-F17-G17,0) | J17: TAX SAFE | K17: =K14-K11
D18: =IF(E18="PAGATO",C18-F18-G18,0) | F18: =IF(E18="PAGATO",C18*SETUP!$C$4*SETUP!$C$5,0) | G18: =IF(E18="PAGATO",IF(COUNTIF($E$5:E18,"PAGATO")=1,SETUP!$C$7,0),0) | H18: =IF(E18="PAGATO",C18-F18-G18,0) | J18: STATO MESE | K18: =IF(K16>=0.2,"MESE SANO",IF(K16>=0.1,"ATTENZIONE",IF(K17<0,"TASSE A RISCHIO","SAVING BASSO")))
D19: =IF(E19="PAGATO",C19-F19-G19,0) | F19: =IF(E19="PAGATO",C19*SETUP!$C$4*SETUP!$C$5,0) | G19: =IF(E19="PAGATO",IF(COUNTIF($E$5:E19,"PAGATO")=1,SETUP!$C$7,0),0) | H19: =IF(E19="PAGATO",C19-F19-G19,0) | J19: SECCHIELLI RISPARMIO
D20: =IF(E20="PAGATO",C20-F20-G20,0) | F20: =IF(E20="PAGATO",C20*SETUP!$C$4*SETUP!$C$5,0) | G20: =IF(E20="PAGATO",IF(COUNTIF($E$5:E20,"PAGATO")=1,SETUP!$C$7,0),0) | H20: =IF(E20="PAGATO",C20-F20-G20,0) | J20: OBIETTIVO | K20: IMPORTO | L20: DESCRIZIONE
D21: =IF(E21="PAGATO",C21-F21-G21,0) | F21: =IF(E21="PAGATO",C21*SETUP!$C$4*SETUP!$C$5,0) | G21: =IF(E21="PAGATO",IF(COUNTIF($E$5:E21,"PAGATO")=1,SETUP!$C$7,0),0) | H21: =IF(E21="PAGATO",C21-F21-G21,0)
D22: =IF(E22="PAGATO",C22-F22-G22,0) | F22: =IF(E22="PAGATO",C22*SETUP!$C$4*SETUP!$C$5,0) | G22: =IF(E22="PAGATO",IF(COUNTIF($E$5:E22,"PAGATO")=1,SETUP!$C$7,0),0) | H22: =IF(E22="PAGATO",C22-F22-G22,0)
D23: =IF(E23="PAGATO",C23-F23-G23,0) | F23: =IF(E23="PAGATO",C23*SETUP!$C$4*SETUP!$C$5,0) | G23: =IF(E23="PAGATO",IF(COUNTIF($E$5:E23,"PAGATO")=1,SETUP!$C$7,0),0) | H23: =IF(E23="PAGATO",C23-F23-G23,0)
D24: =IF(E24="PAGATO",C24-F24-G24,0) | F24: =IF(E24="PAGATO",C24*SETUP!$C$4*SETUP!$C$5,0) | G24: =IF(E24="PAGATO",IF(COUNTIF($E$5:E24,"PAGATO")=1,SETUP!$C$7,0),0) | H24: =IF(E24="PAGATO",C24-F24-G24,0)
D25: =IF(E25="PAGATO",C25-F25-G25,0) | F25: =IF(E25="PAGATO",C25*SETUP!$C$4*SETUP!$C$5,0) | G25: =IF(E25="PAGATO",IF(COUNTIF($E$5:E25,"PAGATO")=1,SETUP!$C$7,0),0) | H25: =IF(E25="PAGATO",C25-F25-G25,0)
D26: =IF(E26="PAGATO",C26-F26-G26,0) | F26: =IF(E26="PAGATO",C26*SETUP!$C$4*SETUP!$C$5,0) | G26: =IF(E26="PAGATO",IF(COUNTIF($E$5:E26,"PAGATO")=1,SETUP!$C$7,0),0) | H26: =IF(E26="PAGATO",C26-F26-G26,0)
D27: =IF(E27="PAGATO",C27-F27-G27,0) | F27: =IF(E27="PAGATO",C27*SETUP!$C$4*SETUP!$C$5,0) | G27: =IF(E27="PAGATO",IF(COUNTIF($E$5:E27,"PAGATO")=1,SETUP!$C$7,0),0) | H27: =IF(E27="PAGATO",C27-F27-G27,0)
D28: =IF(E28="PAGATO",C28-F28-G28,0) | F28: =IF(E28="PAGATO",C28*SETUP!$C$4*SETUP!$C$5,0) | G28: =IF(E28="PAGATO",IF(COUNTIF($E$5:E28,"PAGATO")=1,SETUP!$C$7,0),0) | H28: =IF(E28="PAGATO",C28-F28-G28,0)
D29: =IF(E29="PAGATO",C29-F29-G29,0) | F29: =IF(E29="PAGATO",C29*SETUP!$C$4*SETUP!$C$5,0) | G29: =IF(E29="PAGATO",IF(COUNTIF($E$5:E29,"PAGATO")=1,SETUP!$C$7,0),0) | H29: =IF(E29="PAGATO",C29-F29-G29,0)
D30: =IF(E30="PAGATO",C30-F30-G30,0) | F30: =IF(E30="PAGATO",C30*SETUP!$C$4*SETUP!$C$5,0) | G30: =IF(E30="PAGATO",IF(COUNTIF($E$5:E30,"PAGATO")=1,SETUP!$C$7,0),0) | H30: =IF(E30="PAGATO",C30-F30-G30,0)
D31: =IF(E31="PAGATO",C31-F31-G31,0) | F31: =IF(E31="PAGATO",C31*SETUP!$C$4*SETUP!$C$5,0) | G31: =IF(E31="PAGATO",IF(COUNTIF($E$5:E31,"PAGATO")=1,SETUP!$C$7,0),0) | H31: =IF(E31="PAGATO",C31-F31-G31,0)
D32: =IF(E32="PAGATO",C32-F32-G32,0) | F32: =IF(E32="PAGATO",C32*SETUP!$C$4*SETUP!$C$5,0) | G32: =IF(E32="PAGATO",IF(COUNTIF($E$5:E32,"PAGATO")=1,SETUP!$C$7,0),0) | H32: =IF(E32="PAGATO",C32-F32-G32,0)
... D36: =IF(E36="PAGATO",C36-F36-G36,0) | F36: =IF(E36="PAGATO",C36*SETUP!$C$4*SETUP!$C$5,0) | G36: =IF(E36="PAGATO",IF(COUNTIF($E$5:E36,"PAGATO")=1,SETUP!$C$7,0),0) | H36: =IF(E36="PAGATO",C36-F36-G36,0)
B39: ENTRATE NETTE / ESENTASSE
B40: VOCE | C40: IMPORTO NETTO | D40: NOTE
B51: TOTALE ENTRATE NETTE | C51: =SUM(C41:C50)
B54: USCITE
B55: CATEGORIA | C55: IMPORTO | D55: DATA | E55: TIPO | F55: NOTE
B89: TOTALE USCITE EFFETTIVE | C89: =SUMIF(E56:E88,"EFFETTIVA",C56:C88)
B90: TOTALE SPESE PROGRAMMATE | C90: =SUMIF(E56:E88,"PROGRAMMATA",C56:C88)

Sheet AGOSTO
B1: AGOSTO 2026
B3: FATTURE P.IVA | J3: RIEPILOGO MESE
B4: CLIENTE | C4: LORDO | D4: NETTO | E4: STATO | F4: TASSE | G4: INPS | H4: NETTO REALE
D5: =IF(E5="PAGATO",C5-F5-G5,0) | F5: =IF(E5="PAGATO",C5*SETUP!$C$4*SETUP!$C$5,0) | G5: =IF(E5="PAGATO",IF(COUNTIF($E$5:E5,"PAGATO")=1,SETUP!$C$7,0),0) | H5: =IF(E5="PAGATO",C5-F5-G5,0) | J5: Fatturato Incassato | K5: =SUMIF(E5:E36,"PAGATO",C5:C36)
D6: =IF(E6="PAGATO",C6-F6-G6,0) | F6: =IF(E6="PAGATO",C6*SETUP!$C$4*SETUP!$C$5,0) | G6: =IF(E6="PAGATO",IF(COUNTIF($E$5:E6,"PAGATO")=1,SETUP!$C$7,0),0) | H6: =IF(E6="PAGATO",C6-F6-G6,0) | J6: Da Incassare | K6: =SUMIF(E5:E36,"DA PAGARE",C5:C36)
D7: =IF(E7="PAGATO",C7-F7-G7,0) | F7: =IF(E7="PAGATO",C7*SETUP!$C$4*SETUP!$C$5,0) | G7: =IF(E7="PAGATO",IF(COUNTIF($E$5:E7,"PAGATO")=1,SETUP!$C$7,0),0) | H7: =IF(E7="PAGATO",C7-F7-G7,0) | J7: Pipeline Programmata | K7: =SUMIF(E5:E36,"PROGRAMMATO",C5:C36)
D8: =IF(E8="PAGATO",C8-F8-G8,0) | F8: =IF(E8="PAGATO",C8*SETUP!$C$4*SETUP!$C$5,0) | G8: =IF(E8="PAGATO",IF(COUNTIF($E$5:E8,"PAGATO")=1,SETUP!$C$7,0),0) | H8: =IF(E8="PAGATO",C8-F8-G8,0) | J8: Entrate Nette Pure | K8: =C51
D9: =IF(E9="PAGATO",C9-F9-G9,0) | F9: =IF(E9="PAGATO",C9*SETUP!$C$4*SETUP!$C$5,0) | G9: =IF(E9="PAGATO",IF(COUNTIF($E$5:E9,"PAGATO")=1,SETUP!$C$7,0),0) | H9: =IF(E9="PAGATO",C9-F9-G9,0) | J9: Spese Effettive | K9: =C89
D10: =IF(E10="PAGATO",C10-F10-G10,0) | F10: =IF(E10="PAGATO",C10*SETUP!$C$4*SETUP!$C$5,0) | G10: =IF(E10="PAGATO",IF(COUNTIF($E$5:E10,"PAGATO")=1,SETUP!$C$7,0),0) | H10: =IF(E10="PAGATO",C10-F10-G10,0) | J10: Spese Programmate | K10: =C90
D11: =IF(E11="PAGATO",C11-F11-G11,0) | F11: =IF(E11="PAGATO",C11*SETUP!$C$4*SETUP!$C$5,0) | G11: =IF(E11="PAGATO",IF(COUNTIF($E$5:E11,"PAGATO")=1,SETUP!$C$7,0),0) | H11: =IF(E11="PAGATO",C11-F11-G11,0) | J11: Zavorra Fiscale | K11: =SUM(F5:F36)+SUM(G5:G36)
D12: =IF(E12="PAGATO",C12-F12-G12,0) | F12: =IF(E12="PAGATO",C12*SETUP!$C$4*SETUP!$C$5,0) | G12: =IF(E12="PAGATO",IF(COUNTIF($E$5:E12,"PAGATO")=1,SETUP!$C$7,0),0) | H12: =IF(E12="PAGATO",C12-F12-G12,0) | J12: Netto Reale Mensile | K12: =(K5-K11)+K8-K9
D13: =IF(E13="PAGATO",C13-F13-G13,0) | F13: =IF(E13="PAGATO",C13*SETUP!$C$4*SETUP!$C$5,0) | G13: =IF(E13="PAGATO",IF(COUNTIF($E$5:E13,"PAGATO")=1,SETUP!$C$7,0),0) | H13: =IF(E13="PAGATO",C13-F13-G13,0) | J13: Totale Secchielli | K13: =SUM(K20:K31)
D14: =IF(E14="PAGATO",C14-F14-G14,0) | F14: =IF(E14="PAGATO",C14*SETUP!$C$4*SETUP!$C$5,0) | G14: =IF(E14="PAGATO",IF(COUNTIF($E$5:E14,"PAGATO")=1,SETUP!$C$7,0),0) | H14: =IF(E14="PAGATO",C14-F14-G14,0) | J14: Netto Rimanente | K14: =K12-K13
D15: =IF(E15="PAGATO",C15-F15-G15,0) | F15: =IF(E15="PAGATO",C15*SETUP!$C$4*SETUP!$C$5,0) | G15: =IF(E15="PAGATO",IF(COUNTIF($E$5:E15,"PAGATO")=1,SETUP!$C$7,0),0) | H15: =IF(E15="PAGATO",C15-F15-G15,0) | J15: Imponibile Mese | K15: =K5*SETUP!$C$4
D16: =IF(E16="PAGATO",C16-F16-G16,0) | F16: =IF(E16="PAGATO",C16*SETUP!$C$4*SETUP!$C$5,0) | G16: =IF(E16="PAGATO",IF(COUNTIF($E$5:E16,"PAGATO")=1,SETUP!$C$7,0),0) | H16: =IF(E16="PAGATO",C16-F16-G16,0) | J16: Saving Rate | K16: =IFERROR(K13/K5,0)
D17: =IF(E17="PAGATO",C17-F17-G17,0) | F17: =IF(E17="PAGATO",C17*SETUP!$C$4*SETUP!$C$5,0) | G17: =IF(E17="PAGATO",IF(COUNTIF($E$5:E17,"PAGATO")=1,SETUP!$C$7,0),0) | H17: =IF(E17="PAGATO",C17-F17-G17,0) | J17: TAX SAFE | K17: =K14-K11
D18: =IF(E18="PAGATO",C18-F18-G18,0) | F18: =IF(E18="PAGATO",C18*SETUP!$C$4*SETUP!$C$5,0) | G18: =IF(E18="PAGATO",IF(COUNTIF($E$5:E18,"PAGATO")=1,SETUP!$C$7,0),0) | H18: =IF(E18="PAGATO",C18-F18-G18,0) | J18: STATO MESE | K18: =IF(K16>=0.2,"MESE SANO",IF(K16>=0.1,"ATTENZIONE",IF(K17<0,"TASSE A RISCHIO","SAVING BASSO")))
D19: =IF(E19="PAGATO",C19-F19-G19,0) | F19: =IF(E19="PAGATO",C19*SETUP!$C$4*SETUP!$C$5,0) | G19: =IF(E19="PAGATO",IF(COUNTIF($E$5:E19,"PAGATO")=1,SETUP!$C$7,0),0) | H19: =IF(E19="PAGATO",C19-F19-G19,0) | J19: SECCHIELLI RISPARMIO
D20: =IF(E20="PAGATO",C20-F20-G20,0) | F20: =IF(E20="PAGATO",C20*SETUP!$C$4*SETUP!$C$5,0) | G20: =IF(E20="PAGATO",IF(COUNTIF($E$5:E20,"PAGATO")=1,SETUP!$C$7,0),0) | H20: =IF(E20="PAGATO",C20-F20-G20,0) | J20: OBIETTIVO | K20: IMPORTO | L20: DESCRIZIONE
D21: =IF(E21="PAGATO",C21-F21-G21,0) | F21: =IF(E21="PAGATO",C21*SETUP!$C$4*SETUP!$C$5,0) | G21: =IF(E21="PAGATO",IF(COUNTIF($E$5:E21,"PAGATO")=1,SETUP!$C$7,0),0) | H21: =IF(E21="PAGATO",C21-F21-G21,0)
D22: =IF(E22="PAGATO",C22-F22-G22,0) | F22: =IF(E22="PAGATO",C22*SETUP!$C$4*SETUP!$C$5,0) | G22: =IF(E22="PAGATO",IF(COUNTIF($E$5:E22,"PAGATO")=1,SETUP!$C$7,0),0) | H22: =IF(E22="PAGATO",C22-F22-G22,0)
D23: =IF(E23="PAGATO",C23-F23-G23,0) | F23: =IF(E23="PAGATO",C23*SETUP!$C$4*SETUP!$C$5,0) | G23: =IF(E23="PAGATO",IF(COUNTIF($E$5:E23,"PAGATO")=1,SETUP!$C$7,0),0) | H23: =IF(E23="PAGATO",C23-F23-G23,0)
D24: =IF(E24="PAGATO",C24-F24-G24,0) | F24: =IF(E24="PAGATO",C24*SETUP!$C$4*SETUP!$C$5,0) | G24: =IF(E24="PAGATO",IF(COUNTIF($E$5:E24,"PAGATO")=1,SETUP!$C$7,0),0) | H24: =IF(E24="PAGATO",C24-F24-G24,0)
D25: =IF(E25="PAGATO",C25-F25-G25,0) | F25: =IF(E25="PAGATO",C25*SETUP!$C$4*SETUP!$C$5,0) | G25: =IF(E25="PAGATO",IF(COUNTIF($E$5:E25,"PAGATO")=1,SETUP!$C$7,0),0) | H25: =IF(E25="PAGATO",C25-F25-G25,0)
D26: =IF(E26="PAGATO",C26-F26-G26,0) | F26: =IF(E26="PAGATO",C26*SETUP!$C$4*SETUP!$C$5,0) | G26: =IF(E26="PAGATO",IF(COUNTIF($E$5:E26,"PAGATO")=1,SETUP!$C$7,0),0) | H26: =IF(E26="PAGATO",C26-F26-G26,0)
D27: =IF(E27="PAGATO",C27-F27-G27,0) | F27: =IF(E27="PAGATO",C27*SETUP!$C$4*SETUP!$C$5,0) | G27: =IF(E27="PAGATO",IF(COUNTIF($E$5:E27,"PAGATO")=1,SETUP!$C$7,0),0) | H27: =IF(E27="PAGATO",C27-F27-G27,0)
D28: =IF(E28="PAGATO",C28-F28-G28,0) | F28: =IF(E28="PAGATO",C28*SETUP!$C$4*SETUP!$C$5,0) | G28: =IF(E28="PAGATO",IF(COUNTIF($E$5:E28,"PAGATO")=1,SETUP!$C$7,0),0) | H28: =IF(E28="PAGATO",C28-F28-G28,0)
D29: =IF(E29="PAGATO",C29-F29-G29,0) | F29: =IF(E29="PAGATO",C29*SETUP!$C$4*SETUP!$C$5,0) | G29: =IF(E29="PAGATO",IF(COUNTIF($E$5:E29,"PAGATO")=1,SETUP!$C$7,0),0) | H29: =IF(E29="PAGATO",C29-F29-G29,0)
D30: =IF(E30="PAGATO",C30-F30-G30,0) | F30: =IF(E30="PAGATO",C30*SETUP!$C$4*SETUP!$C$5,0) | G30: =IF(E30="PAGATO",IF(COUNTIF($E$5:E30,"PAGATO")=1,SETUP!$C$7,0),0) | H30: =IF(E30="PAGATO",C30-F30-G30,0)
D31: =IF(E31="PAGATO",C31-F31-G31,0) | F31: =IF(E31="PAGATO",C31*SETUP!$C$4*SETUP!$C$5,0) | G31: =IF(E31="PAGATO",IF(COUNTIF($E$5:E31,"PAGATO")=1,SETUP!$C$7,0),0) | H31: =IF(E31="PAGATO",C31-F31-G31,0)
D32: =IF(E32="PAGATO",C32-F32-G32,0) | F32: =IF(E32="PAGATO",C32*SETUP!$C$4*SETUP!$C$5,0) | G32: =IF(E32="PAGATO",IF(COUNTIF($E$5:E32,"PAGATO")=1,SETUP!$C$7,0),0) | H32: =IF(E32="PAGATO",C32-F32-G32,0)
... D36: =IF(E36="PAGATO",C36-F36-G36,0) | F36: =IF(E36="PAGATO",C36*SETUP!$C$4*SETUP!$C$5,0) | G36: =IF(E36="PAGATO",IF(COUNTIF($E$5:E36,"PAGATO")=1,SETUP!$C$7,0),0) | H36: =IF(E36="PAGATO",C36-F36-G36,0)
B39: ENTRATE NETTE / ESENTASSE
B40: VOCE | C40: IMPORTO NETTO | D40: NOTE
B51: TOTALE ENTRATE NETTE | C51: =SUM(C41:C50)
B54: USCITE
B55: CATEGORIA | C55: IMPORTO | D55: DATA | E55: TIPO | F55: NOTE
B89: TOTALE USCITE EFFETTIVE | C89: =SUMIF(E56:E88,"EFFETTIVA",C56:C88)
B90: TOTALE SPESE PROGRAMMATE | C90: =SUMIF(E56:E88,"PROGRAMMATA",C56:C88)

Sheet SETTEMBRE
B1: SETTEMBRE 2026
B3: FATTURE P.IVA | J3: RIEPILOGO MESE
B4: CLIENTE | C4: LORDO | D4: NETTO | E4: STATO | F4: TASSE | G4: INPS | H4: NETTO REALE
D5: =IF(E5="PAGATO",C5-F5-G5,0) | F5: =IF(E5="PAGATO",C5*SETUP!$C$4*SETUP!$C$5,0) | G5: =IF(E5="PAGATO",IF(COUNTIF($E$5:E5,"PAGATO")=1,SETUP!$C$7,0),0) | H5: =IF(E5="PAGATO",C5-F5-G5,0) | J5: Fatturato Incassato | K5: =SUMIF(E5:E36,"PAGATO",C5:C36)
D6: =IF(E6="PAGATO",C6-F6-G6,0) | F6: =IF(E6="PAGATO",C6*SETUP!$C$4*SETUP!$C$5,0) | G6: =IF(E6="PAGATO",IF(COUNTIF($E$5:E6,"PAGATO")=1,SETUP!$C$7,0),0) | H6: =IF(E6="PAGATO",C6-F6-G6,0) | J6: Da Incassare | K6: =SUMIF(E5:E36,"DA PAGARE",C5:C36)
D7: =IF(E7="PAGATO",C7-F7-G7,0) | F7: =IF(E7="PAGATO",C7*SETUP!$C$4*SETUP!$C$5,0) | G7: =IF(E7="PAGATO",IF(COUNTIF($E$5:E7,"PAGATO")=1,SETUP!$C$7,0),0) | H7: =IF(E7="PAGATO",C7-F7-G7,0) | J7: Pipeline Programmata | K7: =SUMIF(E5:E36,"PROGRAMMATO",C5:C36)
D8: =IF(E8="PAGATO",C8-F8-G8,0) | F8: =IF(E8="PAGATO",C8*SETUP!$C$4*SETUP!$C$5,0) | G8: =IF(E8="PAGATO",IF(COUNTIF($E$5:E8,"PAGATO")=1,SETUP!$C$7,0),0) | H8: =IF(E8="PAGATO",C8-F8-G8,0) | J8: Entrate Nette Pure | K8: =C51
D9: =IF(E9="PAGATO",C9-F9-G9,0) | F9: =IF(E9="PAGATO",C9*SETUP!$C$4*SETUP!$C$5,0) | G9: =IF(E9="PAGATO",IF(COUNTIF($E$5:E9,"PAGATO")=1,SETUP!$C$7,0),0) | H9: =IF(E9="PAGATO",C9-F9-G9,0) | J9: Spese Effettive | K9: =C89
D10: =IF(E10="PAGATO",C10-F10-G10,0) | F10: =IF(E10="PAGATO",C10*SETUP!$C$4*SETUP!$C$5,0) | G10: =IF(E10="PAGATO",IF(COUNTIF($E$5:E10,"PAGATO")=1,SETUP!$C$7,0),0) | H10: =IF(E10="PAGATO",C10-F10-G10,0) | J10: Spese Programmate | K10: =C90
D11: =IF(E11="PAGATO",C11-F11-G11,0) | F11: =IF(E11="PAGATO",C11*SETUP!$C$4*SETUP!$C$5,0) | G11: =IF(E11="PAGATO",IF(COUNTIF($E$5:E11,"PAGATO")=1,SETUP!$C$7,0),0) | H11: =IF(E11="PAGATO",C11-F11-G11,0) | J11: Zavorra Fiscale | K11: =SUM(F5:F36)+SUM(G5:G36)
D12: =IF(E12="PAGATO",C12-F12-G12,0) | F12: =IF(E12="PAGATO",C12*SETUP!$C$4*SETUP!$C$5,0) | G12: =IF(E12="PAGATO",IF(COUNTIF($E$5:E12,"PAGATO")=1,SETUP!$C$7,0),0) | H12: =IF(E12="PAGATO",C12-F12-G12,0) | J12: Netto Reale Mensile | K12: =(K5-K11)+K8-K9
D13: =IF(E13="PAGATO",C13-F13-G13,0) | F13: =IF(E13="PAGATO",C13*SETUP!$C$4*SETUP!$C$5,0) | G13: =IF(E13="PAGATO",IF(COUNTIF($E$5:E13,"PAGATO")=1,SETUP!$C$7,0),0) | H13: =IF(E13="PAGATO",C13-F13-G13,0) | J13: Totale Secchielli | K13: =SUM(K20:K31)
D14: =IF(E14="PAGATO",C14-F14-G14,0) | F14: =IF(E14="PAGATO",C14*SETUP!$C$4*SETUP!$C$5,0) | G14: =IF(E14="PAGATO",IF(COUNTIF($E$5:E14,"PAGATO")=1,SETUP!$C$7,0),0) | H14: =IF(E14="PAGATO",C14-F14-G14,0) | J14: Netto Rimanente | K14: =K12-K13
